Workbook
Name \Q: #REF!
Name \S: #REF!
Name \W: #REF!
Name \x: #REF!
Name _??: BlankMacro1
Name _??: BlankMacro1
Name _??: BlankMacro1
Name _??: BlankMacro1
Name _??: BlankMacro1
Name _??: BlankMacro1
Name _??: BlankMacro1
Name _??: BlankMacro1
Name _??: BlankMacro1
Name _??????1: BlankMacro1
Name _??????1: BlankMacro1
Name _??????1: BlankMacro1
Name _??????1: BlankMacro1
Name _??????1: BlankMacro1
Name _??????1: BlankMacro1
Name _??????1: BlankMacro1
Name _??????1: BlankMacro1
Name _??????1: BlankMacro1
Name _??????2: BlankMacro1
Name _??????2: BlankMacro1
Name _??????2: BlankMacro1
Name _??????2: BlankMacro1
Name _??????2: BlankMacro1
Name _??????2: BlankMacro1
Name _??????2: BlankMacro1
Name _??????2: BlankMacro1
Name _??????2: BlankMacro1
Name _??????3: BlankMacro1
Name _??????3: BlankMacro1
Name _??????3: BlankMacro1
Name _??????3: BlankMacro1
Name _??????3: BlankMacro1
Name _??????3: BlankMacro1
Name _??????3: BlankMacro1
Name _??????3: BlankMacro1
Name _??????3: BlankMacro1
Name _??????4: BlankMacro1
Name _??????4: BlankMacro1
Name _??????4: BlankMacro1
Name _??????4: BlankMacro1
Name _??????4: BlankMacro1
Name _??????4: BlankMacro1
Name _??????4: BlankMacro1
Name _??????4: BlankMacro1
Name _??????4: BlankMacro1
Name _??????5: BlankMacro1
Name _??????5: BlankMacro1
Name _??????5: BlankMacro1
Name _??????5: BlankMacro1
Name _??????5: BlankMacro1
Name _??????5: BlankMacro1
Name _??????5: BlankMacro1
Name _??????5: BlankMacro1
Name _??????5: BlankMacro1
Name _??????6: BlankMacro1
Name _??????6: BlankMacro1

Sheet foxz

Sheet 01-Bia
B1: CỘNG HÒA XÃ HỘI CHỦ NGHĨA VIỆT NAM
B2: Độc lập - Tự do - Hạnh phúc
B9: HỒ SƠ THANH TOÁN
B11: ĐỢT 02
B17: DỰ ÁN: DỰ ÁN ĐẦU TƯ XÂY DỰNG NHÀ Ở CAO TẦNG KẾT HỢP THƯƠNG MẠI DỊCH VỤ VÀ NHÀ Ở THẤP TẦNG SUNSHINE CRYSTAL RIVER
B18: GÓI THẦU: THI CÔNG KẾT CẤU, CHỐNG THẤM CẢNH QUAN NGOÀI NHÀ KHU VỰC CAO TẦNG
B19: ĐỊA ĐIỂM: Ô ĐẤT CT01-CT VÀ CT01-TT (ĐƯỢC ĐIỀU CHỈNH TỪ Ô ĐẤT CT01) THUỘC KHU ĐÔ THỊ NAM THĂNG LONG, GIAI ĐOẠN III, PHƯỜNG PHÚ THƯỢNG, QUẬN TÂY HỒ, HÀ NỘI
B20: BÊN GIAO THẦU: CÔNG TY TNHH ĐẦU TƯ THƯƠNG MẠI SÔNG MÃ
B21: BÊN NHẬN THẦU: CÔNG TY CỔ PHẦN ĐẦU TƯ XÂY DỰNG HOÀNG LONG GROUP
B22: SỐ HỢP ĐỒNG : 21/2025/HĐTC/CT01/SM-HL NGÀY 10/02/2025
B29: HÀ NỘI - 2025

Sheet 01-Công văn 
A1: CÔNG TY CỔ PHẦN ĐTXD HOÀNG LONG GROUP | E1: CỘNG HÒA XÃ HỘI CHỦ NGHĨA VIỆT NAM
E2: Độc Lập - Tự Do - Hạnh Phúc
A3: 01.2025/CV-HL-SM/CT01 | E3: =====o0o =====
A4: (V/v: Đề nghị thanh toán) | E4: Hà Nội, ngày .... tháng .… năm 2025
A6: GIẤY ĐỀ NGHỊ THANH TOÁN
A7: Kính gửi: | C7: CÔNG TY TNHH ĐẦU TƯ THƯƠNG MẠI SÔNG MÃ
A9: - Căn cứ Hợp đồng thi công số 21/2025/HĐTC/CT01/SM-HL ngày 10/02/2025 giữa Công ty TNHH Đầu tư Thương mại Sông Mã và Công ty Cổ phần Đầu tư Xây dựng Hoàng Long Group về việc thực hiện Gói thầu: Thi công kết cấu, chống thấm cảnh quan ngoài nhà khu vực cao tầng thuộc Dự án đầu tư xây dựng nhà ở cao tầng kết hợp thương mại dịch vụ và nhà ở thấp tầng Sunshine Crystal River
A10: - Căn cứ vào hồ sơ thanh toán đợt 1
B12: 1 | C12: Giá trị hoàn thành | F12: ='02.2 ĐNTT'!E17 -> 1767478295 | H12: đồng
B13: 2 | C13: Giá trị thanh toán | F13: ='02.2 ĐNTT'!J30 -> 1.2380757e+09 | H13: đồng | K13: 2864147927 | M13: 1781704938
K14: =F13-K13 -> -1.6260723e+09 | M14: 1.1757101e+09
A15: Nay Công ty Cổ phần Đầu tư xây dựng Hoàng Long Group đề nghị Công ty TNHH Đầu tư Thương mại Sông Mã thanh toán số tiền là:
A16: Giá trị: | D16: =F13 -> 1.2380757e+09 | F16: =H12 -> đồng | L16: 927072875
A17: ='02.2 ĐNTT'!B32 -> Bằng chữ:
A19: Về tài khoản:
B20: + Chủ tài khoản: Công ty Cổ phần Đầu tư Xây dựng Hoàng Long Group
B21: + Người đại diện: Đầu Minh Lăng + Chức vụ: Tổng Giám đốc | K21: ='02.2 ĐNTT'!J30:K30 -> 0
B22: + Số tài khoản: 00083589003
B23: + Tại Ngân hàng: TMCP Tiên Phong - Chi nhánh Đống Đa
A24: Kính mong Công ty TNHH Đầu tư Thương mại Sông Mã tạo điều kiện giúp đỡ.
A25: Xin trân trọng cảm ơn./
F26: CÔNG TY CỔ PHẦN ĐẦU TƯ XÂY DỰNG
F27: HOÀNG LONG GROUP
A28: Nơi nhận:
A29: - Như kính gửi
A30: - Lưu CT

Sheet 02.1-ĐNTT
A2: Dự án: Dự án đầu tư xây dựng nhà ở cao tầng kết hợp thương mại dịch vụ và nhà ở thấp tầng Sunshine Crystal River
A3: BẢNG TỔNG HỢP GIÁ TRỊ ĐỀ NGHỊ THANH TOÁN THEO KÌ
B5: Thầu phụ: Công ty Cổ phần Đầu tư Xây dựng Hoàng Long Group | E5: Hợp đồng số: 21/2025/CT01/SM-HL | J5: Địa điểm thi công: | K5: Ô đất CT01-CT và CT01-TT (được điều chỉnh từ ô đất CT01) thuộc Khu đô thị Nam Thăng Long, giai đoạn III, Phường Phú Thượng, Quận Tây Hồ, Hà Nội
B7: Chủ thẻ: Công ty Cổ phần Đầu tư Xây dựng Hoàng Long Group | E7: Ngân hàng: TMCP Tiên Phong - Chi nhánh Đống Đa | J7: Thanh toán lần : | K7: 02
B8: Số tài khoản: 00083589003 | J8: Đơn vị tính: VNĐ
A10: Stt | B10: Hạng mục công việc | C10: ĐVT | D10: Đơn giá (Chưa VAT) | E10: Hợp đồng | G10: Khối lượng nghiệm thu | J10: Giá trị nghiệm thu | M10: Hợp đồng còn lại
E11: Khối lượng | F11: Giá trị | G11: Luỹ kế kỳ trước | H11: Kỳ này | I11: Luỹ kế đến nay | J11: Luỹ kế kỳ trước | K11: Kỳ này | L11: Luỹ kế đến nay | M11: Khối lượng | N11: Giá trị
B12: HĐ số 21/2025/CT01/SM-HL | J12: =+SUBTOTAL(9,J13:J152) -> 1989051752 | K12: =+SUBTOTAL(9,K13:K152) -> 1636553977 | L12: =+SUBTOTAL(9,L13:L152) -> 3625605729 | N12: =+SUBTOTAL(9,N13:N152) -> 1.1089772e+10
A13: * | B13: HẠNG MỤC: THI CÔNG KẾT CẤU CẢNH QUAN NGOÀI NHÀ KHU VỰC CAO TẦNG
A14: I | B14: CÔNG TÁC XÂY
A15: 1 | B15: Xây tường gạch đặc, chiều dày >330mm, VXM mác 75 | C15: m3 | D15: 2275030 | E15: 35.03 | F15: =+E15*D15 -> 79694301 | G15: ='03-GTHT DOT...'!E10 -> 0 | H15: ='03-GTHT DOT...'!F10 -> 0 | I15: ='03-GTHT DOT...'!G10 -> 0 | J15: ='03-GTHT DOT...'!H10 -> 0 | K15: ='03-GTHT DOT...'!I10 -> 0 | L15: ='03-GTHT DOT...'!J10 -> 0 | M15: =E15-I15 -> 35.03 | N15: =F15-L15 -> 79694301
A16: 2 | B16: Xây tường gạch đặc, chiều dày <=330mm, VXM mác 75 | C16: m3 | D16: 2275030 | E16: 1174.45 | F16: =+E16*D16 -> 2.671909e+09 | G16: ='03-GTHT DOT...'!E11 -> 0 | H16: ='03-GTHT DOT...'!F11 -> 0 | I16: ='03-GTHT DOT...'!G11 -> 0 | J16: ='03-GTHT DOT...'!H11 -> 0 | K16: ='03-GTHT DOT...'!I11 -> 0 | L16: ='03-GTHT DOT...'!J11 -> 0 | M16: =E16-I16 -> 1174.45 | N16: =F16-L16 -> 2.671909e+09
A17: 3 | B17: Xây tường gạch đặc, chiều dày <=110mm, VXM mác 75 | C17: m3 | D17: 2335944 | E17: 19.56 | F17: =+E17*D17 -> 45691065 | G17: ='03-GTHT DOT...'!E12 -> 0 | H17: ='03-GTHT DOT...'!F12 -> 0 | I17: ='03-GTHT DOT...'!G12 -> 0 | J17: ='03-GTHT DOT...'!H12 -> 0 | K17: ='03-GTHT DOT...'!I12 -> 0 | L17: ='03-GTHT DOT...'!J12 -> 0 | M17: =E17-I17 -> 19.56 | N17: =F17-L17 -> 45691065
A18: 4 | B18: Xây cột, trụ, gạch đặc, VXM mác 75 | C18: m3 | D18: 2572168 | E18: 0.99 | F18: =+E18*D18 -> 2546446.3 | G18: ='03-GTHT DOT...'!E13 -> 0 | H18: ='03-GTHT DOT...'!F13 -> 0 | I18: ='03-GTHT DOT...'!G13 -> 0 | J18: ='03-GTHT DOT...'!H13 -> 0 | K18: ='03-GTHT DOT...'!I13 -> 0 | L18: ='03-GTHT DOT...'!J13 -> 0 | M18: =E18-I18 -> 0.99 | N18: =F18-L18 -> 2546446.3
A19: 5 | B19: Ván khuôn giằng tường | C19: m2 | D19: 240597 | E19: 256.45 | F19: =+E19*D19 -> 61701101 | G19: ='03-GTHT DOT...'!E14 -> 0 | H19: ='03-GTHT DOT...'!F14 -> 0 | I19: ='03-GTHT DOT...'!G14 -> 0 | J19: ='03-GTHT DOT...'!H14 -> 0 | K19: ='03-GTHT DOT...'!I14 -> 0 | L19: ='03-GTHT DOT...'!J14 -> 0 | M19: =E19-I19 -> 256.45 | N19: =F19-L19 -> 61701101
A20: 6 | B20: Cốt thép giằng tường | C20: kg | D20: 6030 | E20: 2029.13 | F20: =+E20*D20 -> 12235654 | G20: ='03-GTHT DOT...'!E15 -> 0 | H20: ='03-GTHT DOT...'!F15 -> 0 | I20: ='03-GTHT DOT...'!G15 -> 0 | J20: ='03-GTHT DOT...'!H15 -> 0 | K20: ='03-GTHT DOT...'!I15 -> 0 | L20: ='03-GTHT DOT...'!J15 -> 0 | M20: =E20-I20 -> 2029.13 | N20: =F20-L20 -> 12235654
A21: 7 | B21: Bê tông giằng tường mác 200# | C21: m3 | D21: 366825 | E21: 28.21 | F21: =+E21*D21 -> 10348133 | G21: ='03-GTHT DOT...'!E16 -> 0 | H21: ='03-GTHT DOT...'!F16 -> 0 | I21: ='03-GTHT DOT...'!G16 -> 0 | J21: ='03-GTHT DOT...'!H16 -> 0 | K21: ='03-GTHT DOT...'!I16 -> 0 | L21: ='03-GTHT DOT...'!J16 -> 0 | M21: =E21-I21 -> 28.21 | N21: =F21-L21 -> 10348133
A22: 8 | B22: Khoan cấy cốt thép, đường kính thép D14 | C22: vị trí | D22: 27600 | E22: 548 | F22: =+E22*D22 -> 15124800 | G22: ='03-GTHT DOT...'!E17 -> 0 | H22: ='03-GTHT DOT...'!F17 -> 0 | I22: ='03-GTHT DOT...'!G17 -> 0 | J22: ='03-GTHT DOT...'!H17 -> 0 | K22: ='03-GTHT DOT...'!I17 -> 0 | L22: ='03-GTHT DOT...'!J17 -> 0 | M22: =E22-I22 -> 548 | N22: =F22-L22 -> 15124800
A23: 9 | B23: Ván khuôn trụ tường | C23: m2 | D23: 240597 | E23: 162.76 | F23: =+E23*D23 -> 39159568 | G23: ='03-GTHT DOT...'!E18 -> 0 | H23: ='03-GTHT DOT...'!F18 -> 0 | I23: ='03-GTHT DOT...'!G18 -> 0 | J23: ='03-GTHT DOT...'!H18 -> 0 | K23: ='03-GTHT DOT...'!I18 -> 0 | L23: ='03-GTHT DOT...'!J18 -> 0 | M23: =E23-I23 -> 162.76 | N23: =F23-L23 -> 39159568
A24: 10 | B24: Cốt thép trụ tường | C24: kg | D24: 6030 | E24: 1268.44 | F24: =+E24*D24 -> 7648693.2 | G24: ='03-GTHT DOT...'!E19 -> 0 | H24: ='03-GTHT DOT...'!F19 -> 0 | I24: ='03-GTHT DOT...'!G19 -> 0 | J24: ='03-GTHT DOT...'!H19 -> 0 | K24: ='03-GTHT DOT...'!I19 -> 0 | L24: ='03-GTHT DOT...'!J19 -> 0 | M24: =E24-I24 -> 1268.44 | N24: =F24-L24 -> 7648693.2
A25: 11 | B25: Bê tông trụ tường mác 200# | C25: m3 | D25: 366825 | E25: 8.95 | F25: =+E25*D25 -> 3283083.7 | G25: ='03-GTHT DOT...'!E20 -> 0 | H25: ='03-GTHT DOT...'!F20 -> 0 | I25: ='03-GTHT DOT...'!G20 -> 0 | J25: ='03-GTHT DOT...'!H20 -> 0 | K25: ='03-GTHT DOT...'!I20 -> 0 | L25: ='03-GTHT DOT...'!J20 -> 0 | M25: =E25-I25 -> 8.95 | N25: =F25-L25 -> 3283083.7
A26: 12 | B26: Ván khuôn tấm đan, bậc cấp | C26: m2 | D26: 240597 | E26: 60.88 | F26: =+E26*D26 -> 14647545 | G26: ='03-GTHT DOT...'!E21 -> 0 | H26: ='03-GTHT DOT...'!F21 -> 0 | I26: ='03-GTHT DOT...'!G21 -> 0 | J26: ='03-GTHT DOT...'!H21 -> 0 | K26: ='03-GTHT DOT...'!I21 -> 0 | L26: ='03-GTHT DOT...'!J21 -> 0 | M26: =E26-I26 -> 60.88 | N26: =F26-L26 -> 14647545
... A30: 16 | B30: Chi phí cộng thêm đối với đầu việc ván khuôn bậc tam cấp - tại vị trí ván khuôn thí (ván khuôn chết không luân chuyển được) | C30: m2 | D30: 60000 | E30: 1 | F30: =+E30*D30 -> 60000 | G30: ='03-GTHT DOT...'!E25 -> 0 | H30: ='03-GTHT DOT...'!F25 -> 0 | I30: ='03-GTHT DOT...'!G25 -> 0 | J30: ='03-GTHT DOT...'!H25 -> 0 | K30: ='03-GTHT DOT...'!I25 -> 0 | L30: ='03-GTHT DOT...'!J25 -> 0 | M30: =E30-I30 -> 1 | N30: =F30-L30 -> 60000
A31: II | B31: CÔNG TÁC BÊ TÔNG | G31: ='03-GTHT DOT...'!E26 -> 0 | H31: ='03-GTHT DOT...'!F26 -> 0 | I31: ='03-GTHT DOT...'!G26 -> 0 | J31: ='03-GTHT DOT...'!H26 -> 0 | K31: ='03-GTHT DOT...'!I26 -> 0 | L31: ='03-GTHT DOT...'!J26 -> 0 | M31: =E31-I31 -> 0
A32: 16 | B32: Bê tông sản xuất qua dây chuyền trạm trộn tại hiện trường hoặc thương phẩm, đổ bằng bơm bê tông, bê tông dầm mác M400# | C32: m3 | D32: 366825 | E32: 94.40925 | F32: =+E32*D32 -> 34631673 | G32: ='03-GTHT DOT...'!E27 -> 18.4544 | H32: ='03-GTHT DOT...'!F27 -> 18.172098 | I32: ='03-GTHT DOT...'!G27 -> 36.626498 | J32: ='03-GTHT DOT...'!H27 -> 6769535 | K32: ='03-GTHT DOT...'!I27 -> 6665980 | L32: ='03-GTHT DOT...'!J27 -> 13435515 | M32: =E32-I32 -> 57.782752 | N32: =F32-L32 -> 21196158
A33: 17 | B33: Bê tông sản xuất qua dây chuyền trạm trộn tại hiện trường hoặc thương phẩm, đổ bằng bơm bê tông, bê tông giếng gió mác M400# | C33: m3 | D33: 366825 | E33: 93.24379 | F33: =+E33*D33 -> 34204153 | G33: ='03-GTHT DOT...'!E28 -> 0 | H33: ='03-GTHT DOT...'!F28 -> 13.021151 | I33: ='03-GTHT DOT...'!G28 -> 13.021151 | J33: ='03-GTHT DOT...'!H28 -> 0 | K33: ='03-GTHT DOT...'!I28 -> 4776484 | L33: ='03-GTHT DOT...'!J28 -> 4776484 | M33: =E33-I33 -> 80.222639 | N33: =F33-L33 -> 29427669
A34: 18 | B34: Bê tông sản xuất qua dây chuyền trạm trộn tại hiện trường hoặc thương phẩm, đổ bằng bơm bê tông, bê tông vách bể mác M400# | C34: m3 | D34: 387025 | E34: 439.5078 | F34: =+E34*D34 -> 1.7010051e+08 | G34: ='03-GTHT DOT...'!E29 -> 200.37653 | H34: ='03-GTHT DOT...'!F29 -> 299.2042 | I34: ='03-GTHT DOT...'!G29 -> 499.58074 | J34: ='03-GTHT DOT...'!H29 -> 77550728 | K34: ='03-GTHT DOT...'!I29 -> 115799507 | L34: ='03-GTHT DOT...'!J29 -> 193350235 | M34: =E34-I34 -> -60.072932 | N34: =F34-L34 -> -23249727
A35: 19 | B35: Bê tông sản xuất qua dây chuyền trạm trộn tại hiện trường hoặc thương phẩm, đổ bằng bơm bê tông, bê tông sàn đáy bể mác M400# | C35: m3 | D35: 385007 | E35: 1380.6915 | F35: =+E35*D35 -> 5.3157589e+08 | G35: ='03-GTHT DOT...'!E30 -> 560.80935 | H35: ='03-GTHT DOT...'!F30 -> 312.15609 | I35: ='03-GTHT DOT...'!G30 -> 872.96544 | J35: ='03-GTHT DOT...'!H30 -> 215915524 | K35: ='03-GTHT DOT...'!I30 -> 120182280 | L35: ='03-GTHT DOT...'!J30 -> 336097804 | M35: =E35-I35 -> 507.72606 | N35: =F35-L35 -> 1.9547809e+08
A36: 20 | B36: Bê tông rãnh thoát nước B200 mác M400# | C36: m3 | D36: 366825 | E36: 56.26125 | F36: =+E36*D36 -> 20638033 | G36: ='03-GTHT DOT...'!E31 -> 0 | H36: ='03-GTHT DOT...'!F31 -> 0 | I36: ='03-GTHT DOT...'!G31 -> 0 | J36: ='03-GTHT DOT...'!H31 -> 0 | K36: ='03-GTHT DOT...'!I31 -> 0 | L36: ='03-GTHT DOT...'!J31 -> 0 | M36: =E36-I36 -> 56.26125 | N36: =F36-L36 -> 20638033
A37: III | B37: CÔNG TÁC VÁN KHUÔN | G37: ='03-GTHT DOT...'!E32 -> 0 | H37: ='03-GTHT DOT...'!F32 -> 0 | I37: ='03-GTHT DOT...'!G32 -> 0 | J37: ='03-GTHT DOT...'!H32 -> 0 | K37: ='03-GTHT DOT...'!I32 -> 0 | L37: ='03-GTHT DOT...'!J32 -> 0 | M37: =E37-I37 -> 0
A38: 21 | B38: Ván khuôn dầm bể | C38: m2 | D38: 240597 | E38: 629.395 | F38: =+E38*D38 -> 1.5143055e+08 | G38: ='03-GTHT DOT...'!E33 -> 12.302847 | H38: ='03-GTHT DOT...'!F33 -> 145.9326 | I38: ='03-GTHT DOT...'!G33 -> 158.23545 | J38: ='03-GTHT DOT...'!H33 -> 2960028 | K38: ='03-GTHT DOT...'!I33 -> 35110946 | L38: ='03-GTHT DOT...'!J33 -> 38070974 | M38: =E38-I38 -> 471.15955 | N38: =F38-L38 -> 1.1335957e+08
A39: 22 | B39: Ván khuôn giếng gió | C39: m2 | D39: 240597 | E39: 1062.1026 | F39: =+E39*D39 -> 2.555387e+08 | G39: ='03-GTHT DOT...'!E34 -> 0 | H39: ='03-GTHT DOT...'!F34 -> 118.3741 | I39: ='03-GTHT DOT...'!G34 -> 118.3741 | J39: ='03-GTHT DOT...'!H34 -> 0 | K39: ='03-GTHT DOT...'!I34 -> 28480453 | L39: ='03-GTHT DOT...'!J34 -> 28480453 | M39: =E39-I39 -> 943.7285 | N39: =F39-L39 -> 2.2705825e+08
A40: 23 | B40: Ván khuôn vách bể | C40: m2 | D40: 240597 | E40: 609.1374 | F40: =+E40*D40 -> 1.4655663e+08 | G40: ='03-GTHT DOT...'!E35 -> 0 | H40: ='03-GTHT DOT...'!F35 -> 1401.112 | I40: ='03-GTHT DOT...'!G35 -> 1401.112 | J40: ='03-GTHT DOT...'!H35 -> 0 | K40: ='03-GTHT DOT...'!I35 -> 337103339 | L40: ='03-GTHT DOT...'!J35 -> 337103339 | M40: =E40-I40 -> -791.97458 | N40: =F40-L40 -> -1.9054671e+08
A41: 24 | B41: Ván khuôn cong vách bể | C41: m2 | D41: 276777 | E41: 2657.9397 | F41: =+E41*D41 -> 7.3565659e+08 | G41: ='03-GTHT DOT...'!E36 -> 1494.7809 | H41: ='03-GTHT DOT...'!F36 -> 1133.9824 | I41: ='03-GTHT DOT...'!G36 -> 2628.7633 | J41: ='03-GTHT DOT...'!H36 -> 413720982 | K41: ='03-GTHT DOT...'!I36 -> 313860247 | L41: ='03-GTHT DOT...'!J36 -> 727581229 | M41: =E41-I41 -> 29.176417 | N41: =F41-L41 -> 8075361.2
A42: 25 | B42: Ván khuôn sàn đáy bể | C42: m2 | D42: 240597 | E42: 8103.3649 | F42: =+E42*D42 -> 1.9496453e+09 | G42: ='03-GTHT DOT...'!E37 -> 2723.6891 | H42: ='03-GTHT DOT...'!F37 -> 936.2513 | I42: ='03-GTHT DOT...'!G37 -> 3659.9404 | J42: ='03-GTHT DOT...'!H37 -> 655311423 | K42: ='03-GTHT DOT...'!I37 -> 225259254 | L42: ='03-GTHT DOT...'!J37 -> 880570677 | M42: =E42-I42 -> 4443.4245 | N42: =F42-L42 -> 1.0690746e+09
A43: 26 | B43: Ván khuôn rãnh thoát nước B200 | C43: m2 | D43: 240597 | E43: 520.9375 | F43: =+E43*D43 -> 1.25336e+08 | G43: ='03-GTHT DOT...'!E38 -> 0 | H43: ='03-GTHT DOT...'!F38 -> 0 | I43: ='03-GTHT DOT...'!G38 -> 0 | J43: ='03-GTHT DOT...'!H38 -> 0 | K43: ='03-GTHT DOT...'!I38 -> 0 | L43: ='03-GTHT DOT...'!J38 -> 0 | M43: =E43-I43 -> 520.9375 | N43: =F43-L43 -> 1.25336e+08
A44: 27 | B44: Chi phí cộng thêm đối với đầu việc ván khuôn bậc sàn đáy bể tại vị trí ván khuôn thí (ván khuôn chết không luân chuyển được) | C44: m2 | D44: 60000 | E44: 1 | F44: =+E44*D44 -> 60000 | G44: ='03-GTHT DOT...'!E39 -> 0 | H44: ='03-GTHT DOT...'!F39 -> 928.0593 | I44: ='03-GTHT DOT...'!G39 -> 928.0593 | J44: ='03-GTHT DOT...'!H39 -> 0 | K44: ='03-GTHT DOT...'!I39 -> 55683558 | L44: ='03-GTHT DOT...'!J39 -> 55683558 | M44: =E44-I44 -> -927.0593 | N44: =F44-L44 -> -55623558
A45: IV | B45: CÔNG TÁC CỐT THÉP | G45: ='03-GTHT DOT...'!E40 -> 0 | H45: ='03-GTHT DOT...'!F40 -> 0 | I45: ='03-GTHT DOT...'!G40 -> 0 | J45: ='03-GTHT DOT...'!H40 -> 0 | K45: ='03-GTHT DOT...'!I40 -> 0 | L45: ='03-GTHT DOT...'!J40 -> 0 | M45: =E45-I45 -> 0
A46: 26 | B46: Cốt thép dầm bể | C46: kg | D46: 6030 | E46: 12273.202 | F46: =+E46*D46 -> 74007411 | G46: ='03-GTHT DOT...'!E41 -> 7418.0994 | H46: ='03-GTHT DOT...'!F41 -> 3724.2575 | I46: ='03-GTHT DOT...'!G41 -> 11142.357 | J46: ='03-GTHT DOT...'!H41 -> 44731140 | K46: ='03-GTHT DOT...'!I41 -> 22457273 | L46: ='03-GTHT DOT...'!J41 -> 67188413 | M46: =E46-I46 -> 1130.8456 | N46: =F46-L46 -> 6818998.1 | P46: 300 | Q46: =P46*D46 -> 1809000
A47: 28 | B47: Cốt thép giếng gió | C47: kg | D47: 6030 | E47: 7832.4784 | F47: =+E47*D47 -> 47229845 | G47: ='03-GTHT DOT...'!E42 -> 0 | H47: ='03-GTHT DOT...'!F42 -> 800.76072 | I47: ='03-GTHT DOT...'!G42 -> 800.76072 | J47: ='03-GTHT DOT...'!H42 -> 0 | K47: ='03-GTHT DOT...'!I42 -> 4828587 | L47: ='03-GTHT DOT...'!J42 -> 4828587 | M47: =E47-I47 -> 7031.7176 | N47: =F47-L47 -> 42401258
...

Sheet 02.2 ĐNTT
A2: ='02.1-ĐNTT'!A2:N2 -> Dự án: Dự án đầu tư xây dựng nhà ở cao tầng kết hợp thương mại dịch vụ và nhà ở thấp tầng Sunshine Crystal River
A3: ĐỀ NGHỊ THANH TOÁN THEO KÌ
B5: ='02.1-ĐNTT'!B5:D6 -> Thầu phụ: Công ty Cổ phần Đầu tư Xây dựng Hoàng Long Group | F5: ='02.1-ĐNTT'!E5 -> Hợp đồng số: 21/2025/CT01/SM-HL | J5: Địa điểm thi công: | K5: ='02.1-ĐNTT'!K5:N6 -> Ô đất CT01-CT và CT01-TT (được điều chỉnh từ ô đất CT01) thuộc Khu đô thị Nam Thăng Long, giai đoạn III, Phường Phú Thượng, Quận Tây Hồ, Hà Nội
B6: ='02.1-ĐNTT'!B7 -> Chủ thẻ: Công ty Cổ phần Đầu tư Xây dựng Hoàng Long Group | F6: ='02.1-ĐNTT'!E7 -> Ngân hàng: TMCP Tiên Phong - Chi nhánh Đống Đa | J6: Thanh toán lần : | K6: ='02.1-ĐNTT'!K7 -> 02
B7: ='02.1-ĐNTT'!B8 -> Số tài khoản: 00083589003 | J7: Đơn vị tính: vnđ
K8: Hà Nội, ngày …... tháng …... năm 2025
A9: Giá trị hợp đồng + PLHĐ [1] = [1.1]+[1.2] + …. | E9: =E10+E11 -> 1.5892608e+10
A10: Giá trị HĐ gốc [1.1] | E10: ='02.1-ĐNTT'!F155 -> 1.5892608e+10
A11: Giá trị PLHĐ số …. [1.2] | E11: =0 -> 0
A12: Giá trị tạm ứng HĐ + PLHĐ [2] = [2.1] + [2.2] + …. | E12: =E13+E14 -> 3178521623
A13: Giá trị tạm ứng HĐ [2.1] | E13: =ROUND(E10*20%,0) -> 3178521623
A14: Giá trị tạm ứng PLHĐ số ….. [2.2] | E14: 0
A15: Giá trị tạm ứng vật tư [3] | E15: 0
A16: Lũy kế giá trị nghiệm thu đến nay [4] | E16: ='02.1-ĐNTT'!L155 -> 3.9156542e+09
A17: Giá trị nghiệm thu kỳ này [5] | E17: ='02.1-ĐNTT'!K155 -> 1767478295
A18: Giá trị hoàn thành kỳ này theo HĐ [5A] | E18: ='02.1-ĐNTT'!K155 -> 1767478295
A19: Giá trị hoàn thành kỳ này theo PLHĐ [5B] | E19: 0
A20: Lũy kế giá trị đã duyệt các kỳ trước [6] = [7]+[8]+[9]+[10]+[11] | E20: =E21+E22+E23+E24+E25 -> 1307099570
B21: - Lũy kế giá trị ĐNTT [7] | E21: 1307099570
B22: - Lũy kế tạm giữ vật tư [8] | E22: 0
B23: - Lũy kế trừ BHLĐ [9] | E23: 0
B24: - Lũy kế trừ khác [10] | E24: 0 | G24: Giá trị trừ kỳ này [17]=[17a]+[17b]+[17c]+[17d]
B25: - Còn nợ kỳ trước chưa bao gồm BL [11] | E25: 0 | G25: (Không bao gồm bảo lưu)
A26: Lũy kế bảo lưu 10% đến nay [12] = [4]*10% | E26: =ROUND(E16*10%,0) -> 391565419 | G26: - Trừ vật tư kỳ này [17a] | K26: 0
A27: Lũy kế thu hồi tạm ứng đến nay [13] =[4]*[2]/{[1]*0.8} | E27: =ROUND(E16*E12/(E9*0.8),0) -> 978913547 | G27: - Trừ BHLĐ kỳ này [17b] | K27: 0
A28: Lũy kế thu hồi tạm ứng vật tư [14] = [….] | E28: 0 | G28: - Tạm giữ kỳ này [17c] | J28: =+'đối trừ đợt 2'!J26 -> 19363984
A29: [15] = [6]+[12]+[13]+[14] | E29: =E20+E26+E27+E28 -> 2677578536 | G29: - Trừ khác kỳ này [17d] | J29: 0 | P29: 1.3385996e+09
A30: Giá trị thanh toán kỳ này (chưa trừ) [16] = [4-15] | E30: =E16-E29 -> 1.2380757e+09 | G30: Giá trị thanh toán kỳ này [18]= [16] - [17] | J30: =E30-J24 -> 1.2380757e+09 | L30: đồng | O30: 1382840607 | Q30: 1.247323e+09
B32: Bằng chữ:
B33: BÊN NHẬN THẦU | G33: PHỤ TRÁCH BAN ĐIỀU HÀNH DỰ ÁN | K33: BÊN GIAO THẦU | O33: =E16*0.65 -> 2.5451752e+09

Sheet 03-GTHT DOT...
A2: CÔNG TRÌNH: THI CÔNG KẾT CẤU, CHỐNG THẤM CẢNH QUAN NGOÀI NHÀ KHU VỰC CAO TẦNG
A3: BẢNG TỔNG HỢP GIÁ TRỊ KHỐI LƯỢNG HOÀN THÀNH THEO HỢP ĐỒNG
A5: Stt | B5: Nội dung | C5: Đơn vị | D5: Đơn giá | E5: Khối lượng nghiệm thu | H5: Giá trị nghiệm thu | K5: Ghi chú
E6: Luỹ kế kỳ trước | F6: Kỳ này | G6: Lũy kế đến nay | H6: Luỹ kế kỳ trước | I6: Kỳ này | J6: Lũy kế đến nay
B7: ='02.1-ĐNTT'!B12 -> HĐ số 21/2025/CT01/SM-HL
A8: ='02.1-ĐNTT'!A13 -> * | B8: ='02.1-ĐNTT'!B13 -> HẠNG MỤC: THI CÔNG KẾT CẤU CẢNH QUAN NGOÀI NHÀ KHU VỰC CAO TẦNG
A9: ='02.1-ĐNTT'!A14 -> I | B9: ='02.1-ĐNTT'!B14 -> CÔNG TÁC XÂY
A10: ='02.1-ĐNTT'!A15 -> 1 | B10: ='02.1-ĐNTT'!B15 -> Xây tường gạch đặc, chiều dày >330mm, VXM mác 75 | C10: ='02.1-ĐNTT'!C15 -> m3 | D10: ='02.1-ĐNTT'!D15 -> 2275030 | E10: 0 | F10: ='04-THKL DOT...'!F15 -> 0 | G10: =E10+F10 -> 0 | H10: =ROUND($D10*E10,0) -> 0 | I10: =ROUND($D10*F10,0) -> 0 | J10: =H10+I10 -> 0
A11: ='02.1-ĐNTT'!A16 -> 2 | B11: ='02.1-ĐNTT'!B16 -> Xây tường gạch đặc, chiều dày <=330mm, VXM mác 75 | C11: ='02.1-ĐNTT'!C16 -> m3 | D11: ='02.1-ĐNTT'!D16 -> 2275030 | E11: 0 | F11: ='04-THKL DOT...'!F16 -> 0 | G11: =E11+F11 -> 0 | H11: =ROUND($D11*E11,0) -> 0 | I11: =ROUND($D11*F11,0) -> 0 | J11: =H11+I11 -> 0
A12: ='02.1-ĐNTT'!A17 -> 3 | B12: ='02.1-ĐNTT'!B17 -> Xây tường gạch đặc, chiều dày <=110mm, VXM mác 75 | C12: ='02.1-ĐNTT'!C17 -> m3 | D12: ='02.1-ĐNTT'!D17 -> 2335944 | E12: 0 | F12: ='04-THKL DOT...'!F17 -> 0 | G12: =E12+F12 -> 0 | H12: =ROUND($D12*E12,0) -> 0 | I12: =ROUND($D12*F12,0) -> 0 | J12: =H12+I12 -> 0
A13: ='02.1-ĐNTT'!A18 -> 4 | B13: ='02.1-ĐNTT'!B18 -> Xây cột, trụ, gạch đặc, VXM mác 75 | C13: ='02.1-ĐNTT'!C18 -> m3 | D13: ='02.1-ĐNTT'!D18 -> 2572168 | E13: 0 | F13: ='04-THKL DOT...'!F18 -> 0 | G13: =E13+F13 -> 0 | H13: =ROUND($D13*E13,0) -> 0 | I13: =ROUND($D13*F13,0) -> 0 | J13: =H13+I13 -> 0
A14: ='02.1-ĐNTT'!A19 -> 5 | B14: ='02.1-ĐNTT'!B19 -> Ván khuôn giằng tường | C14: ='02.1-ĐNTT'!C19 -> m2 | D14: ='02.1-ĐNTT'!D19 -> 240597 | E14: 0 | F14: ='04-THKL DOT...'!F19 -> 0 | G14: =E14+F14 -> 0 | H14: =ROUND($D14*E14,0) -> 0 | I14: =ROUND($D14*F14,0) -> 0 | J14: =H14+I14 -> 0
A15: ='02.1-ĐNTT'!A20 -> 6 | B15: ='02.1-ĐNTT'!B20 -> Cốt thép giằng tường | C15: ='02.1-ĐNTT'!C20 -> kg | D15: ='02.1-ĐNTT'!D20 -> 6030 | E15: 0 | F15: ='04-THKL DOT...'!F20 -> 0 | G15: =E15+F15 -> 0 | H15: =ROUND($D15*E15,0) -> 0 | I15: =ROUND($D15*F15,0) -> 0 | J15: =H15+I15 -> 0
A16: ='02.1-ĐNTT'!A21 -> 7 | B16: ='02.1-ĐNTT'!B21 -> Bê tông giằng tường mác 200# | C16: ='02.1-ĐNTT'!C21 -> m3 | D16: ='02.1-ĐNTT'!D21 -> 366825 | E16: 0 | F16: ='04-THKL DOT...'!F21 -> 0 | G16: =E16+F16 -> 0 | H16: =ROUND($D16*E16,0) -> 0 | I16: =ROUND($D16*F16,0) -> 0 | J16: =H16+I16 -> 0
A17: ='02.1-ĐNTT'!A22 -> 8 | B17: ='02.1-ĐNTT'!B22 -> Khoan cấy cốt thép, đường kính thép D14 | C17: ='02.1-ĐNTT'!C22 -> vị trí | D17: ='02.1-ĐNTT'!D22 -> 27600 | E17: 0 | F17: ='04-THKL DOT...'!F22 -> 0 | G17: =E17+F17 -> 0 | H17: =ROUND($D17*E17,0) -> 0 | I17: =ROUND($D17*F17,0) -> 0 | J17: =H17+I17 -> 0
A18: ='02.1-ĐNTT'!A23 -> 9 | B18: ='02.1-ĐNTT'!B23 -> Ván khuôn trụ tường | C18: ='02.1-ĐNTT'!C23 -> m2 | D18: ='02.1-ĐNTT'!D23 -> 240597 | E18: 0 | F18: ='04-THKL DOT...'!F23 -> 0 | G18: =E18+F18 -> 0 | H18: =ROUND($D18*E18,0) -> 0 | I18: =ROUND($D18*F18,0) -> 0 | J18: =H18+I18 -> 0
A19: ='02.1-ĐNTT'!A24 -> 10 | B19: ='02.1-ĐNTT'!B24 -> Cốt thép trụ tường | C19: ='02.1-ĐNTT'!C24 -> kg | D19: ='02.1-ĐNTT'!D24 -> 6030 | E19: 0 | F19: ='04-THKL DOT...'!F24 -> 0 | G19: =E19+F19 -> 0 | H19: =ROUND($D19*E19,0) -> 0 | I19: =ROUND($D19*F19,0) -> 0 | J19: =H19+I19 -> 0
A20: ='02.1-ĐNTT'!A25 -> 11 | B20: ='02.1-ĐNTT'!B25 -> Bê tông trụ tường mác 200# | C20: ='02.1-ĐNTT'!C25 -> m3 | D20: ='02.1-ĐNTT'!D25 -> 366825 | E20: 0 | F20: ='04-THKL DOT...'!F25 -> 0 | G20: =E20+F20 -> 0 | H20: =ROUND($D20*E20,0) -> 0 | I20: =ROUND($D20*F20,0) -> 0 | J20: =H20+I20 -> 0
A21: ='02.1-ĐNTT'!A26 -> 12 | B21: ='02.1-ĐNTT'!B26 -> Ván khuôn tấm đan, bậc cấp | C21: ='02.1-ĐNTT'!C26 -> m2 | D21: ='02.1-ĐNTT'!D26 -> 240597 | E21: 0 | F21: ='04-THKL DOT...'!F26 -> 0 | G21: =E21+F21 -> 0 | H21: =ROUND($D21*E21,0) -> 0 | I21: =ROUND($D21*F21,0) -> 0 | J21: =H21+I21 -> 0
... A25: ='02.1-ĐNTT'!A30 -> 16 | B25: ='02.1-ĐNTT'!B30 -> Chi phí cộng thêm đối với đầu việc ván khuôn bậc tam cấp - tại vị trí ván khuôn thí (ván khuôn chết không luân chuyển được) | C25: ='02.1-ĐNTT'!C30 -> m2 | D25: ='02.1-ĐNTT'!D30 -> 60000 | E25: 0 | F25: ='04-THKL DOT...'!F30 -> 0 | G25: =E25+F25 -> 0 | H25: =ROUND($D25*E25,0) -> 0 | I25: =ROUND($D25*F25,0) -> 0 | J25: =H25+I25 -> 0
A26: ='02.1-ĐNTT'!A31 -> II | B26: ='02.1-ĐNTT'!B31 -> CÔNG TÁC BÊ TÔNG | D26: ='02.1-ĐNTT'!D31 -> 0 | E26: 0 | F26: ='04-THKL DOT...'!F31 -> 0 | G26: =E26+F26 -> 0 | H26: =ROUND($D26*E26,0) -> 0 | I26: =ROUND($D26*F26,0) -> 0 | J26: =H26+I26 -> 0
A27: ='02.1-ĐNTT'!A32 -> 16 | B27: ='02.1-ĐNTT'!B32 -> Bê tông sản xuất qua dây chuyền trạm trộn tại hiện trường hoặc thương phẩm, đổ bằng bơm bê tông, bê tông dầm mác M400# | C27: ='02.1-ĐNTT'!C32 -> m3 | D27: ='02.1-ĐNTT'!D32 -> 366825 | E27: 18.4544 | F27: ='04-THKL DOT...'!F32 -> 18.172098 | G27: =E27+F27 -> 36.626498 | H27: =ROUND($D27*E27,0) -> 6769535 | I27: =ROUND($D27*F27,0) -> 6665980 | J27: =H27+I27 -> 13435515
A28: ='02.1-ĐNTT'!A33 -> 17 | B28: ='02.1-ĐNTT'!B33 -> Bê tông sản xuất qua dây chuyền trạm trộn tại hiện trường hoặc thương phẩm, đổ bằng bơm bê tông, bê tông giếng gió mác M400# | C28: ='02.1-ĐNTT'!C33 -> m3 | D28: ='02.1-ĐNTT'!D33 -> 366825 | E28: 0 | F28: ='04-THKL DOT...'!F33 -> 13.021151 | G28: =E28+F28 -> 13.021151 | H28: =ROUND($D28*E28,0) -> 0 | I28: =ROUND($D28*F28,0) -> 4776484 | J28: =H28+I28 -> 4776484
A29: ='02.1-ĐNTT'!A34 -> 18 | B29: ='02.1-ĐNTT'!B34 -> Bê tông sản xuất qua dây chuyền trạm trộn tại hiện trường hoặc thương phẩm, đổ bằng bơm bê tông, bê tông vách bể mác M400# | C29: ='02.1-ĐNTT'!C34 -> m3 | D29: ='02.1-ĐNTT'!D34 -> 387025 | E29: 200.37653 | F29: ='04-THKL DOT...'!F34 -> 299.2042 | G29: =E29+F29 -> 499.58074 | H29: =ROUND($D29*E29,0) -> 77550728 | I29: =ROUND($D29*F29,0) -> 115799507 | J29: =H29+I29 -> 193350235
A30: ='02.1-ĐNTT'!A35 -> 19 | B30: ='02.1-ĐNTT'!B35 -> Bê tông sản xuất qua dây chuyền trạm trộn tại hiện trường hoặc thương phẩm, đổ bằng bơm bê tông, bê tông sàn đáy bể mác M400# | C30: ='02.1-ĐNTT'!C35 -> m3 | D30: ='02.1-ĐNTT'!D35 -> 385007 | E30: 560.80935 | F30: ='04-THKL DOT...'!F35 -> 312.15609 | G30: =E30+F30 -> 872.96544 | H30: =ROUND($D30*E30,0) -> 215915524 | I30: =ROUND($D30*F30,0) -> 120182280 | J30: =H30+I30 -> 336097804
A31: ='02.1-ĐNTT'!A36 -> 20 | B31: ='02.1-ĐNTT'!B36 -> Bê tông rãnh thoát nước B200 mác M400# | C31: ='02.1-ĐNTT'!C36 -> m3 | D31: ='02.1-ĐNTT'!D36 -> 366825 | E31: 0 | F31: ='04-THKL DOT...'!F36 -> 0 | G31: =E31+F31 -> 0 | H31: =ROUND($D31*E31,0) -> 0 | I31: =ROUND($D31*F31,0) -> 0 | J31: =H31+I31 -> 0
A32: ='02.1-ĐNTT'!A37 -> III | B32: ='02.1-ĐNTT'!B37 -> CÔNG TÁC VÁN KHUÔN | C32: ='02.1-ĐNTT'!C37 -> 0 | D32: ='02.1-ĐNTT'!D37 -> 0 | E32: 0 | F32: ='04-THKL DOT...'!F37 -> 0 | G32: =E32+F32 -> 0 | H32: =ROUND($D32*E32,0) -> 0 | I32: =ROUND($D32*F32,0) -> 0 | J32: =H32+I32 -> 0
A33: ='02.1-ĐNTT'!A38 -> 21 | B33: ='02.1-ĐNTT'!B38 -> Ván khuôn dầm bể | C33: ='02.1-ĐNTT'!C38 -> m2 | D33: ='02.1-ĐNTT'!D38 -> 240597 | E33: 12.302847 | F33: ='04-THKL DOT...'!F38 -> 145.9326 | G33: =E33+F33 -> 158.23545 | H33: =ROUND($D33*E33,0) -> 2960028 | I33: =ROUND($D33*F33,0) -> 35110946 | J33: =H33+I33 -> 38070974
A34: ='02.1-ĐNTT'!A39 -> 22 | B34: ='02.1-ĐNTT'!B39 -> Ván khuôn giếng gió | C34: ='02.1-ĐNTT'!C39 -> m2 | D34: ='02.1-ĐNTT'!D39 -> 240597 | E34: 0 | F34: ='04-THKL DOT...'!F39 -> 118.3741 | G34: =E34+F34 -> 118.3741 | H34: =ROUND($D34*E34,0) -> 0 | I34: =ROUND($D34*F34,0) -> 28480453 | J34: =H34+I34 -> 28480453
A35: ='02.1-ĐNTT'!A40 -> 23 | B35: ='02.1-ĐNTT'!B40 -> Ván khuôn vách bể | C35: ='02.1-ĐNTT'!C40 -> m2 | D35: ='02.1-ĐNTT'!D40 -> 240597 | E35: 0 | F35: ='04-THKL DOT...'!F40 -> 1401.112 | G35: =E35+F35 -> 1401.112 | H35: =ROUND($D35*E35,0) -> 0 | I35: =ROUND($D35*F35,0) -> 337103339 | J35: =H35+I35 -> 337103339
A36: ='02.1-ĐNTT'!A41 -> 24 | B36: ='02.1-ĐNTT'!B41 -> Ván khuôn cong vách bể | C36: ='02.1-ĐNTT'!C41 -> m2 | D36: ='02.1-ĐNTT'!D41 -> 276777 | E36: 1494.7809 | F36: ='04-THKL DOT...'!F41 -> 1133.9824 | G36: =E36+F36 -> 2628.7633 | H36: =ROUND($D36*E36,0) -> 413720982 | I36: =ROUND($D36*F36,0) -> 313860247 | J36: =H36+I36 -> 727581229
A37: ='02.1-ĐNTT'!A42 -> 25 | B37: ='02.1-ĐNTT'!B42 -> Ván khuôn sàn đáy bể | C37: ='02.1-ĐNTT'!C42 -> m2 | D37: ='02.1-ĐNTT'!D42 -> 240597 | E37: 2723.6891 | F37: ='04-THKL DOT...'!F42 -> 936.2513 | G37: =E37+F37 -> 3659.9404 | H37: =ROUND($D37*E37,0) -> 655311423 | I37: =ROUND($D37*F37,0) -> 225259254 | J37: =H37+I37 -> 880570677
A38: ='02.1-ĐNTT'!A43 -> 26 | B38: ='02.1-ĐNTT'!B43 -> Ván khuôn rãnh thoát nước B200 | C38: ='02.1-ĐNTT'!C43 -> m2 | D38: ='02.1-ĐNTT'!D43 -> 240597 | E38: 0 | F38: ='04-THKL DOT...'!F43 -> 0 | G38: =E38+F38 -> 0 | H38: =ROUND($D38*E38,0) -> 0 | I38: =ROUND($D38*F38,0) -> 0 | J38: =H38+I38 -> 0
A39: ='02.1-ĐNTT'!A44 -> 27 | B39: ='02.1-ĐNTT'!B44 -> Chi phí cộng thêm đối với đầu việc ván khuôn bậc sàn đáy bể tại vị trí ván khuôn thí (ván khuôn chết không luân chuyển được) | C39: ='02.1-ĐNTT'!C44 -> m2 | D39: ='02.1-ĐNTT'!D44 -> 60000 | E39: 0 | F39: ='04-THKL DOT...'!F44 -> 928.0593 | G39: =E39+F39 -> 928.0593 | H39: =ROUND($D39*E39,0) -> 0 | I39: =ROUND($D39*F39,0) -> 55683558 | J39: =H39+I39 -> 55683558
A40: ='02.1-ĐNTT'!A45 -> IV | B40: ='02.1-ĐNTT'!B45 -> CÔNG TÁC CỐT THÉP | D40: ='02.1-ĐNTT'!D45 -> 0 | E40: 0 | F40: ='04-THKL DOT...'!F45 -> 0 | G40: =E40+F40 -> 0 | H40: =ROUND($D40*E40,0) -> 0 | I40: =ROUND($D40*F40,0) -> 0 | J40: =H40+I40 -> 0
A41: ='02.1-ĐNTT'!A46 -> 26 | B41: ='02.1-ĐNTT'!B46 -> Cốt thép dầm bể | C41: ='02.1-ĐNTT'!C46 -> kg | D41: ='02.1-ĐNTT'!D46 -> 6030 | E41: 7418.0994 | F41: ='04-THKL DOT...'!F46 -> 3724.2575 | G41: =E41+F41 -> 11142.357 | H41: =ROUND($D41*E41,0) -> 44731140 | I41: =ROUND($D41*F41,0) -> 22457273 | J41: =H41+I41 -> 67188413
A42: ='02.1-ĐNTT'!A47 -> 28 | B42: ='02.1-ĐNTT'!B47 -> Cốt thép giếng gió | C42: ='02.1-ĐNTT'!C47 -> kg | D42: ='02.1-ĐNTT'!D47 -> 6030 | E42: 0 | F42: ='04-THKL DOT...'!F47 -> 800.76072 | G42: =E42+F42 -> 800.76072 | H42: =ROUND($D42*E42,0) -> 0 | I42: =ROUND($D42*F42,0) -> 4828587 | J42: =H42+I42 -> 4828587
A43: ='02.1-ĐNTT'!A48 -> 29 | B43: ='02.1-ĐNTT'!B48 -> Cốt thép vách bể | C43: ='02.1-ĐNTT'!C48 -> kg | D43: ='02.1-ĐNTT'!D48 -> 6030 | E43: 21402.252 | F43: ='04-THKL DOT...'!F48 -> 22007.775 | G43: =E43+F43 -> 43410.027 | H43: =ROUND($D43*E43,0) -> 129055579 | I43: =ROUND($D43*F43,0) -> 132706882 | J43: =H43+I43 -> 261762461
A44: ='02.1-ĐNTT'!A49 -> 30 | B44: ='02.1-ĐNTT'!B49 -> Cốt thép sàn đáy bể | C44: ='02.1-ĐNTT'!C49 -> kg | D44: ='02.1-ĐNTT'!D49 -> 6030 | E44: 71287.937 | F44: ='04-THKL DOT...'!F49 -> 34821.641 | G44: =E44+F44 -> 106109.58 | H44: =ROUND($D44*E44,0) -> 429866260 | I44: =ROUND($D44*F44,0) -> 209974496 | J44: =H44+I44 -> 639840756
A45: ='02.1-ĐNTT'!A50 -> 31 | B45: ='02.1-ĐNTT'!B50 -> Cốt thép rãnh thoát nước | C45: ='02.1-ĐNTT'!C50 -> kg | D45: ='02.1-ĐNTT'!D50 -> 6030 | E45: 0 | F45: ='04-THKL DOT...'!F50 -> 0 | G45: =E45+F45 -> 0 | H45: =ROUND($D45*E45,0) -> 0 | I45: =ROUND($D45*F45,0) -> 0 | J45: =H45+I45 -> 0
...

Sheet 04-THKL DOT...
A2: BẢNG TỔNG HỢP KHỐI LƯỢNG HOÀN THÀNH THẦU PHỤ ĐÃ THỰC HIỆN LUỸ KẾ
B4: Dự án : | C4: Sunshine Crystal River | F4: Số trang:
B5: Gói thầu: | C5: Thi công kết cấu, chống thấm cảnh quan ngoài nhà khu vực cao tầng | F5: Tổng trang:
B6: Nhà/ Block :
B7: Khu vực :
B8: Tên nhà thầu phụ : | C8: Công ty Cổ phần Đầu tư Xây dựng Hoàng Long Group
A9: Stt | B9: Nội dung công việc/ Khu vực/vị trí thực hiện | C9: Đơn vị | D9: Tổng khối lượng thực hiện | E9: Tỷ lệ lên hồ sơ thanh toán | F9: Khối lượng nghiệm thu | G9: Ghi chú
A11: (1) | B11: (2) | C11: (3) | D11: (4) | E11: (5) | F11: (6)=(4)*(5) | G11: (7)
B12: ='02.1-ĐNTT'!B12 -> HĐ số 21/2025/CT01/SM-HL
A13: ='02.1-ĐNTT'!A13 -> * | B13: ='02.1-ĐNTT'!B13 -> HẠNG MỤC: THI CÔNG KẾT CẤU CẢNH QUAN NGOÀI NHÀ KHU VỰC CAO TẦNG
A14: ='02.1-ĐNTT'!A14 -> I | B14: ='02.1-ĐNTT'!B14 -> CÔNG TÁC XÂY
A15: ='02.1-ĐNTT'!A15 -> 1 | B15: ='02.1-ĐNTT'!B15 -> Xây tường gạch đặc, chiều dày >330mm, VXM mác 75 | C15: ='02.1-ĐNTT'!C15 -> m3 | D15: ='CTKL DOT...'!K12 -> 0 | E15: 0 | F15: =D15*E15 -> 0
A16: ='02.1-ĐNTT'!A16 -> 2 | B16: ='02.1-ĐNTT'!B16 -> Xây tường gạch đặc, chiều dày <=330mm, VXM mác 75 | C16: ='02.1-ĐNTT'!C16 -> m3 | D16: ='CTKL DOT...'!K13 -> 0 | E16: 0 | F16: =D16*E16 -> 0
A17: ='02.1-ĐNTT'!A17 -> 3 | B17: ='02.1-ĐNTT'!B17 -> Xây tường gạch đặc, chiều dày <=110mm, VXM mác 75 | C17: ='02.1-ĐNTT'!C17 -> m3 | D17: ='CTKL DOT...'!K14 -> 0 | E17: 0 | F17: =D17*E17 -> 0
A18: ='02.1-ĐNTT'!A18 -> 4 | B18: ='02.1-ĐNTT'!B18 -> Xây cột, trụ, gạch đặc, VXM mác 75 | C18: ='02.1-ĐNTT'!C18 -> m3 | D18: ='CTKL DOT...'!K15 -> 0 | E18: 0 | F18: =D18*E18 -> 0
A19: ='02.1-ĐNTT'!A19 -> 5 | B19: ='02.1-ĐNTT'!B19 -> Ván khuôn giằng tường | C19: ='02.1-ĐNTT'!C19 -> m2 | D19: ='CTKL DOT...'!K16 -> 0 | E19: 0 | F19: =D19*E19 -> 0
A20: ='02.1-ĐNTT'!A20 -> 6 | B20: ='02.1-ĐNTT'!B20 -> Cốt thép giằng tường | C20: ='02.1-ĐNTT'!C20 -> kg | D20: ='CTKL DOT...'!K17 -> 0 | E20: 0 | F20: =D20*E20 -> 0
A21: ='02.1-ĐNTT'!A21 -> 7 | B21: ='02.1-ĐNTT'!B21 -> Bê tông giằng tường mác 200# | C21: ='02.1-ĐNTT'!C21 -> m3 | D21: ='CTKL DOT...'!K18 -> 0 | E21: 0 | F21: =D21*E21 -> 0
A22: ='02.1-ĐNTT'!A22 -> 8 | B22: ='02.1-ĐNTT'!B22 -> Khoan cấy cốt thép, đường kính thép D14 | C22: ='02.1-ĐNTT'!C22 -> vị trí | D22: ='CTKL DOT...'!K19 -> 0 | E22: 0 | F22: =D22*E22 -> 0
A23: ='02.1-ĐNTT'!A23 -> 9 | B23: ='02.1-ĐNTT'!B23 -> Ván khuôn trụ tường | C23: ='02.1-ĐNTT'!C23 -> m2 | D23: ='CTKL DOT...'!K20 -> 0 | E23: 0 | F23: =D23*E23 -> 0
A24: ='02.1-ĐNTT'!A24 -> 10 | B24: ='02.1-ĐNTT'!B24 -> Cốt thép trụ tường | C24: ='02.1-ĐNTT'!C24 -> kg | D24: ='CTKL DOT...'!K21 -> 0 | E24: 0 | F24: =D24*E24 -> 0
A25: ='02.1-ĐNTT'!A25 -> 11 | B25: ='02.1-ĐNTT'!B25 -> Bê tông trụ tường mác 200# | C25: ='02.1-ĐNTT'!C25 -> m3 | D25: ='CTKL DOT...'!K22 -> 0 | E25: 0 | F25: =D25*E25 -> 0
A26: ='02.1-ĐNTT'!A26 -> 12 | B26: ='02.1-ĐNTT'!B26 -> Ván khuôn tấm đan, bậc cấp | C26: ='02.1-ĐNTT'!C26 -> m2 | D26: ='CTKL DOT...'!K23 -> 0 | E26: 0 | F26: =D26*E26 -> 0
... A30: ='02.1-ĐNTT'!A30 -> 16 | B30: ='02.1-ĐNTT'!B30 -> Chi phí cộng thêm đối với đầu việc ván khuôn bậc tam cấp - tại vị trí ván khuôn thí (ván khuôn chết không luân chuyển được) | C30: ='02.1-ĐNTT'!C30 -> m2 | D30: ='CTKL DOT...'!K27 -> 0 | E30: 0 | F30: =D30*E30 -> 0
A31: ='02.1-ĐNTT'!A31 -> II | B31: ='02.1-ĐNTT'!B31 -> CÔNG TÁC BÊ TÔNG | E31: 0 | F31: =D31*E31 -> 0
A32: ='02.1-ĐNTT'!A32 -> 16 | B32: ='02.1-ĐNTT'!B32 -> Bê tông sản xuất qua dây chuyền trạm trộn tại hiện trường hoặc thương phẩm, đổ bằng bơm bê tông, bê tông dầm mác M400# | C32: ='02.1-ĐNTT'!C32 -> m3 | D32: ='CTKL DOT...'!K29 -> 18.172098 | E32: 1 | F32: =D32*E32 -> 18.172098
A33: ='02.1-ĐNTT'!A33 -> 17 | B33: ='02.1-ĐNTT'!B33 -> Bê tông sản xuất qua dây chuyền trạm trộn tại hiện trường hoặc thương phẩm, đổ bằng bơm bê tông, bê tông giếng gió mác M400# | C33: ='02.1-ĐNTT'!C33 -> m3 | D33: ='CTKL DOT...'!K65 -> 13.021151 | E33: 1 | F33: =D33*E33 -> 13.021151
A34: ='02.1-ĐNTT'!A34 -> 18 | B34: ='02.1-ĐNTT'!B34 -> Bê tông sản xuất qua dây chuyền trạm trộn tại hiện trường hoặc thương phẩm, đổ bằng bơm bê tông, bê tông vách bể mác M400# | C34: ='02.1-ĐNTT'!C34 -> m3 | D34: ='CTKL DOT...'!K69 -> 299.2042 | E34: 1 | F34: =D34*E34 -> 299.2042
A35: ='02.1-ĐNTT'!A35 -> 19 | B35: ='02.1-ĐNTT'!B35 -> Bê tông sản xuất qua dây chuyền trạm trộn tại hiện trường hoặc thương phẩm, đổ bằng bơm bê tông, bê tông sàn đáy bể mác M400# | C35: ='02.1-ĐNTT'!C35 -> m3 | D35: ='CTKL DOT...'!K131 -> 312.15609 | E35: 1 | F35: =D35*E35 -> 312.15609
A36: ='02.1-ĐNTT'!A36 -> 20 | B36: ='02.1-ĐNTT'!B36 -> Bê tông rãnh thoát nước B200 mác M400# | C36: ='02.1-ĐNTT'!C36 -> m3 | D36: ='CTKL DOT...'!K181 -> 0 | E36: 0 | F36: =D36*E36 -> 0
A37: ='02.1-ĐNTT'!A37 -> III | B37: ='02.1-ĐNTT'!B37 -> CÔNG TÁC VÁN KHUÔN | E37: 0 | F37: =D37*E37 -> 0
A38: ='02.1-ĐNTT'!A38 -> 21 | B38: ='02.1-ĐNTT'!B38 -> Ván khuôn dầm bể | C38: ='02.1-ĐNTT'!C38 -> m2 | D38: ='CTKL DOT...'!K183 -> 145.9326 | E38: 1 | F38: =D38*E38 -> 145.9326
A39: ='02.1-ĐNTT'!A39 -> 22 | B39: ='02.1-ĐNTT'!B39 -> Ván khuôn giếng gió | C39: ='02.1-ĐNTT'!C39 -> m2 | D39: ='CTKL DOT...'!K219 -> 118.3741 | E39: 1 | F39: =D39*E39 -> 118.3741
A40: ='02.1-ĐNTT'!A40 -> 23 | B40: ='02.1-ĐNTT'!B40 -> Ván khuôn vách bể | C40: ='02.1-ĐNTT'!C40 -> m2 | D40: ='CTKL DOT...'!K223 -> 1401.112 | E40: 1 | F40: =D40*E40 -> 1401.112
A41: ='02.1-ĐNTT'!A41 -> 24 | B41: ='02.1-ĐNTT'!B41 -> Ván khuôn cong vách bể | C41: ='02.1-ĐNTT'!C41 -> m2 | D41: ='CTKL DOT...'!K271 -> 1133.9824 | E41: 1 | F41: =D41*E41 -> 1133.9824
A42: ='02.1-ĐNTT'!A42 -> 25 | B42: ='02.1-ĐNTT'!B42 -> Ván khuôn sàn đáy bể | C42: ='02.1-ĐNTT'!C42 -> m2 | D42: ='CTKL DOT...'!K288 -> 936.2513 | E42: 1 | F42: =D42*E42 -> 936.2513
A43: ='02.1-ĐNTT'!A43 -> 26 | B43: ='02.1-ĐNTT'!B43 -> Ván khuôn rãnh thoát nước B200 | C43: ='02.1-ĐNTT'!C43 -> m2 | D43: ='CTKL DOT...'!K359 -> 0 | E43: 0 | F43: =D43*E43 -> 0
A44: ='02.1-ĐNTT'!A44 -> 27 | B44: ='02.1-ĐNTT'!B44 -> Chi phí cộng thêm đối với đầu việc ván khuôn bậc sàn đáy bể tại vị trí ván khuôn thí (ván khuôn chết không luân chuyển được) | C44: ='02.1-ĐNTT'!C44 -> m2 | D44: ='CTKL DOT...'!K360 -> 928.0593 | E44: 1 | F44: =D44*E44 -> 928.0593
A45: ='02.1-ĐNTT'!A45 -> IV | B45: ='02.1-ĐNTT'!B45 -> CÔNG TÁC CỐT THÉP | D45: ='CTKL DOT...'!K364 -> 0 | E45: 0 | F45: =D45*E45 -> 0
A46: ='02.1-ĐNTT'!A46 -> 26 | B46: ='02.1-ĐNTT'!B46 -> Cốt thép dầm bể | C46: ='02.1-ĐNTT'!C46 -> kg | D46: ='CTKL DOT...'!K365 -> 3724.2575 | E46: 1 | F46: =D46*E46 -> 3724.2575
...

Sheet CTKL DOT...
A4: BẢNG DIỄN GIẢI CHI TIẾT KHỐI LƯỢNG THẦU PHỤ THỰC HIỆN KỲ NÀY
A6: STT | B6: Nội dung công việc/ Khu vực/vị trí thực hiện | C6: Đơn vị | D6: Số bộ phận giống nhau | E6: Kích thước (m) | H6: Chu vi/ Diện tích | I6: Khối lượng | J6: Hệ số | K6: Tổng khối lượng | L6: Ghi chú
E7: Dài | F7: Rộng | G7: Cao
A8: (1) | B8: (2) | C8: (3) | D8: (4) | E8: (5) | F8: (6) | G8: (7) | H8: (8) | I8: (9) | J8: (10) | K8: (11=(9)x(10) | L8: (12)
B9: ='02.1-ĐNTT'!B12 -> HĐ số 21/2025/CT01/SM-HL
A10: ='02.1-ĐNTT'!A13 -> * | B10: ='02.1-ĐNTT'!B13 -> HẠNG MỤC: THI CÔNG KẾT CẤU CẢNH QUAN NGOÀI NHÀ KHU VỰC CAO TẦNG
A11: ='02.1-ĐNTT'!A14 -> I | B11: ='02.1-ĐNTT'!B14 -> CÔNG TÁC XÂY
A12: ='02.1-ĐNTT'!A15 -> 1 | B12: ='02.1-ĐNTT'!B15 -> Xây tường gạch đặc, chiều dày >330mm, VXM mác 75 | C12: ='02.1-ĐNTT'!C15 -> m3
A13: ='02.1-ĐNTT'!A16 -> 2 | B13: ='02.1-ĐNTT'!B16 -> Xây tường gạch đặc, chiều dày <=330mm, VXM mác 75 | C13: ='02.1-ĐNTT'!C16 -> m3
A14: ='02.1-ĐNTT'!A17 -> 3 | B14: ='02.1-ĐNTT'!B17 -> Xây tường gạch đặc, chiều dày <=110mm, VXM mác 75 | C14: ='02.1-ĐNTT'!C17 -> m3
A15: ='02.1-ĐNTT'!A18 -> 4 | B15: ='02.1-ĐNTT'!B18 -> Xây cột, trụ, gạch đặc, VXM mác 75 | C15: ='02.1-ĐNTT'!C18 -> m3
A16: ='02.1-ĐNTT'!A19 -> 5 | B16: ='02.1-ĐNTT'!B19 -> Ván khuôn giằng tường | C16: ='02.1-ĐNTT'!C19 -> m2
A17: ='02.1-ĐNTT'!A20 -> 6 | B17: ='02.1-ĐNTT'!B20 -> Cốt thép giằng tường | C17: ='02.1-ĐNTT'!C20 -> kg
A18: ='02.1-ĐNTT'!A21 -> 7 | B18: ='02.1-ĐNTT'!B21 -> Bê tông giằng tường mác 200# | C18: ='02.1-ĐNTT'!C21 -> m3
A19: ='02.1-ĐNTT'!A22 -> 8 | B19: ='02.1-ĐNTT'!B22 -> Khoan cấy cốt thép, đường kính thép D14 | C19: ='02.1-ĐNTT'!C22 -> vị trí
A20: ='02.1-ĐNTT'!A23 -> 9 | B20: ='02.1-ĐNTT'!B23 -> Ván khuôn trụ tường | C20: ='02.1-ĐNTT'!C23 -> m2
A21: ='02.1-ĐNTT'!A24 -> 10 | B21: ='02.1-ĐNTT'!B24 -> Cốt thép trụ tường | C21: ='02.1-ĐNTT'!C24 -> kg
A22: ='02.1-ĐNTT'!A25 -> 11 | B22: ='02.1-ĐNTT'!B25 -> Bê tông trụ tường mác 200# | C22: ='02.1-ĐNTT'!C25 -> m3
A23: ='02.1-ĐNTT'!A26 -> 12 | B23: ='02.1-ĐNTT'!B26 -> Ván khuôn tấm đan, bậc cấp | C23: ='02.1-ĐNTT'!C26 -> m2
... A27: ='02.1-ĐNTT'!A30 -> 16 | B27: ='02.1-ĐNTT'!B30 -> Chi phí cộng thêm đối với đầu việc ván khuôn bậc tam cấp - tại vị trí ván khuôn thí (ván khuôn chết không luân chuyển được) | C27: ='02.1-ĐNTT'!C30 -> m2
A28: ='02.1-ĐNTT'!A31 -> II | B28: ='02.1-ĐNTT'!B31 -> CÔNG TÁC BÊ TÔNG
A29: ='02.1-ĐNTT'!A32 -> 16 | B29: ='02.1-ĐNTT'!B32 -> Bê tông sản xuất qua dây chuyền trạm trộn tại hiện trường hoặc thương phẩm, đổ bằng bơm bê tông, bê tông dầm mác M400# | C29: ='02.1-ĐNTT'!C32 -> m3 | K29: =+SUBTOTAL(9,K30:K64) -> 18.172098 | L29: BV SHOP-HOBOI-02
B30: Dầm bể bơi trục B18-B27
B31: + BC1 | D31: 1 | E31: =66.17/2 -> 33.085 | F31: 0.3 | G31: =0.45-0.2 -> 0.25 | J31: 1 | K31: =+PRODUCT(D31:J31) -> 2.481375 | L31: =+_xlfn.FORMULATEXT(G31) -> =0,45-0,2
B32: + BC2 | D32: 1 | E32: =46.69/2 -> 23.345 | F32: 0.3 | G32: =0.61-0.2 -> 0.41 | J32: 1 | K32: =+PRODUCT(D32:J32) -> 2.871435 | L32: =+_xlfn.FORMULATEXT(G32) -> =0,61-0,2
B33: + BC1.1 | D33: 1 | E33: 16.695 | F33: 0.3 | G33: =0.29-0.2 -> 0.09 | J33: 1 | K33: =+PRODUCT(D33:J33) -> 0.450765 | L33: =+_xlfn.FORMULATEXT(G33) -> =0,29-0,2
B34: + BC1.2 | D34: 1 | E34: 20.45 | F34: 0.3 | G34: =0.29-0.2 -> 0.09 | J34: 1 | K34: =+PRODUCT(D34:J34) -> 0.55215 | L34: =+_xlfn.FORMULATEXT(G34) -> =0,29-0,2
B35: + BC1.3 | D35: 1 | E35: =7.205+7.015 -> 14.22 | F35: 0.3 | G35: =0.29-0.2 -> 0.09 | J35: 1 | K35: =+PRODUCT(D35:J35) -> 0.38394 | L35: =+_xlfn.FORMULATEXT(G35) -> =0,29-0,2
B36: + BC1.4 | D36: 1 | E36: =4.445+4.475 -> 8.92 | F36: 0.3 | G36: =0.29-0.2 -> 0.09 | J36: 1 | K36: =+PRODUCT(D36:J36) -> 0.24084 | L36: =+_xlfn.FORMULATEXT(G36) -> =0,29-0,2
B37: + BC1.5 | D37: 1 | E37: =4.79+4.855 -> 9.645 | F37: 0.3 | G37: =0.29-0.2 -> 0.09 | J37: 1 | K37: =+PRODUCT(D37:J37) -> 0.260415 | L37: =+_xlfn.FORMULATEXT(G37) -> =0,29-0,2
B38: + BY1 | D38: 1 | E38: 5.125 | F38: 0.3 | G38: =0.61-0.15 -> 0.46 | J38: 1 | K38: =+PRODUCT(D38:J38) -> 0.70725 | L38: =+_xlfn.FORMULATEXT(G38) -> =0,61-0,15
B39: Dầm dãy bồn cây trục BF
B40: - Giằng TX1 | D40: 1 | E40: 125.768 | F40: 0.22 | G40: =0.3 -> 0.3 | J40: 1 | K40: =+PRODUCT(D40:J40) -> 8.300688
B41: - Vách bồn cây trục 12-16
B42: + Giằng TX-3.1 | D42: 1 | E42: =+'thép dầm bồn cây'!D392/1000 -> 1.51 | F42: 0.22 | G42: 0.2 | J42: 1 | K42: =+PRODUCT(D42:J42) -> 0.06644
B43: + Giằng TX-3.2 | D43: 1 | E43: =+'thép dầm bồn cây'!D397/1000 -> 2.765 | F43: 0.22 | G43: 0.2 | J43: 1 | K43: =+PRODUCT(D43:J43) -> 0.12166
B44: + Giằng TX-3.3 | D44: 1 | E44: =+'thép dầm bồn cây'!D402/1000 -> 1.005 | F44: 0.22 | G44: 0.2 | J44: 1 | K44: =+PRODUCT(D44:J44) -> 0.04422
B45: + Giằng TX-3.4 | D45: 1 | E45: =+'thép dầm bồn cây'!D407/1000 -> 3.545 | F45: 0.22 | G45: 0.2 | J45: 1 | K45: =+PRODUCT(D45:J45) -> 0.15598
B46: + Giằng TX-3.5 | D46: 1 | E46: =+'thép dầm bồn cây'!D412/1000 -> 3.62 | F46: 0.22 | G46: 0.2 | J46: 1 | K46: =+PRODUCT(D46:J46) -> 0.15928
B47: + Giằng TX-3.6 | D47: 1 | E47: =+'thép dầm bồn cây'!D417/1000 -> 0.935 | F47: 0.22 | G47: 0.2 | J47: 1 | K47: =+PRODUCT(D47:J47) -> 0.04114
...

Sheet đối trừ đợt 2
B1: Thi công kết cấu, chống thấm cảnh quan ngoài nhà khu vực cao tầng
B2: Dự án: Dự án đầu tư xây dựng nhà ở cao tầng kết hợp thương mại dịch vụ và nhà ở thấp tầng SunShine Crystal River
B3: Địa điểm: Ô đất CT01-CT và CT01-TT(được điều chỉnh từ ô đất CT01) thuộc khu đô thị Nam Thăng Long, giai đoạn III, phường Phú Thượng, quận Tây Hồ, Hà Nội
B4: Bên giao thầu: Công ty TNHH Đầu tư Thương mại Sông Mã
B5: Bên nhận thầu: Công ty Cổ phần Đầu tư Xây dựng Hoàng Long Group
A6: BẢNG TỔNG HỢP GIÁ TRỊ KHẤU TRỪ
A7: Từ ngày ….../….../ năm …….... Đến ngày ….../….../ năm ……....
K8: Thanh toán lần: | L8: 1
K9: Đơn vị tính: vnđ
A10: STT | B10: Nội dung | C10: Đơn vị | D10: Đơn giá | E10: Khối lượng | H10: Đơn giá | I10: Giá trị tiền | L10: Ghi chú
E11: LK Kỳ trước | F11: Kỳ này | G11: LK đến nay | H11: VAT 8% | I11: LK Kỳ trước | J11: Kỳ này | K11: LK đến nay
A12: A | B12: Khấu trừ khác | I12: =+SUBTOTAL(9,I13:I23) -> 44735953 | J12: =+SUBTOTAL(9,J13:J20) -> 0 | K12: =+SUBTOTAL(9,K13:K23) -> 44735953
A13: І | B13: Tiền điện | I13: =+SUBTOTAL(9,I14:I16) -> 14310000 | J13: =+SUBTOTAL(9,J14:J16) -> 0 | K13: =+SUBTOTAL(9,K14:K16) -> 14310000
A14: 1 | B14: Tiền điện tháng 2/2025 | C14: tháng | E14: 2160000 | G14: =+E14+F14 -> 2160000 | I14: =+E14 -> 2160000 | K14: =+I14+J14 -> 2160000
A15: 2 | B15: Tiền điện tháng 3/2025 | C15: tháng | E15: 6750000 | G15: =+E15+F15 -> 6750000 | I15: =+E15 -> 6750000 | K15: =+I15+J15 -> 6750000
A16: 3 | B16: Tiền điện tháng 4/2025 | C16: tháng | E16: 5400000 | G16: =+E16+F16 -> 5400000 | I16: =+E16 -> 5400000 | K16: =+I16+J16 -> 5400000
A17: II | B17: Tiền rác thải | G17: =+E17+F17 -> 0 | I17: =+SUBTOTAL(9,I18:I20) -> 28800000 | J17: =+SUBTOTAL(9,J18:J20) -> 0 | K17: =+SUBTOTAL(9,K18:K20) -> 28800000
A18: 1 | B18: Tiền rác tháng 3/2025 | C18: tháng | E18: 2700000 | G18: =+E18+F18 -> 2700000 | I18: =+E18 -> 2700000 | K18: =+I18+J18 -> 2700000
A19: 2 | B19: Tiền rác tháng 3/2025 | C19: tháng | E19: 8100000 | G19: =+E19+F19 -> 8100000 | I19: =+E19 -> 8100000 | K19: =+I19+J19 -> 8100000
A20: 3 | B20: Dọn vệ sinh- biên bản làm việc ngày 25/04/2025 | C20: công | E20: 36 | G20: =+E20+F20 -> 36 | H20: 500000 | I20: =E20*H20 -> 18000000 | K20: =+I20+J20 -> 18000000
A21: III | B21: Khấu trừ bê tông | G21: =+E21+F21 -> 0 | I21: =+SUBTOTAL(9,I22:I23) -> 1625952.5 | J21: =+SUBTOTAL(9,J22:J23) -> 0 | K21: =+SUBTOTAL(9,K22:K23) -> 1625952.5
A22: 1 | B22: Mác 450 - Lỗ mở số 03 | C22: m3 | E22: 1.37 | G22: =+E22+F22 -> 1.37 | H22: =+I22/E22 -> 1122327 | I22: 1537588 | K22: =+I22+J22 -> 1537588 | L22: Việt Đức hầm đợt 27
A23: 2 | B23: Phụ gia R7-Dầm giằng thang thoát hiểm | C23: m3 | E23: 3 | G23: =+E23+F23 -> 3 | H23: =+I23/E23 -> 29454.84 | I23: 88364.52 | K23: =I23+J23 -> 88364.52 | L23: Việt Đức thấp tầng đợt 24
A24: B | B24: Tạm giữ hao hụt thép | G24: =+E24+F24 -> 0 | I24: =+SUBTOTAL(9,I25:I25) -> 26876935 | J24: =+SUBTOTAL(9,J25:J25) -> 19363984 | K24: =+SUBTOTAL(9,K25:K25) -> 46240919
A25: 1 | B25: Cốt thép tạm giữ hao hụt | C25: kg | E25: 1854.3491 | F25: =921+415 -> 1336 | G25: =+E25+F25 -> 3190.3491 | H25: 14494 | I25: =E25*H25 -> 26876935 | J25: =F25*H25 -> 19363984 | K25: =I25+J25 -> 46240919 | L25: Tạm giữ hao hụt 3%
B26: Tổng cộng (Đã bao gồm VAT) | I26: =+SUBTOTAL(9,I14:I25) -> 71612888 | J26: =+SUBTOTAL(9,J14:J25) -> 19363984 | K26: =+SUBTOTAL(9,K14:K25) -> 90976872
B28: CHỈ HUY TRƯỞNG | H28: BÊN NHẬN THẦU

Sheet thép dầm bồn cây
A1: BẢNG KHỐI LƯỢNG CỐT THÉP DẦM BỒN CÂY
A2: Công trình: Chung cư cao tầng kết hợp dịch vụ thương mại và nhà ở Thấp tầng Sunshine Crystal River
A3: Hạng mục: Thi công kết cấu, chống thấm cảnh quan ngoài nhà - Khu vực nhà cao tầng
A5: Cấu kiện | B5: Số hiệu thép | C5: Hình dạng, kích thước | F5: Đ/K (mm) | G5: Chiều dài/ 1 thanh (mm) | H5: Số mối nối | I5: Chiều dài mối nối (mm) | J5: Chiều dài 1 thanh (mm) | K5: Số thanh/1 KC | L5: Số lượng cấu kiện | M5: Tổng chiều dài (m) | N5: Trọng lượng (kg/1m) | O5: Khối lượng (kg) | P5: Ghi chú | R5: 6 | S5: 8 | T5: 10 | U5: 12 | V5: 14 | W5: 16 | X5: 18 | Y5: 20 | Z5: 22
R6: 0.222 | S6: 0.395 | T6: 0.617 | U6: 0.888 | V6: 1.21 | W6: 1.58 | X6: 2 | Y6: 2.47 | Z6: 2.98
A7: (1) | B7: (2) | C7: (3) | F7: (4) | G7: (5) | K7: (6) | L7: (7) | M7: (8) | N7: (9) | O7: (10) | P7: (12)
A8: Giằng chân tường xây trục B37-B38
A9: Tường xây TX-1 | C9: L= | D9: 1960 | E9: mm
B10: 1 | C10: 200 | D10: =D9+200+150 -> 2310 | E10: =250 -> 250 | F10: 10 | G10: =C10+D10+E10 -> 2760 | H10: 0 | I10: =F10*45 -> 450 | J10: =G10+I10*H10 -> 2760 | K10: 2 | L10: 1 | M10: =J10*K10*L10/1000 -> 5.52 | N10: =_xlfn.XLOOKUP(F10,$R$5:$Z$5,$R$6:$Z$6,"NOT_FOUND",0) -> 0.617 | O10: =M10*N10 -> 3.40584
B11: 2 | C11: 100 | D11: =D9+200+170 -> 2330 | E11: 130 | F11: 10 | G11: =C11+D11+E11 -> 2560 | H11: 0 | I11: =F11*45 -> 450 | J11: =G11+I11*H11 -> 2560 | K11: 2 | L11: 1 | M11: =J11*K11*L11/1000 -> 5.12 | N11: =_xlfn.XLOOKUP(F11,$R$5:$Z$5,$R$6:$Z$6,"NOT_FOUND",0) -> 0.617 | O11: =M11*N11 -> 3.15904
B12: 3 | C12: 240 | D12: 160 | E12: 60 | F12: 6 | G12: =(C12+D12+E12)*2 -> 920 | H12: 0 | I12: =F12*45 -> 270 | J12: =G12+I12*H12 -> 920 | K12: =+ROUND(D9/200,0) -> 10 | L12: 1 | M12: =J12*K12*L12/1000 -> 9.2 | N12: =_xlfn.XLOOKUP(F12,$R$5:$Z$5,$R$6:$Z$6,"NOT_FOUND",0) -> 0.222 | O12: =M12*N12 -> 2.0424
B13: * | C13: 100 | D13: 200 | F13: 10 | G13: =C13+D13 -> 300 | H13: 0 | I13: =F13*45 -> 450 | J13: =G13+I13*H13 -> 300 | K13: =+ROUND(D9/600,0) -> 3 | L13: 1 | M13: =J13*K13*L13/1000 -> 0.9 | N13: =_xlfn.XLOOKUP(F13,$R$5:$Z$5,$R$6:$Z$6,"NOT_FOUND",0) -> 0.617 | O13: =M13*N13 -> 0.5553 | P13: khoan cắm
A14: Tường xây TX-1 | C14: L= | D14: 2005 | E14: mm
B15: 1 | C15: 200 | D15: =D14+200+150 -> 2355 | E15: =250 -> 250 | F15: 10 | G15: =C15+D15+E15 -> 2805 | H15: 0 | I15: =F15*45 -> 450 | J15: =G15+I15*H15 -> 2805 | K15: 2 | L15: 1 | M15: =J15*K15*L15/1000 -> 5.61 | N15: =_xlfn.XLOOKUP(F15,$R$5:$Z$5,$R$6:$Z$6,"NOT_FOUND",0) -> 0.617 | O15: =M15*N15 -> 3.46137
B16: 2 | C16: 100 | D16: =D14+200+170 -> 2375 | E16: 130 | F16: 10 | G16: =C16+D16+E16 -> 2605 | H16: 0 | I16: =F16*45 -> 450 | J16: =G16+I16*H16 -> 2605 | K16: 2 | L16: 1 | M16: =J16*K16*L16/1000 -> 5.21 | N16: =_xlfn.XLOOKUP(F16,$R$5:$Z$5,$R$6:$Z$6,"NOT_FOUND",0) -> 0.617 | O16: =M16*N16 -> 3.21457
B17: 3 | C17: 240 | D17: 160 | E17: 60 | F17: 6 | G17: =(C17+D17+E17)*2 -> 920 | H17: 0 | I17: =F17*45 -> 270 | J17: =G17+I17*H17 -> 920 | K17: =+ROUND(D14/200,0) -> 10 | L17: 1 | M17: =J17*K17*L17/1000 -> 9.2 | N17: =_xlfn.XLOOKUP(F17,$R$5:$Z$5,$R$6:$Z$6,"NOT_FOUND",0) -> 0.222 | O17: =M17*N17 -> 2.0424
B18: * | C18: 100 | D18: 200 | F18: 10 | G18: =C18+D18 -> 300 | H18: 0 | I18: =F18*45 -> 450 | J18: =G18+I18*H18 -> 300 | K18: =+ROUND(D14/600,0) -> 3 | L18: 1 | M18: =J18*K18*L18/1000 -> 0.9 | N18: =_xlfn.XLOOKUP(F18,$R$5:$Z$5,$R$6:$Z$6,"NOT_FOUND",0) -> 0.617 | O18: =M18*N18 -> 0.5553 | P18: khoan cắm
A19: Tường xây TX-1 | C19: L= | D19: 2050 | E19: mm
B20: 1 | C20: 200 | D20: =D19+200+150 -> 2400 | E20: =250 -> 250 | F20: 10 | G20: =C20+D20+E20 -> 2850 | H20: 0 | I20: =F20*45 -> 450 | J20: =G20+I20*H20 -> 2850 | K20: 2 | L20: 1 | M20: =J20*K20*L20/1000 -> 5.7 | N20: =_xlfn.XLOOKUP(F20,$R$5:$Z$5,$R$6:$Z$6,"NOT_FOUND",0) -> 0.617 | O20: =M20*N20 -> 3.5169
B21: 2 | C21: 100 | D21: =D19+200+170 -> 2420 | E21: 130 | F21: 10 | G21: =C21+D21+E21 -> 2650 | H21: 0 | I21: =F21*45 -> 450 | J21: =G21+I21*H21 -> 2650 | K21: 2 | L21: 1 | M21: =J21*K21*L21/1000 -> 5.3 | N21: =_xlfn.XLOOKUP(F21,$R$5:$Z$5,$R$6:$Z$6,"NOT_FOUND",0) -> 0.617 | O21: =M21*N21 -> 3.2701
B22: 3 | C22: 240 | D22: 160 | E22: 60 | F22: 6 | G22: =(C22+D22+E22)*2 -> 920 | H22: 0 | I22: =F22*45 -> 270 | J22: =G22+I22*H22 -> 920 | K22: =+ROUND(D19/200,0) -> 10 | L22: 1 | M22: =J22*K22*L22/1000 -> 9.2 | N22: =_xlfn.XLOOKUP(F22,$R$5:$Z$5,$R$6:$Z$6,"NOT_FOUND",0) -> 0.222 | O22: =M22*N22 -> 2.0424
B23: * | C23: 100 | D23: 200 | F23: 10 | G23: =C23+D23 -> 300 | H23: 0 | I23: =F23*45 -> 450 | J23: =G23+I23*H23 -> 300 | K23: =+ROUND(D19/600,0) -> 3 | L23: 1 | M23: =J23*K23*L23/1000 -> 0.9 | N23: =_xlfn.XLOOKUP(F23,$R$5:$Z$5,$R$6:$Z$6,"NOT_FOUND",0) -> 0.617 | O23: =M23*N23 -> 0.5553 | P23: khoan cắm
A24: Tường xây TX-1 | C24: L= | D24: 2070 | E24: mm
B25: 1 | C25: 200 | D25: =D24+200+150 -> 2420 | E25: =250 -> 250 | F25: 10 | G25: =C25+D25+E25 -> 2870 | H25: 0 | I25: =F25*45 -> 450 | J25: =G25+I25*H25 -> 2870 | K25: 2 | L25: 1 | M25: =J25*K25*L25/1000 -> 5.74 | N25: =_xlfn.XLOOKUP(F25,$R$5:$Z$5,$R$6:$Z$6,"NOT_FOUND",0) -> 0.617 | O25: =M25*N25 -> 3.54158
B26: 2 | C26: 100 | D26: =D24+200+170 -> 2440 | E26: 130 | F26: 10 | G26: =C26+D26+E26 -> 2670 | H26: 0 | I26: =F26*45 -> 450 | J26: =G26+I26*H26 -> 2670 | K26: 2 | L26: 1 | M26: =J26*K26*L26/1000 -> 5.34 | N26: =_xlfn.XLOOKUP(F26,$R$5:$Z$5,$R$6:$Z$6,"NOT_FOUND",0) -> 0.617 | O26: =M26*N26 -> 3.29478
B27: 3 | C27: 240 | D27: 160 | E27: 60 | F27: 6 | G27: =(C27+D27+E27)*2 -> 920 | H27: 0 | I27: =F27*45 -> 270 | J27: =G27+I27*H27 -> 920 | K27: =+ROUND(D24/200,0) -> 10 | L27: 1 | M27: =J27*K27*L27/1000 -> 9.2 | N27: =_xlfn.XLOOKUP(F27,$R$5:$Z$5,$R$6:$Z$6,"NOT_FOUND",0) -> 0.222 | O27: =M27*N27 -> 2.0424
B28: * | C28: 100 | D28: 200 | F28: 10 | G28: =C28+D28 -> 300 | H28: 0 | I28: =F28*45 -> 450 | J28: =G28+I28*H28 -> 300 | K28: =+ROUND(D24/600,0) -> 3 | L28: 1 | M28: =J28*K28*L28/1000 -> 0.9 | N28: =_xlfn.XLOOKUP(F28,$R$5:$Z$5,$R$6:$Z$6,"NOT_FOUND",0) -> 0.617 | O28: =M28*N28 -> 0.5553 | P28: khoan cắm
A29: Giằng chân tường xây trục B36-B37
A30: Tường xây TX-1 | C30: L= | D30: 2055 | E30: mm
B31: 1 | C31: 200 | D31: =D30+200+150 -> 2405 | E31: =250 -> 250 | F31: 10 | G31: =C31+D31+E31 -> 2855 | H31: 0 | I31: =F31*45 -> 450 | J31: =G31+I31*H31 -> 2855 | K31: 2 | L31: 1 | M31: =J31*K31*L31/1000 -> 5.71 | N31: =_xlfn.XLOOKUP(F31,$R$5:$Z$5,$R$6:$Z$6,"NOT_FOUND",0) -> 0.617 | O31: =M31*N31 -> 3.52307
B32: 2 | C32: 100 | D32: =D30+200+170 -> 2425 | E32: 130 | F32: 10 | G32: =C32+D32+E32 -> 2655 | H32: 0 | I32: =F32*45 -> 450 | J32: =G32+I32*H32 -> 2655 | K32: 2 | L32: 1 | M32: =J32*K32*L32/1000 -> 5.31 | N32: =_xlfn.XLOOKUP(F32,$R$5:$Z$5,$R$6:$Z$6,"NOT_FOUND",0) -> 0.617 | O32: =M32*N32 -> 3.27627
B33: 3 | C33: 240 | D33: 160 | E33: 60 | F33: 6 | G33: =(C33+D33+E33)*2 -> 920 | H33: 0 | I33: =F33*45 -> 270 | J33: =G33+I33*H33 -> 920 | K33: =+ROUND(D30/200,0) -> 10 | L33: 1 | M33: =J33*K33*L33/1000 -> 9.2 | N33: =_xlfn.XLOOKUP(F33,$R$5:$Z$5,$R$6:$Z$6,"NOT_FOUND",0) -> 0.222 | O33: =M33*N33 -> 2.0424
B34: * | C34: 100 | D34: 200 | F34: 10 | G34: =C34+D34 -> 300 | H34: 0 | I34: =F34*45 -> 450 | J34: =G34+I34*H34 -> 300 | K34: =+ROUND(D30/600,0) -> 3 | L34: 1 | M34: =J34*K34*L34/1000 -> 0.9 | N34: =_xlfn.XLOOKUP(F34,$R$5:$Z$5,$R$6:$Z$6,"NOT_FOUND",0) -> 0.617 | O34: =M34*N34 -> 0.5553 | P34: khoan cắm
A35: Tường xây TX-1 | C35: L= | D35: 2020 | E35: mm
B36: 1 | C36: 200 | D36: =D35+200+150 -> 2370 | E36: =250 -> 250 | F36: 10 | G36: =C36+D36+E36 -> 2820 | H36: 0 | I36: =F36*45 -> 450 | J36: =G36+I36*H36 -> 2820 | K36: 2 | L36: 1 | M36: =J36*K36*L36/1000 -> 5.64 | N36: =_xlfn.XLOOKUP(F36,$R$5:$Z$5,$R$6:$Z$6,"NOT_FOUND",0) -> 0.617 | O36: =M36*N36 -> 3.47988
B37: 2 | C37: 100 | D37: =D35+200+170 -> 2390 | E37: 130 | F37: 10 | G37: =C37+D37+E37 -> 2620 | H37: 0 | I37: =F37*45 -> 450 | J37: =G37+I37*H37 -> 2620 | K37: 2 | L37: 1 | M37: =J37*K37*L37/1000 -> 5.24 | N37: =_xlfn.XLOOKUP(F37,$R$5:$Z$5,$R$6:$Z$6,"NOT_FOUND",0) -> 0.617 | O37: =M37*N37 -> 3.23308
B38: 3 | C38: 240 | D38: 160 | E38: 60 | F38: 6 | G38: =(C38+D38+E38)*2 -> 920 | H38: 0 | I38: =F38*45 -> 270 | J38: =G38+I38*H38 -> 920 | K38: =+ROUND(D35/200,0) -> 10 | L38: 1 | M38: =J38*K38*L38/1000 -> 9.2 | N38: =_xlfn.XLOOKUP(F38,$R$5:$Z$5,$R$6:$Z$6,"NOT_FOUND",0) -> 0.222 | O38: =M38*N38 -> 2.0424
B39: * | C39: 100 | D39: 200 | F39: 10 | G39: =C39+D39 -> 300 | H39: 0 | I39: =F39*45 -> 450 | J39: =G39+I39*H39 -> 300 | K39: =+ROUND(D35/600,0) -> 3 | L39: 1 | M39: =J39*K39*L39/1000 -> 0.9 | N39: =_xlfn.XLOOKUP(F39,$R$5:$Z$5,$R$6:$Z$6,"NOT_FOUND",0) -> 0.617 | O39: =M39*N39 -> 0.5553 | P39: khoan cắm
A40: Giằng chân tường xây trục B35-B36
A41: Tường xây TX-1 | C41: L= | D41: 1960 | E41: mm
...

Sheet thép vách giếng gió
A1: BẢNG KHỐI LƯỢNG CỐT THÉP VÁCH GIẾNG GIÓ
A2: Công trình: Chung cư cao tầng kết hợp dịch vụ thương mại và nhà ở Thấp tầng Sunshine Crystal River
A3: Hạng mục: Thi công kết cấu, chống thấm cảnh quan ngoài nhà - Khu vực nhà cao tầng
A5: Cấu kiện | B5: Số hiệu thép | C5: Hình dạng, kích thước | F5: Đ/K (mm) | G5: Chiều dài/ 1 thanh (mm) | H5: Số lượng thanh nối /thanh mỏ | I5: Chiều dài thanh nối | J5: Chiều dài 1 thanh (mm) | K5: Số thanh/1 KC | L5: Số lượng cấu kiện | M5: Tổng chiều dài (m) | N5: Trọng lượng (kg/1m) | O5: Khối lượng (kg) | P5: Ghi chú | R5: 6 | S5: 8 | T5: 10 | U5: 12 | V5: 14 | W5: 16 | X5: 18 | Y5: 20 | Z5: 22
R6: 0.222 | S6: 0.395 | T6: 0.617 | U6: 0.888 | V6: 1.21 | W6: 1.58 | X6: 2 | Y6: 2.47 | Z6: 2.98
A7: (1) | B7: (2) | C7: (3) | F7: (4) | G7: (5) | H7: (6) | I7: (7) | K7: (8) | L7: (9) | M7: (10) | N7: (12) | O7: (13) | P7: (14)
A8: Thép Vách GG10 | C8: L= | D8: =(11840+10640)/2 -> 11240 | E8: mm
B9: 1 | C9: 150 | D9: 2350 | F9: 10 | G9: =C9+D9+E9 -> 2500 | J9: =+I9*H9+G9 -> 2500 | K9: =+ROUND(D8/200,0)+1 -> 57 | L9: 2 | M9: =J9*K9*L9/1000 -> 285 | N9: =_xlfn.XLOOKUP(F9,$R$5:$Z$5,$R$6:$Z$6,"NOT_FOUND",0) -> 0.617 | O9: =M9*N9 -> 175.845 | P9: khoan cắm | Q9: sửa số lượng thanh thép vách từ 39 lên 57
B10: 2 | D10: 11840 | F10: 10 | G10: =C10+D10+E10 -> 11840 | J10: =+I10*H10+G10 -> 11840 | K10: 12 | L10: 1 | M10: =J10*K10*L10/1000 -> 142.08 | N10: =_xlfn.XLOOKUP(F10,$R$5:$Z$5,$R$6:$Z$6,"NOT_FOUND",0) -> 0.617 | O10: =M10*N10 -> 87.66336
B11: 2 | D11: 10640 | F11: 10 | G11: =C11+D11+E11 -> 10640 | J11: =+I11*H11+G11 -> 10640 | K11: 12 | L11: 1 | M11: =J11*K11*L11/1000 -> 127.68 | N11: =_xlfn.XLOOKUP(F11,$R$5:$Z$5,$R$6:$Z$6,"NOT_FOUND",0) -> 0.617 | O11: =M11*N11 -> 78.77856
B12: 3 | C12: 60 | D12: 150 | E12: 60 | F12: 6 | G12: =C12+D12+E12 -> 270 | J12: =+I12*H12+G12 -> 270 | K12: =+ROUND(D11/600,0)+1 -> 19 | L12: 4 | M12: =J12*K12*L12/1000 -> 20.52 | N12: =_xlfn.XLOOKUP(F12,$R$5:$Z$5,$R$6:$Z$6,"NOT_FOUND",0) -> 0.222 | O12: =M12*N12 -> 4.55544
B13: 4 | C13: 150 | D13: 300 | F13: 10 | G13: =C13+D13+E13 -> 450 | J13: =+I13*H13+G13 -> 450 | K13: =+K12 -> 19 | L13: 1 | M13: =J13*K13*L13/1000 -> 8.55 | N13: =_xlfn.XLOOKUP(F13,$R$5:$Z$5,$R$6:$Z$6,"NOT_FOUND",0) -> 0.617 | P13: khoan cắm | Q13: =15647/2 -> 7823.5
A14: Thép Vách GG11 | C14: L= | D14: =(8440+7200)/2 -> 7820 | E14: mm
B15: 1 | C15: 150 | D15: 2350 | F15: 10 | G15: =C15+D15+E15 -> 2500 | J15: =+I15*H15+G15 -> 2500 | K15: =+ROUND(D14/200,0)+1 -> 40 | L15: 2 | M15: =J15*K15*L15/1000 -> 200 | N15: =_xlfn.XLOOKUP(F15,$R$5:$Z$5,$R$6:$Z$6,"NOT_FOUND",0) -> 0.617 | O15: =M15*N15 -> 123.4 | P15: khoan cắm
B16: 2 | D16: 8440 | F16: 10 | G16: =C16+D16+E16 -> 8440 | J16: =+I16*H16+G16 -> 8440 | K16: 12 | L16: 1 | M16: =J16*K16*L16/1000 -> 101.28 | N16: =_xlfn.XLOOKUP(F16,$R$5:$Z$5,$R$6:$Z$6,"NOT_FOUND",0) -> 0.617 | O16: =M16*N16 -> 62.48976
B17: 2 | D17: 7200 | F17: 10 | G17: =C17+D17+E17 -> 7200 | J17: =+I17*H17+G17 -> 7200 | K17: 12 | L17: 1 | M17: =J17*K17*L17/1000 -> 86.4 | N17: =_xlfn.XLOOKUP(F17,$R$5:$Z$5,$R$6:$Z$6,"NOT_FOUND",0) -> 0.617 | O17: =M17*N17 -> 53.3088
B18: 3 | C18: 60 | D18: 150 | E18: 60 | F18: 6 | G18: =C18+D18+E18 -> 270 | J18: =+I18*H18+G18 -> 270 | K18: =+ROUND(D17/600,0)+1 -> 13 | L18: 4 | M18: =J18*K18*L18/1000 -> 14.04 | N18: =_xlfn.XLOOKUP(F18,$R$5:$Z$5,$R$6:$Z$6,"NOT_FOUND",0) -> 0.222 | O18: =M18*N18 -> 3.11688
B19: 4 | C19: 150 | D19: 300 | F19: 10 | G19: =C19+D19+E19 -> 450 | J19: =+I19*H19+G19 -> 450 | K19: =+K18 -> 13 | L19: 1 | M19: =J19*K19*L19/1000 -> 5.85 | N19: =_xlfn.XLOOKUP(F19,$R$5:$Z$5,$R$6:$Z$6,"NOT_FOUND",0) -> 0.617 | P19: khoan cắm
A20: Thép Vách GG12 | C20: L= | D20: =+(7440+6200)/2 -> 6820 | E20: mm
B21: 1 | C21: 150 | D21: 2350 | F21: 10 | G21: =C21+D21+E21 -> 2500 | J21: =+I21*H21+G21 -> 2500 | K21: =+ROUND(D20/200,0)+1 -> 35 | L21: 2 | M21: =J21*K21*L21/1000 -> 175 | N21: =_xlfn.XLOOKUP(F21,$R$5:$Z$5,$R$6:$Z$6,"NOT_FOUND",0) -> 0.617 | O21: =M21*N21 -> 107.975 | P21: khoan cắm
B22: 2 | D22: 7440 | F22: 10 | G22: =C22+D22+E22 -> 7440 | J22: =+I22*H22+G22 -> 7440 | K22: 12 | L22: 1 | M22: =J22*K22*L22/1000 -> 89.28 | N22: =_xlfn.XLOOKUP(F22,$R$5:$Z$5,$R$6:$Z$6,"NOT_FOUND",0) -> 0.617 | O22: =M22*N22 -> 55.08576 | S22: 12040 | T22: =+S22/200+1 -> 61.2
B23: 2 | D23: 6200 | F23: 10 | G23: =C23+D23+E23 -> 6200 | J23: =+I23*H23+G23 -> 6200 | K23: 12 | L23: 1 | M23: =J23*K23*L23/1000 -> 74.4 | N23: =_xlfn.XLOOKUP(F23,$R$5:$Z$5,$R$6:$Z$6,"NOT_FOUND",0) -> 0.617 | O23: =M23*N23 -> 45.9048 | S23: 10440 | T23: =+S23/200+1 -> 53.2
B24: 3 | C24: 60 | D24: 150 | E24: 60 | F24: 6 | G24: =C24+D24+E24 -> 270 | J24: =+I24*H24+G24 -> 270 | K24: =+ROUND(D23/600,0)+1 -> 11 | L24: 4 | M24: =J24*K24*L24/1000 -> 11.88 | N24: =_xlfn.XLOOKUP(F24,$R$5:$Z$5,$R$6:$Z$6,"NOT_FOUND",0) -> 0.222 | O24: =M24*N24 -> 2.63736
