Workbook

Sheet Rate_Master
A1: Tên hạng mục 專案名稱 | B1: Khối lượng 專案數量 | C1: Đơn giá chào
C2: Vật tư chính 主要材料 | D2: Nhân công + vật tư phụ+ máy thi công 人工+輔助材料+施工機械
A3: Nhà kho 1 一號倉庫 | C3: 0 | D3: 0
A4: KẾT CẤU BÊ TÔNG 混凝土結構 | C4: 0 | D4: 0
A5: Công tác cọc 基樁工項 | C5: 0 | D5: 0
A6: Huy động và giải thể thiết bị ép cọc 調動和拆除壓樁設備 | B6: 1 | C6: 0 | D6: 1.15e+08
A7: Cung cấp cọc thí nghiệm PHC D400A 提供PHC D400A試驗樁 | B7: 288 | C7: 425500 | D7: 0
A8: Thi công khoan dẫn cho cọc thí nghiệm PHC D400A PHC D400A試驗樁導孔施工 | B8: 264 | C8: 0 | D8: 69000
A9: Thi công ép cọc thí nghiệm PHC D400A PHC D400A試驗樁壓樁施工 | B9: 276 | C9: 0 | D9: 57500
A10: Thí nghiệm nén tĩnh cọc (khả năng chịu nén, bao gồm ép cọc thí nghiệm và thí nghiệm nghiệm thu khả năng chịu lực của cọc, cao độ đỉnh cọc là cao độ mặt đất sau khi san lấp mặt bằng, Sức chịu tải của cọc đơn là 1100kN, và Tải trọng thí nghiệm là 2200kN) 基樁靜載試驗(抗壓,含先行試打樁及承載力驗收樁檢測、樁頂標高為整地後地面標高，單樁抗壓承載力特徵值1100kN，試驗值為2200kN) | B10: 12 | C10: 0 | D10: 13800000
A11: Thí nghiệm biến dạng nhỏ PIT cho cọc 基樁小應變試驗 | B11: 237 | C11: 0 | D11: 253000
A12: Cung cấp cọc đại trà PHC D400A 提供PHC D400A工程樁 | B12: 25784 | C12: 402500 | D12: 0
A13: Cung cấp mũi cọc D400 提供D400樁尖 | B13: 1184 | C13: 80500 | D13: 0
A14: Thi công khoan dẫn cho cọc đại trà PHC D400A PHC D400A工程樁導孔施工 | B14: 25092.3 | C14: 0 | D14: 69000
A15: Thi công ép cọc đại trà PHC D400A PHC D400A工程樁壓樁施工 | B15: 26264.3 | C15: 0 | D15: 57500
A16: Xử lý đầu cọc D400 ( Bao gồm cắt , cốt thép, bê tông đầu cọc và vận chuyển đầu cọc thừa ra ngoài công trường nếu có) 樁頭處理D400mm(包括切割、鋼筋、樁頭混凝土以及將多餘的樁頭移運到工地外面) | B16: 1184 | C16: 483000 | D16: 161000
A17: Công tác đất 土方工項 | C17: 0 | D17: 0
A18: Đào đất móng, dầm móng 地基、基礎梁開挖 | B18: 5734.03 | C18: 0 | D18: 32200
A19: Đầm chặt đất đáy móng, dầm móng 將基礎底部土壤、基礎梁壓實 | B19: 4049.697 | C19: 0 | D19: 17250
A20: Lấp đất móng và đầm chặt 將基礎回填並壓實 | B20: 4200.136 | C20: 0 | D20: 37950
A21: Vận chuyển xử lý đất thừa ( Trong phạm vi công trường) 多餘土壤運輸和處理（施工現場內） | B21: 1533.894 | C21: 0 | D21: 32200
A22: Lớp nylon lót cho bê tông lót đài móng dầm móng 用於混凝土承台和基礎樑的尼龍墊層 | B22: 4049.697 | C22: 6900 | D22: 1725
A23: Lớp màng HDPE chống ẩm, chống thấm dày 0.3mm ( hàn nhiệt) cho sàn nền tầng 1 一樓地板防潮防水HDPE膜層0.3mm厚（熱焊接） | B23: 12881.334 | C23: 34500 | D23: 5750
A24: San gạt, lu nền hiện trạng nhà xưởng, độ chặt k>=0.90 整平並碾壓廠房現況地基，壓實系數k≥0.90 | B24: 12881.334 | C24: 0 | D24: 13800
A25: Cấp phối đá dăm loại II đầm chặt,dày 35cm, k>=0.92 二型碎石級配層35cm厚，壓實k>=0.92 | B25: 4526.726 | C25: 512325 | D25: 103500
A26: Công tác bê tông 混凝土工項 | C26: 0 | D26: 0
A27: Bê tông lót đá 1x2 B7.5 cho móng, dầm móng, nền 基礎、基礎樑、底層的石1x2 B7.5混凝土墊層 | B27: 407.88 | C27: 1249762.5 | D27: 207000
A28: Bê tông đá 1x2 B30 cho đài móng, dầm móng, cổ cột, vách hố pit thang máy,nền sàn tầng 1 承台、基礎樑、柱頸、電梯坑、一層地面的石1x2 B30混凝土 | B28: 6339.057 | C28: 1607444.4 | D28: 149500
A29: Bê tông đá 1x2 B30 cho cột từ tầng 1 đến tầng mái 從一層到屋頂的柱子採用石1x2 B30混凝土 | B29: 89.422 | C29: 1520555.6 | D29: 253000
A30: Bê tông đá 1x2 B30 cho dầm sàn từ tầng 2 đến tầng mái 二樓至屋頂地板樑的石1x2 B30混凝土 | B30: 135.26 | C30: 1520555.6 | D30: 149500
A31: Bê tông đá mi M250 bảo vệ lớp chống thấm mái 保護屋頂防水層的石M250混凝土 | B31: 20.93136 | C31: 1390222.2 | D31: 149500
A32: Bê tông đá mi M250 bảo vệ chân cột kết cấu thép thép 保護鋼結構柱腳之M250細石混凝土 | B32: 50.263 | C32: 1390222.2 | D32: 149500
A33: Vữa tự chảy không co ngót cường độ cao cho chân cột kết cấu thép ‌鋼結構柱腳的高強度無收縮自流砂漿 | B33: 2.51315 | C33: 22425000 | D33: 8004000
A34: Công tác ván khuôn 模板工項 | C34: 0 | D34: 0
A35: Ván khuôn bê tông lót cho móng, dầm móng, nền 基礎、基礎樑和地面的混凝土墊層模板 | B35: 1078.603 | C35: 80500 | D35: 92000
A36: Ván khuôn cho đài móng, dầm móng, cổ cột, vách hố pit thang máy,nền sàn tầng 1 承台、基礎樑、柱頸、電梯坑、一層地面的模板 | B36: 8972.119 | C36: 126500 | D36: 103500
A37: Ván khuôn cho cột từ tầng 1 đến tầng mái 從一樓到屋頂的柱子模板 | B37: 1160.744 | C37: 126500 | D37: 149500
A38: Ván khuôn cho dầm sàn từ tầng 2 đến tầng mái 二樓至屋頂地板樑的模板 | B38: 914.944 | C38: 126500 | D38: 115000
A39: Ván khuôn cho bê tông bảo vệ chân cột kết cấu thép ‌鋼結構柱腳保護混凝土之模板 | B39: 306.63 | C39: 126500 | D39: 97750
A40: Công tác cốt thép 鋼筋工項 | C40: 0 | D40: 0
...

Sheet 總表
A2: 工程標單 (I) 工 程 總 表 (Summary sheet)
B3: Chủ đầu tư 業主
B4: Dự án 工程名稱
B5: Địa điểm 工程名稱
B6: Hạng mục công trình
B7: Nhà thầu thi công | C7: Công ty TNHH Công trình L&K Việt Nam
A8: TT 專案 | B8: Tên hạng mục, mô tả thông số kỹ thuật 專案名稱﹑規格及說明 | C8: Đơn vị 单位 | D8: Khối lượng 專案數量 | E8: Đơn giá 專案單價 (VND) | F8: Đơn giá nhà thầu | G8: Thành Tiền 專案複價 (VND) | H8: Thành tiền nhà thầu | I8: Thông số kỹ thuật hoặc ghi chú của nhà thầu 廠商規格說明或備註
A9: A | B9: Công trình kiến trúc kỹ thuật 技術建築工程 | C9: Lot | D9: 1 | G9: =SUBTOTAL(9,G10:G34) -> 8.4416761e+11 | H9: =SUBTOTAL(9,H10:H34) -> #VALUE!
A10: 1A | B10: Nhà kho 1 一號倉庫 | C10: Lot | D10: 1 | E10: ='1A'!J9 -> 9.0448258e+10 | F10: =+'1A'!K9 -> 9.1218444e+10 | G10: =+D10*E10 -> 9.0448258e+10 | H10: =+D10*F10 -> 9.1218444e+10
A11: 2A | B11: Nhà xưởng sản xuất 1 一號生產廠房 | C11: Lot | D11: 1 | E11: ='2A'!J9 -> 8.6908269e+10 | F11: =+'2A'!K9 -> 8.7899232e+10 | G11: =+D11*E11 -> 8.6908269e+10 | H11: =+D11*F11 -> 8.7899232e+10
A12: 3A | B12: Nhà xưởng sản xuất 2 二號生產廠房 | C12: Lot | D12: 1 | E12: ='3A'!J9 -> 9.2953723e+10 | F12: =+'3A'!K9 -> 9.3648496e+10 | G12: =+D12*E12 -> 9.2953723e+10 | H12: =+D12*F12 -> 9.3648496e+10
A13: 4A | B13: Nhà xưởng sản xuất 3 三號生產廠房 | C13: Lot | D13: 1 | E13: ='4A'!K9 -> 1.1934102e+11 | F13: =+'4A'!L9 -> 1.347729e+11 | G13: =+D13*E13 -> 1.1934102e+11 | H13: =+D13*F13 -> 1.347729e+11
A14: 5A | B14: Nhà xưởng sản xuất 4 四號生產廠房 | C14: Lot | D14: 1 | E14: ='5A'!K9 -> 9.4570532e+10 | F14: =+'5A'!L9 -> 8.7712753e+10 | G14: =+D14*E14 -> 9.4570532e+10 | H14: =+D14*F14 -> 8.7712753e+10
A15: 6A | B15: Nhà xưởng sản xuất 5 五號生產廠房 | C15: Lot | D15: 1 | E15: ='6A'!J9 -> 7.3994582e+10 | F15: =+'6A'!K9 -> #VALUE! | G15: =+D15*E15 -> 7.3994582e+10 | H15: =+D15*F15 -> #VALUE!
A16: 7A | B16: Nhà kho 2 二號倉庫 | C16: Lot | D16: 1 | E16: ='7A'!J9 -> 7.1761269e+10 | F16: =+'7A'!K9 -> 7.2115055e+10 | G16: =+D16*E16 -> 7.1761269e+10 | H16: =+D16*F16 -> 7.2115055e+10
A17: 8A | B17: Nhà kho 3 三號倉庫 | C17: Lot | D17: 1 | E17: ='8A'!J9 -> 7.5544945e+10 | F17: =+'8A'!K9 -> 7.6319242e+10 | G17: =+D17*E17 -> 7.5544945e+10 | H17: =+D17*F17 -> 7.6319242e+10
A18: 9A | B18: Kho rác 垃圾房 | C18: Lot | D18: 1 | E18: ='9A'!J9 -> 2.2028741e+09 | F18: =+'9A'!K9 -> 2.2239642e+09 | G18: =+D18*E18 -> 2.2028741e+09 | H18: =+D18*F18 -> 2.2239642e+09
A19: 10A | B19: Kho rác thải nguy hại 危害廢物庫 | C19: Lot | D19: 1 | E19: ='10A'!J9 -> 1.9872462e+09 | F19: =+'10A'!K9 -> 1.9887652e+09 | G19: =+D19*E19 -> 1.9872462e+09 | H19: =+D19*F19 -> 1.9887652e+09
A20: 11A | B20: Nhà trộn sơn, kho sơn 調漆房+油漆倉庫 | C20: Lot | D20: 1 | E20: ='11A'!J9 -> 6.3706257e+09 | F20: =+'11A'!K9 -> 7.0217753e+09 | G20: =+D20*E20 -> 6.3706257e+09 | H20: =+D20*F20 -> 7.0217753e+09
A21: 12A | B21: Nhà bảo dưỡng 維修房 | C21: Lot | D21: 1 | E21: ='12A'!J9 -> 1.0644383e+10 | F21: =+'12A'!K9 -> 1.1369451e+10 | G21: =+D21*E21 -> 1.0644383e+10 | H21: =+D21*F21 -> 1.1369451e+10
A22: 13A | B22: Nhà văn phòng 辦公棟 | C22: Lot | D22: 1 | E22: ='13A'!J9 -> 4.9939374e+10 | F22: =+'13A'!K9 -> 5.0274529e+10 | G22: =+D22*E22 -> 4.9939374e+10 | H22: =+D22*F22 -> 5.0274529e+10
A23: 14A | B23: Nhà ăn 食堂 | C23: Lot | D23: 1 | E23: ='14A'!J9 -> 3.0179795e+10 | F23: =+'14A'!K9 -> 2.9821143e+10 | G23: =+D23*E23 -> 3.0179795e+10 | H23: =+D23*F23 -> 2.9821143e+10
A24: 15A | B24: Nhà xe 停車場 | C24: Lot | D24: 1 | E24: ='15A'!J9 -> 1.5242509e+10 | F24: =+'15A'!K9 -> 1.5248529e+10 | G24: =+D24*E24 -> 1.5242509e+10 | H24: =+D24*F24 -> 1.5248529e+10
A25: 16A | B25: Trạm biến áp số 1 一號變壓站 | C25: Lot | D25: 1 | E25: ='16A'!I9 -> 4.4041937e+09 | F25: =+E25 -> 4.4041937e+09 | G25: =+D25*E25 -> 4.4041937e+09 | H25: =+D25*F25 -> 4.4041937e+09
A26: 17A | B26: Trạm biến áp số 2 二號變壓站 | C26: Lot | D26: 1 | E26: ='17A'!I9 -> 3.1607899e+09 | F26: =+E26 -> 3.1607899e+09 | G26: =+D26*E26 -> 3.1607899e+09 | H26: =+D26*F26 -> 3.1607899e+09
A27: 18A | B27: Nhà bảo vệ số 1 一號警衛室 | C27: Lot | D27: 1 | E27: ='18A'!I9 -> 1.4731558e+09 | F27: =+E27 -> 1.4731558e+09 | G27: =+D27*E27 -> 1.4731558e+09 | H27: =+D27*F27 -> 1.4731558e+09
A28: 19A | B28: Nhà bảo vệ số 2 二號警衛室 | C28: Lot | D28: 1 | E28: ='19A'!I9 -> 1.3627036e+09 | F28: =+E28 -> 1.3627036e+09 | G28: =+D28*E28 -> 1.3627036e+09 | H28: =+D28*F28 -> 1.3627036e+09
A29: 20A | B29: Khu xử lý nước thải 廢水處理區 | C29: Lot | D29: 0 | E29: 0 | F29: 0 | G29: 0 | H29: 0 | I29: Không thuộc phạm vi gói thầu này ‌不屬於此標案的範圍內
A30: 21A | B30: Nhà máy bơm, bể nước sinh hoạt – sản xuất-PCCC 泵房-生活水池及生產水池-消防水池 | C30: Lot | D30: 1 | E30: ='21A'!J9 -> 3.6694775e+09 | F30: ='21A'!K9 -> 3.6828018e+09 | G30: =+D30*E30 -> 3.6694775e+09 | H30: =+D30*F30 -> 3.6828018e+09
A31: 22A | B31: Mái nối số 1~32 雨棚 | C31: Lot | D31: 1 | E31: ='22A'!J9 -> 6.064413e+09 | F31: ='22A'!K9 -> 5.550838e+09 | G31: =+D31*E31 -> 6.064413e+09 | H31: =+D31*F31 -> 5.550838e+09
A32: 23A | B32: Hồ cảnh quan 1 一號景觀湖 | C32: Lot | D32: 1 | E32: ='23A'!I9 -> 5.9028786e+08 | F32: =+E32 -> 5.9028786e+08 | G32: =+D32*E32 -> 5.9028786e+08 | H32: =+D32*F32 -> 5.9028786e+08
A33: 24A | B33: Hồ cảnh quan 2 二號景觀湖 | C33: Lot | D33: 1 | E33: ='24A'!I9 -> 7.1270155e+08 | F33: =+E33 -> 7.1270155e+08 | G33: =+D33*E33 -> 7.1270155e+08 | H33: =+D33*F33 -> 7.1270155e+08
A34: 25A | B34: Trạm cân 地磅 | C34: Lot | D34: 1 | E34: ='25A'!I9 -> 6.4048225e+08 | F34: =+E34 -> 6.4048225e+08 | G34: =+D34*E34 -> 6.4048225e+08 | H34: =+D34*F34 -> 6.4048225e+08
A35: B | B35: Công trình ngoài nhà 戶外工程 | C35: Lot | D35: 1 | G35: =SUBTOTAL(9,G36:G41) -> 1.0885127e+11 | H35: =SUBTOTAL(9,H36:H41) -> 1.0885127e+11
A36: 1B | B36: San lấp mặt bằng 場地土方回填 | C36: Lot | D36: 1 | E36: ='1B'!I9 -> 4562641176 | F36: =+E36 -> 4562641176 | G36: =+D36*E36 -> 4562641176 | H36: =+G36 -> 4562641176
A37: 2B | B37: Hàng rào 圍墻 | C37: Lot | D37: 1 | E37: ='2B'!I9 -> 1.8877214e+10 | F37: =+E37 -> 1.8877214e+10 | G37: =+D37*E37 -> 1.8877214e+10 | H37: =+G37 -> 1.8877214e+10
A38: 3B | B38: Hệ thống thoát nước mưa 雨水排水系統 | C38: Lot | D38: 1 | E38: ='3B'!I9 -> 38094529654 | F38: =+E38 -> 38094529654 | G38: =+D38*E38 -> 38094529654 | H38: =+G38 -> 38094529654
A39: 4B | B39: Hệ thống thoát nước thải 廢水排水系統 | C39: Lot | D39: 1 | E39: ='4B'!I9 -> 3370437250 | F39: =+E39 -> 3370437250 | G39: =+D39*E39 -> 3370437250 | H39: =+G39 -> 3370437250
A40: 5B | B40: Đường nội bộ 內部道路 | C40: Lot | D40: 1 | E40: ='5B'!I9 -> 3.3705494e+10 | F40: =+E40 -> 3.3705494e+10 | G40: =+D40*E40 -> 3.3705494e+10 | H40: =+G40 -> 3.3705494e+10
A41: 6B | B41: Cảnh quan 景觀 | C41: Lot | D41: 1 | E41: ='6B'!I9 -> 1.0240955e+10 | F41: =+E41 -> 1.0240955e+10 | G41: =+D41*E41 -> 1.0240955e+10 | H41: =+G41 -> 1.0240955e+10
...

Sheet 1A
A2: 工程標單 (II) 詳細價目表 (Detail sheet)
B3: Chủ đầu tư 業主
B4: Dự án 工程名稱
B5: Địa điểm 工程名稱
B6: Hạng mục công trình | C6: =INDEX(總表!$B$9:$B$47,MATCH('1A'!A9,總表!$A$9:$A$48,0)) -> Nhà kho 1 一號倉庫
B7: Nhà thầu thi công | C7: Công ty TNHH Công trình L&K Việt Nam
A8: TT 專案 | B8: Tên hạng mục 專案名稱 | C8: Thông số kỹ thuật , mô tả 規格及說明 | D8: Đơn vị 单位 | E8: Khối lượng 專案數量 | F8: Khối lượng Nhà thầu | G8: Vật tư chính 主要材料 | H8: Nhân công + vật tư phụ+ máy thi công 人工+輔助材料+施工機械 | I8: Đơn giá 專案單價 (VND) | J8: Thành Tiền 專案複價 (VND) | K8: Thành tiền Nhà thầu | L8: Ghi chú
A9: 1A | B9: =C6 -> Nhà kho 1 一號倉庫 | J9: =SUBTOTAL(9,J10:J174) -> 9.0448258e+10 | K9: =SUBTOTAL(9,K10:K173) -> 9.1218444e+10
A10: =$A$9&".C" -> 1A.C | B10: KẾT CẤU BÊ TÔNG 混凝土結構
A11: =$A$10&1 -> 1A.C1 | B11: Công tác cọc 基樁工項 | J11: =SUBTOTAL(9,J12:J22) -> 1.4974625e+10 | K11: =SUBTOTAL(9,K12:K22) -> 1.4974625e+10
A12: =$A$11&"."&ROW()-ROW($A$11) -> 1A.C1.1 | B12: Huy động và giải thể thiết bị ép cọc 調動和拆除壓樁設備 | D12: Set | E12: 1 | F12: 1 | G12: =_xlfn.XLOOKUP(B12, Rate_Master!$A:$A, Rate_Master!$C:$C, "") -> 0 | H12: =_xlfn.XLOOKUP(B12, Rate_Master!$A:$A, Rate_Master!$D:$D, "") -> 1.15e+08 | I12: =G12+H12 -> 1.15e+08 | J12: =I12*E12 -> 1.15e+08 | K12: =+F12*I12 -> 1.15e+08
A13: =$A$11&"."&ROW()-ROW($A$11) -> 1A.C1.2 | B13: Cung cấp cọc thí nghiệm PHC D400A 提供PHC D400A試驗樁 | D13: M | E13: 288 | F13: 288 | G13: =_xlfn.XLOOKUP(B13, Rate_Master!$A:$A, Rate_Master!$C:$C, "") -> 425500 | H13: =_xlfn.XLOOKUP(B13, Rate_Master!$A:$A, Rate_Master!$D:$D, "") -> 0 | I13: =G13+H13 -> 425500 | J13: =I13*E13 -> 1.22544e+08 | K13: =+F13*I13 -> 1.22544e+08
A14: =$A$11&"."&ROW()-ROW($A$11) -> 1A.C1.3 | B14: Thi công khoan dẫn cho cọc thí nghiệm PHC D400A PHC D400A試驗樁導孔施工 | D14: M | E14: 264 | F14: 264 | G14: =_xlfn.XLOOKUP(B14, Rate_Master!$A:$A, Rate_Master!$C:$C, "") -> 0 | H14: =_xlfn.XLOOKUP(B14, Rate_Master!$A:$A, Rate_Master!$D:$D, "") -> 69000 | I14: =G14+H14 -> 69000 | J14: =I14*E14 -> 18216000 | K14: =+F14*I14 -> 18216000
A15: =$A$11&"."&ROW()-ROW($A$11) -> 1A.C1.4 | B15: Thi công ép cọc thí nghiệm PHC D400A PHC D400A試驗樁壓樁施工 | D15: M | E15: 276 | F15: 276 | G15: =_xlfn.XLOOKUP(B15, Rate_Master!$A:$A, Rate_Master!$C:$C, "") -> 0 | H15: =_xlfn.XLOOKUP(B15, Rate_Master!$A:$A, Rate_Master!$D:$D, "") -> 57500 | I15: =G15+H15 -> 57500 | J15: =I15*E15 -> 15870000 | K15: =+F15*I15 -> 15870000
A16: =$A$11&"."&ROW()-ROW($A$11) -> 1A.C1.5 | B16: Thí nghiệm nén tĩnh cọc (khả năng chịu nén, bao gồm ép cọc thí nghiệm và thí nghiệm nghiệm thu khả năng chịu lực của cọc, cao độ đỉnh cọc là cao độ mặt đất sau khi san lấp mặt bằng, Sức chịu tải của cọc đơn là 1100kN, và Tải trọng thí nghiệm là 2200kN) 基樁靜載試驗(抗壓,含先行試打樁及承載力驗收樁檢測、樁頂標高為整地後地面標高，單樁抗壓承載力特徵值1100kN，試驗值為2200kN) | D16: Pcs | E16: 12 | F16: 12 | G16: =_xlfn.XLOOKUP(B16, Rate_Master!$A:$A, Rate_Master!$C:$C, "") -> 0 | H16: =_xlfn.XLOOKUP(B16, Rate_Master!$A:$A, Rate_Master!$D:$D, "") -> 13800000 | I16: =G16+H16 -> 13800000 | J16: =I16*E16 -> 1.656e+08 | K16: =+F16*I16 -> 1.656e+08
A17: =$A$11&"."&ROW()-ROW($A$11) -> 1A.C1.6 | B17: Thí nghiệm biến dạng nhỏ PIT cho cọc 基樁小應變試驗 | D17: Pcs | E17: 237 | F17: 237 | G17: =_xlfn.XLOOKUP(B17, Rate_Master!$A:$A, Rate_Master!$C:$C, "") -> 0 | H17: =_xlfn.XLOOKUP(B17, Rate_Master!$A:$A, Rate_Master!$D:$D, "") -> 253000 | I17: =G17+H17 -> 253000 | J17: =I17*E17 -> 59961000 | K17: =+F17*I17 -> 59961000
A18: =$A$11&"."&ROW()-ROW($A$11) -> 1A.C1.7 | B18: Cung cấp cọc đại trà PHC D400A 提供PHC D400A工程樁 | D18: M | E18: 25784 | F18: 25784 | G18: =_xlfn.XLOOKUP(B18, Rate_Master!$A:$A, Rate_Master!$C:$C, "") -> 402500 | H18: =_xlfn.XLOOKUP(B18, Rate_Master!$A:$A, Rate_Master!$D:$D, "") -> 0 | I18: =G18+H18 -> 402500 | J18: =I18*E18 -> 1.037806e+10 | K18: =+F18*I18 -> 1.037806e+10
A19: =$A$11&"."&ROW()-ROW($A$11) -> 1A.C1.8 | B19: Cung cấp mũi cọc D400 提供D400樁尖 | D19: Pcs | E19: 1184 | F19: 1184 | G19: =_xlfn.XLOOKUP(B19, Rate_Master!$A:$A, Rate_Master!$C:$C, "") -> 80500 | H19: =_xlfn.XLOOKUP(B19, Rate_Master!$A:$A, Rate_Master!$D:$D, "") -> 0 | I19: =G19+H19 -> 80500 | J19: =I19*E19 -> 95312000 | K19: =+F19*I19 -> 95312000
A20: =$A$11&"."&ROW()-ROW($A$11) -> 1A.C1.9 | B20: Thi công khoan dẫn cho cọc đại trà PHC D400A PHC D400A工程樁導孔施工 | D20: M | E20: 25092.3 | F20: 25092.3 | G20: =_xlfn.XLOOKUP(B20, Rate_Master!$A:$A, Rate_Master!$C:$C, "") -> 0 | H20: =_xlfn.XLOOKUP(B20, Rate_Master!$A:$A, Rate_Master!$D:$D, "") -> 69000 | I20: =G20+H20 -> 69000 | J20: =I20*E20 -> 1731368700 | K20: =+F20*I20 -> 1731368700
A21: =$A$11&"."&ROW()-ROW($A$11) -> 1A.C1.10 | B21: Thi công ép cọc đại trà PHC D400A PHC D400A工程樁壓樁施工 | D21: M | E21: 26264.3 | F21: 26264.3 | G21: =_xlfn.XLOOKUP(B21, Rate_Master!$A:$A, Rate_Master!$C:$C, "") -> 0 | H21: =_xlfn.XLOOKUP(B21, Rate_Master!$A:$A, Rate_Master!$D:$D, "") -> 57500 | I21: =G21+H21 -> 57500 | J21: =I21*E21 -> 1.5101972e+09 | K21: =+F21*I21 -> 1.5101972e+09
A22: =$A$11&"."&ROW()-ROW($A$11) -> 1A.C1.11 | B22: Xử lý đầu cọc D400 ( Bao gồm cắt , cốt thép, bê tông đầu cọc và vận chuyển đầu cọc thừa ra ngoài công trường nếu có) 樁頭處理D400mm(包括切割、鋼筋、樁頭混凝土以及將多餘的樁頭移運到工地外面) | D22: Pcs | E22: 1184 | F22: 1184 | G22: =_xlfn.XLOOKUP(B22, Rate_Master!$A:$A, Rate_Master!$C:$C, "") -> 483000 | H22: =_xlfn.XLOOKUP(B22, Rate_Master!$A:$A, Rate_Master!$D:$D, "") -> 161000 | I22: =G22+H22 -> 644000 | J22: =I22*E22 -> 762496000 | K22: =+F22*I22 -> 762496000
A23: =$A$10&2 -> 1A.C2 | B23: Công tác đất 土方工項 | G23: =_xlfn.XLOOKUP(B23, Rate_Master!$A:$A, Rate_Master!$C:$C, "") -> 0 | H23: =_xlfn.XLOOKUP(B23, Rate_Master!$A:$A, Rate_Master!$D:$D, "") -> 0 | J23: =SUBTOTAL(9,J24:J31) -> 3.9821154e+09 | K23: =SUBTOTAL(9,K24:K31) -> 3.9821154e+09
A24: =$A$23&"."&ROW()-ROW($A$23) -> 1A.C2.1 | B24: Đào đất móng, dầm móng 地基、基礎梁開挖 | D24: cum M3 | E24: 5734.03 | F24: 5734.03 | G24: =_xlfn.XLOOKUP(B24, Rate_Master!$A:$A, Rate_Master!$C:$C, "") -> 0 | H24: =_xlfn.XLOOKUP(B24, Rate_Master!$A:$A, Rate_Master!$D:$D, "") -> 32200 | I24: =G24+H24 -> 32200 | J24: =I24*E24 -> 1.8463577e+08 | K24: =+F24*I24 -> 1.8463577e+08
A25: =$A$23&"."&ROW()-ROW($A$23) -> 1A.C2.2 | B25: Đầm chặt đất đáy móng, dầm móng 將基礎底部土壤、基礎梁壓實 | D25: sqm M2 | E25: 4049.697 | F25: 4049.697 | G25: =_xlfn.XLOOKUP(B25, Rate_Master!$A:$A, Rate_Master!$C:$C, "") -> 0 | H25: =_xlfn.XLOOKUP(B25, Rate_Master!$A:$A, Rate_Master!$D:$D, "") -> 17250 | I25: =G25+H25 -> 17250 | J25: =I25*E25 -> 69857273 | K25: =+F25*I25 -> 69857273
A26: =$A$23&"."&ROW()-ROW($A$23) -> 1A.C2.3 | B26: Lấp đất móng và đầm chặt 將基礎回填並壓實 | D26: cum M3 | E26: 4200.136 | F26: 4200.136 | G26: =_xlfn.XLOOKUP(B26, Rate_Master!$A:$A, Rate_Master!$C:$C, "") -> 0 | H26: =_xlfn.XLOOKUP(B26, Rate_Master!$A:$A, Rate_Master!$D:$D, "") -> 37950 | I26: =G26+H26 -> 37950 | J26: =I26*E26 -> 1.5939516e+08 | K26: =+F26*I26 -> 1.5939516e+08
A27: =$A$23&"."&ROW()-ROW($A$23) -> 1A.C2.4 | B27: Vận chuyển xử lý đất thừa ( Trong phạm vi công trường) 多餘土壤運輸和處理（施工現場內） | C27: Tận dụng đắp nền nhà xưởng 回填利用廠房地坪 | D27: cum M3 | E27: 1533.894 | F27: 1533.894 | G27: =_xlfn.XLOOKUP(B27, Rate_Master!$A:$A, Rate_Master!$C:$C, "") -> 0 | H27: =_xlfn.XLOOKUP(B27, Rate_Master!$A:$A, Rate_Master!$D:$D, "") -> 32200 | I27: =G27+H27 -> 32200 | J27: =I27*E27 -> 49391387 | K27: =+F27*I27 -> 49391387
A28: =$A$23&"."&ROW()-ROW($A$23) -> 1A.C2.5 | B28: Lớp nylon lót cho bê tông lót đài móng dầm móng 用於混凝土承台和基礎樑的尼龍墊層 | D28: sqm M2 | E28: 4049.697 | F28: 4049.697 | G28: =_xlfn.XLOOKUP(B28, Rate_Master!$A:$A, Rate_Master!$C:$C, "") -> 6900 | H28: =_xlfn.XLOOKUP(B28, Rate_Master!$A:$A, Rate_Master!$D:$D, "") -> 1725 | I28: =G28+H28 -> 8625 | J28: =I28*E28 -> 34928637 | K28: =+F28*I28 -> 34928637
A29: =$A$23&"."&ROW()-ROW($A$23) -> 1A.C2.6 | B29: Lớp màng HDPE chống ẩm, chống thấm dày 0.3mm ( hàn nhiệt) cho sàn nền tầng 1 一樓地板防潮防水HDPE膜層0.3mm厚（熱焊接） | D29: sqm M2 | E29: 12881.334 | F29: 12881.334 | G29: =_xlfn.XLOOKUP(B29, Rate_Master!$A:$A, Rate_Master!$C:$C, "") -> 34500 | H29: =_xlfn.XLOOKUP(B29, Rate_Master!$A:$A, Rate_Master!$D:$D, "") -> 5750 | I29: =G29+H29 -> 40250 | J29: =I29*E29 -> 5.1847369e+08 | K29: =+F29*I29 -> 5.1847369e+08
A30: =$A$23&"."&ROW()-ROW($A$23) -> 1A.C2.7 | B30: San gạt, lu nền hiện trạng nhà xưởng, độ chặt k>=0.90 整平並碾壓廠房現況地基，壓實系數k≥0.90 | D30: sqm M2 | E30: 12881.334 | F30: 12881.334 | G30: =_xlfn.XLOOKUP(B30, Rate_Master!$A:$A, Rate_Master!$C:$C, "") -> 0 | H30: =_xlfn.XLOOKUP(B30, Rate_Master!$A:$A, Rate_Master!$D:$D, "") -> 13800 | I30: =G30+H30 -> 13800 | J30: =I30*E30 -> 1.7776241e+08 | K30: =+F30*I30 -> 1.7776241e+08
A31: =$A$23&"."&ROW()-ROW($A$23) -> 1A.C2.8 | B31: Cấp phối đá dăm loại II đầm chặt,dày 35cm, k>=0.92 二型碎石級配層35cm厚，壓實k>=0.92 | D31: cum M3 | E31: 4526.726 | F31: 4526.726 | G31: =_xlfn.XLOOKUP(B31, Rate_Master!$A:$A, Rate_Master!$C:$C, "") -> 512325 | H31: =_xlfn.XLOOKUP(B31, Rate_Master!$A:$A, Rate_Master!$D:$D, "") -> 103500 | I31: =G31+H31 -> 615825 | J31: =I31*E31 -> 2.787671e+09 | K31: =+F31*I31 -> 2.787671e+09
A32: =$A$10&3 -> 1A.C3 | B32: Công tác bê tông 混凝土工項 | G32: =_xlfn.XLOOKUP(B32, Rate_Master!$A:$A, Rate_Master!$C:$C, "") -> 0 | H32: =_xlfn.XLOOKUP(B32, Rate_Master!$A:$A, Rate_Master!$D:$D, "") -> 0 | J32: =SUBTOTAL(9,J33:J39) -> 1.2302134e+10 | K32: =SUBTOTAL(9,K33:K39) -> 1.2302134e+10
A33: =$A$32&"."&ROW()-ROW($A$32) -> 1A.C3.1 | B33: Bê tông lót đá 1x2 B7.5 cho móng, dầm móng, nền 基礎、基礎樑、底層的石1x2 B7.5混凝土墊層 | D33: cum M3 | E33: 407.88 | F33: 407.88 | G33: =_xlfn.XLOOKUP(B33, Rate_Master!$A:$A, Rate_Master!$C:$C, "") -> 1249762.5 | H33: =_xlfn.XLOOKUP(B33, Rate_Master!$A:$A, Rate_Master!$D:$D, "") -> 207000 | I33: =+H33+G33 -> 1456762.5 | J33: =I33*E33 -> 5.9418429e+08 | K33: =+F33*I33 -> 5.9418429e+08
A34: =$A$32&"."&ROW()-ROW($A$32) -> 1A.C3.2 | B34: Bê tông đá 1x2 B30 cho đài móng, dầm móng, cổ cột, vách hố pit thang máy,nền sàn tầng 1 承台、基礎樑、柱頸、電梯坑、一層地面的石1x2 B30混凝土 | D34: cum M3 | E34: 6339.057 | F34: 6339.057 | G34: =_xlfn.XLOOKUP(B34, Rate_Master!$A:$A, Rate_Master!$C:$C, "") -> 1607444.4 | H34: =_xlfn.XLOOKUP(B34, Rate_Master!$A:$A, Rate_Master!$D:$D, "") -> 149500 | I34: =+H34+G34 -> 1756944.4 | J34: =I34*E34 -> 1.1137371e+10 | K34: =+F34*I34 -> 1.1137371e+10
A35: =$A$32&"."&ROW()-ROW($A$32) -> 1A.C3.3 | B35: Bê tông đá 1x2 B30 cho cột từ tầng 1 đến tầng mái 從一層到屋頂的柱子採用石1x2 B30混凝土 | D35: cum M3 | E35: 89.422 | F35: 89.422 | G35: =_xlfn.XLOOKUP(B35, Rate_Master!$A:$A, Rate_Master!$C:$C, "") -> 1520555.6 | H35: =_xlfn.XLOOKUP(B35, Rate_Master!$A:$A, Rate_Master!$D:$D, "") -> 253000 | I35: =+H35+G35 -> 1773555.6 | J35: =I35*E35 -> 1.5859488e+08 | K35: =+F35*I35 -> 1.5859488e+08
A36: =$A$32&"."&ROW()-ROW($A$32) -> 1A.C3.4 | B36: Bê tông đá 1x2 B30 cho dầm sàn từ tầng 2 đến tầng mái 二樓至屋頂地板樑的石1x2 B30混凝土 | D36: cum M3 | E36: 135.26 | F36: 135.26 | G36: =_xlfn.XLOOKUP(B36, Rate_Master!$A:$A, Rate_Master!$C:$C, "") -> 1520555.6 | H36: =_xlfn.XLOOKUP(B36, Rate_Master!$A:$A, Rate_Master!$D:$D, "") -> 149500 | I36: =+H36+G36 -> 1670055.6 | J36: =I36*E36 -> 2.2589171e+08 | K36: =+F36*I36 -> 2.2589171e+08
A37: =$A$32&"."&ROW()-ROW($A$32) -> 1A.C3.5 | B37: Bê tông đá mi M250 bảo vệ lớp chống thấm mái 保護屋頂防水層的石M250混凝土 | D37: cum M3 | E37: 20.93136 | F37: 20.93136 | G37: =_xlfn.XLOOKUP(B37, Rate_Master!$A:$A, Rate_Master!$C:$C, "") -> 1390222.2 | H37: =_xlfn.XLOOKUP(B37, Rate_Master!$A:$A, Rate_Master!$D:$D, "") -> 149500 | I37: =+H37+G37 -> 1539722.2 | J37: =I37*E37 -> 32228480 | K37: =+F37*I37 -> 32228480
A38: =$A$32&"."&ROW()-ROW($A$32) -> 1A.C3.6 | B38: Bê tông đá mi M250 bảo vệ chân cột kết cấu thép thép 保護鋼結構柱腳之M250細石混凝土 | D38: cum M3 | E38: 50.263 | F38: 50.263 | G38: =_xlfn.XLOOKUP(B38, Rate_Master!$A:$A, Rate_Master!$C:$C, "") -> 1390222.2 | H38: =_xlfn.XLOOKUP(B38, Rate_Master!$A:$A, Rate_Master!$D:$D, "") -> 149500 | I38: =+H38+G38 -> 1539722.2 | J38: =I38*E38 -> 77391058 | K38: =+F38*I38 -> 77391058
A39: =$A$32&"."&ROW()-ROW($A$32) -> 1A.C3.7 | B39: Vữa tự chảy không co ngót cường độ cao cho chân cột kết cấu thép ‌鋼結構柱腳的高強度無收縮自流砂漿 | D39: cum M3 | E39: 2.51315 | F39: 2.51315 | G39: =_xlfn.XLOOKUP(B39, Rate_Master!$A:$A, Rate_Master!$C:$C, "") -> 22425000 | H39: =_xlfn.XLOOKUP(B39, Rate_Master!$A:$A, Rate_Master!$D:$D, "") -> 8004000 | I39: =+H39+G39 -> 30429000 | J39: =I39*E39 -> 76472641 | K39: =+F39*I39 -> 76472641
A40: =$A$10&4 -> 1A.C4 | B40: Công tác ván khuôn 模板工項 | G40: =_xlfn.XLOOKUP(B40, Rate_Master!$A:$A, Rate_Master!$C:$C, "") -> 0 | H40: =_xlfn.XLOOKUP(B40, Rate_Master!$A:$A, Rate_Master!$D:$D, "") -> 0 | J40: =SUBTOTAL(9,J41:J45) -> 2859732485 | K40: =SUBTOTAL(9,K41:K45) -> 2859732485
A41: =$A$40&"."&ROW()-ROW($A$40) -> 1A.C4.1 | B41: Ván khuôn bê tông lót cho móng, dầm móng, nền 基礎、基礎樑和地面的混凝土墊層模板 | D41: sqm M2 | E41: 1078.603 | F41: 1078.603 | G41: =_xlfn.XLOOKUP(B41, Rate_Master!$A:$A, Rate_Master!$C:$C, "") -> 80500 | H41: =_xlfn.XLOOKUP(B41, Rate_Master!$A:$A, Rate_Master!$D:$D, "") -> 92000 | I41: =+H41+G41 -> 172500 | J41: =I41*E41 -> 1.8605902e+08 | K41: =+F41*I41 -> 1.8605902e+08
...

Sheet 2A
A2: 工程標單 (II) 詳細價目表 (Detail sheet)
B3: Chủ đầu tư 業主
B4: Dự án 工程名稱
B5: Địa điểm 工程名稱
B6: Hạng mục công trình | C6: =INDEX(總表!$B$9:$B$47,MATCH('2A'!A9,總表!$A$9:$A$48,0)) -> Nhà xưởng sản xuất 1 一號生產廠房
B7: Nhà thầu thi công | C7: Công ty TNHH Công trình L&K Việt Nam
A8: TT 專案 | B8: Tên hạng mục 專案名稱 | C8: Thông số kỹ thuật , mô tả 規格及說明 | D8: Đơn vị 单位 | E8: Khối lượng 專案數量 | F8: Khối lượng Nhà thầu | G8: Vật tư chính 主要材料 | H8: Nhân công + vật tư phụ+ máy thi công 人工+輔助材料+施工機械 | I8: Đơn giá 專案單價 (VND) | J8: Thành Tiền 專案複價 (VND) | K8: Thành tiền Nhà thầu | L8: Ghi chú
A9: 2A | B9: =C6 -> Nhà xưởng sản xuất 1 一號生產廠房 | G9: =_xlfn.XLOOKUP(B9, Rate_Master!$A:$A, Rate_Master!$C:$C, "") -> 0 | H9: =_xlfn.XLOOKUP(B9, Rate_Master!$A:$A, Rate_Master!$D:$D, "") -> 0 | J9: =SUBTOTAL(9,J10:J172) -> 8.6908269e+10 | K9: =SUBTOTAL(9,K10:K172) -> 8.7899232e+10
A10: =$A$9&".C" -> 2A.C | B10: KẾT CẤU BÊ TÔNG 混凝土結構 | G10: =_xlfn.XLOOKUP(B10, Rate_Master!$A:$A, Rate_Master!$C:$C, "") -> 0 | H10: =_xlfn.XLOOKUP(B10, Rate_Master!$A:$A, Rate_Master!$D:$D, "") -> 0
A11: =$A$10&1 -> 2A.C1 | B11: Công tác cọc 基樁工項 | G11: =_xlfn.XLOOKUP(B11, Rate_Master!$A:$A, Rate_Master!$C:$C, "") -> 0 | H11: =_xlfn.XLOOKUP(B11, Rate_Master!$A:$A, Rate_Master!$D:$D, "") -> 0 | J11: =SUBTOTAL(9,J12:J22) -> 1.4994592e+10 | K11: =SUBTOTAL(9,K12:K22) -> 1.4994592e+10
A12: =$A$11&"."&ROW()-ROW($A$11) -> 2A.C1.1 | B12: Huy động và giải thể thiết bị ép cọc 調動和拆除壓樁設備 | D12: Set | E12: 1 | F12: 1 | G12: =_xlfn.XLOOKUP(B12, Rate_Master!$A:$A, Rate_Master!$C:$C, "") -> 0 | H12: =_xlfn.XLOOKUP(B12, Rate_Master!$A:$A, Rate_Master!$D:$D, "") -> 1.15e+08 | I12: =G12+H12 -> 1.15e+08 | J12: =I12*E12 -> 1.15e+08 | K12: =I12*F12 -> 1.15e+08
A13: =$A$11&"."&ROW()-ROW($A$11) -> 2A.C1.2 | B13: Cung cấp cọc thí nghiệm PHC D400A 提供PHC D400A試驗樁 | D13: M | E13: 288 | F13: 288 | G13: =_xlfn.XLOOKUP(B13, Rate_Master!$A:$A, Rate_Master!$C:$C, "") -> 425500 | H13: =_xlfn.XLOOKUP(B13, Rate_Master!$A:$A, Rate_Master!$D:$D, "") -> 0 | I13: =G13+H13 -> 425500 | J13: =I13*E13 -> 1.22544e+08 | K13: =I13*F13 -> 1.22544e+08
A14: =$A$11&"."&ROW()-ROW($A$11) -> 2A.C1.3 | B14: Thi công khoan dẫn cho cọc thí nghiệm PHC D400A PHC D400A試驗樁導孔施工 | D14: M | E14: 264 | F14: 264 | G14: =_xlfn.XLOOKUP(B14, Rate_Master!$A:$A, Rate_Master!$C:$C, "") -> 0 | H14: =_xlfn.XLOOKUP(B14, Rate_Master!$A:$A, Rate_Master!$D:$D, "") -> 69000 | I14: =G14+H14 -> 69000 | J14: =I14*E14 -> 18216000 | K14: =I14*F14 -> 18216000
A15: =$A$11&"."&ROW()-ROW($A$11) -> 2A.C1.4 | B15: Thi công ép cọc thí nghiệm PHC D400A PHC D400A試驗樁壓樁施工 | D15: M | E15: 276 | F15: 276 | G15: =_xlfn.XLOOKUP(B15, Rate_Master!$A:$A, Rate_Master!$C:$C, "") -> 0 | H15: =_xlfn.XLOOKUP(B15, Rate_Master!$A:$A, Rate_Master!$D:$D, "") -> 57500 | I15: =G15+H15 -> 57500 | J15: =I15*E15 -> 15870000 | K15: =I15*F15 -> 15870000
A16: =$A$11&"."&ROW()-ROW($A$11) -> 2A.C1.5 | B16: Thí nghiệm nén tĩnh cọc (khả năng chịu nén, bao gồm ép cọc thí nghiệm và thí nghiệm nghiệm thu khả năng chịu lực của cọc, cao độ đỉnh cọc là cao độ mặt đất sau khi san lấp mặt bằng, Sức chịu tải của cọc đơn là 1100kN, và Tải trọng thí nghiệm là 2200kN) 基樁靜載試驗(抗壓,含先行試打樁及承載力驗收樁檢測、樁頂標高為整地後地面標高，單樁抗壓承載力特徵值1100kN，試驗值為2200kN) | D16: Pcs | E16: 12 | F16: 12 | G16: =_xlfn.XLOOKUP(B16, Rate_Master!$A:$A, Rate_Master!$C:$C, "") -> 0 | H16: =_xlfn.XLOOKUP(B16, Rate_Master!$A:$A, Rate_Master!$D:$D, "") -> 13800000 | I16: =G16+H16 -> 13800000 | J16: =I16*E16 -> 1.656e+08 | K16: =I16*F16 -> 1.656e+08
A17: =$A$11&"."&ROW()-ROW($A$11) -> 2A.C1.6 | B17: Thí nghiệm biến dạng nhỏ PIT cho cọc 基樁小應變試驗 | D17: Pcs | E17: 238 | F17: 238 | G17: =_xlfn.XLOOKUP(B17, Rate_Master!$A:$A, Rate_Master!$C:$C, "") -> 0 | H17: =_xlfn.XLOOKUP(B17, Rate_Master!$A:$A, Rate_Master!$D:$D, "") -> 253000 | I17: =G17+H17 -> 253000 | J17: =I17*E17 -> 60214000 | K17: =I17*F17 -> 60214000
A18: =$A$11&"."&ROW()-ROW($A$11) -> 2A.C1.7 | B18: Cung cấp cọc đại trà PHC D400A 提供PHC D400A工程樁 | D18: M | E18: 25850 | F18: 25850 | G18: =_xlfn.XLOOKUP(B18, Rate_Master!$A:$A, Rate_Master!$C:$C, "") -> 402500 | H18: =_xlfn.XLOOKUP(B18, Rate_Master!$A:$A, Rate_Master!$D:$D, "") -> 0 | I18: =G18+H18 -> 402500 | J18: =I18*E18 -> 1.0404625e+10 | K18: =I18*F18 -> 1.0404625e+10
A19: =$A$11&"."&ROW()-ROW($A$11) -> 2A.C1.8 | B19: Cung cấp mũi cọc D400 提供D400樁尖 | D19: Pcs | E19: 1187 | F19: 1187 | G19: =_xlfn.XLOOKUP(B19, Rate_Master!$A:$A, Rate_Master!$C:$C, "") -> 80500 | H19: =_xlfn.XLOOKUP(B19, Rate_Master!$A:$A, Rate_Master!$D:$D, "") -> 0 | I19: =G19+H19 -> 80500 | J19: =I19*E19 -> 95553500 | K19: =I19*F19 -> 95553500
A20: =$A$11&"."&ROW()-ROW($A$11) -> 2A.C1.9 | B20: Thi công khoan dẫn cho cọc đại trà PHC D400A PHC D400A工程樁導孔施工 | D20: M | E20: 25019.6 | F20: 25019.6 | G20: =_xlfn.XLOOKUP(B20, Rate_Master!$A:$A, Rate_Master!$C:$C, "") -> 0 | H20: =_xlfn.XLOOKUP(B20, Rate_Master!$A:$A, Rate_Master!$D:$D, "") -> 69000 | I20: =G20+H20 -> 69000 | J20: =I20*E20 -> 1726352400 | K20: =I20*F20 -> 1726352400
A21: =$A$11&"."&ROW()-ROW($A$11) -> 2A.C1.10 | B21: Thi công ép cọc đại trà PHC D400A PHC D400A工程樁壓樁施工 | D21: M | E21: 26194.6 | F21: 26194.6 | G21: =_xlfn.XLOOKUP(B21, Rate_Master!$A:$A, Rate_Master!$C:$C, "") -> 0 | H21: =_xlfn.XLOOKUP(B21, Rate_Master!$A:$A, Rate_Master!$D:$D, "") -> 57500 | I21: =G21+H21 -> 57500 | J21: =I21*E21 -> 1.5061895e+09 | K21: =I21*F21 -> 1.5061895e+09
A22: =$A$11&"."&ROW()-ROW($A$11) -> 2A.C1.11 | B22: Xử lý đầu cọc D400 ( Bao gồm cắt , cốt thép, bê tông đầu cọc và vận chuyển đầu cọc thừa ra ngoài công trường nếu có) 樁頭處理D400mm(包括切割、鋼筋、樁頭混凝土以及將多餘的樁頭移運到工地外面) | D22: Pcs | E22: 1187 | F22: 1187 | G22: =_xlfn.XLOOKUP(B22, Rate_Master!$A:$A, Rate_Master!$C:$C, "") -> 483000 | H22: =_xlfn.XLOOKUP(B22, Rate_Master!$A:$A, Rate_Master!$D:$D, "") -> 161000 | I22: =G22+H22 -> 644000 | J22: =I22*E22 -> 764428000 | K22: =I22*F22 -> 764428000
A23: =$A$10&2 -> 2A.C2 | B23: Công tác đất 土方工項 | G23: =_xlfn.XLOOKUP(B23, Rate_Master!$A:$A, Rate_Master!$C:$C, "") -> 0 | H23: =_xlfn.XLOOKUP(B23, Rate_Master!$A:$A, Rate_Master!$D:$D, "") -> 0 | J23: =SUBTOTAL(9,J24:J31) -> 3.8083103e+09 | K23: =SUBTOTAL(9,K24:K31) -> 3.8083103e+09
A24: =$A$23&"."&ROW()-ROW($A$23) -> 2A.C2.1 | B24: Đào đất móng, dầm móng 地基、基礎梁開挖 | D24: cum M3 | E24: 3749.482 | F24: 3749.482 | G24: =_xlfn.XLOOKUP(B24, Rate_Master!$A:$A, Rate_Master!$C:$C, "") -> 0 | H24: =_xlfn.XLOOKUP(B24, Rate_Master!$A:$A, Rate_Master!$D:$D, "") -> 32200 | I24: =G24+H24 -> 32200 | J24: =I24*E24 -> 1.2073332e+08 | K24: =I24*F24 -> 1.2073332e+08
A25: =$A$23&"."&ROW()-ROW($A$23) -> 2A.C2.2 | B25: Đầm chặt đất đáy móng, dầm móng 將基礎底部土壤、基礎梁壓實 | D25: sqm M2 | E25: 4055.43 | F25: 4055.43 | G25: =_xlfn.XLOOKUP(B25, Rate_Master!$A:$A, Rate_Master!$C:$C, "") -> 0 | H25: =_xlfn.XLOOKUP(B25, Rate_Master!$A:$A, Rate_Master!$D:$D, "") -> 17250 | I25: =G25+H25 -> 17250 | J25: =I25*E25 -> 69956168 | K25: =I25*F25 -> 69956168
A26: =$A$23&"."&ROW()-ROW($A$23) -> 2A.C2.3 | B26: Lấp đất móng và đầm chặt 將基礎回填並壓實 | D26: cum M3 | E26: 2420.016 | F26: 2420.016 | G26: =_xlfn.XLOOKUP(B26, Rate_Master!$A:$A, Rate_Master!$C:$C, "") -> 0 | H26: =_xlfn.XLOOKUP(B26, Rate_Master!$A:$A, Rate_Master!$D:$D, "") -> 37950 | I26: =G26+H26 -> 37950 | J26: =I26*E26 -> 91839607 | K26: =I26*F26 -> 91839607
A27: =$A$23&"."&ROW()-ROW($A$23) -> 2A.C2.4 | B27: Vận chuyển xử lý đất thừa ( Trong phạm vi công trường) 多餘土壤運輸和處理（施工現場內） | C27: Tận dụng đắp nền nhà xưởng 回填利用廠房地坪 | D27: cum M3 | E27: 1329.466 | F27: 1329.466 | G27: =_xlfn.XLOOKUP(B27, Rate_Master!$A:$A, Rate_Master!$C:$C, "") -> 0 | H27: =_xlfn.XLOOKUP(B27, Rate_Master!$A:$A, Rate_Master!$D:$D, "") -> 32200 | I27: =G27+H27 -> 32200 | J27: =I27*E27 -> 42808805 | K27: =I27*F27 -> 42808805
A28: =$A$23&"."&ROW()-ROW($A$23) -> 2A.C2.5 | B28: Lớp nylon lót cho bê tông lót đài móng dầm móng 用於混凝土承台和基礎樑的尼龍墊層 | D28: sqm M2 | E28: 4055.43 | F28: 4055.43 | G28: =_xlfn.XLOOKUP(B28, Rate_Master!$A:$A, Rate_Master!$C:$C, "") -> 6900 | H28: =_xlfn.XLOOKUP(B28, Rate_Master!$A:$A, Rate_Master!$D:$D, "") -> 1725 | I28: =G28+H28 -> 8625 | J28: =I28*E28 -> 34978084 | K28: =I28*F28 -> 34978084
A29: =$A$23&"."&ROW()-ROW($A$23) -> 2A.C2.6 | B29: Lớp màng HDPE chống ẩm, chống thấm dày 0.3mm ( hàn nhiệt) cho sàn nền tầng 1 一樓地板防潮防水HDPE膜層0.3mm厚（熱焊接） | D29: sqm M2 | E29: 12742.656 | F29: 12742.656 | G29: =_xlfn.XLOOKUP(B29, Rate_Master!$A:$A, Rate_Master!$C:$C, "") -> 34500 | H29: =_xlfn.XLOOKUP(B29, Rate_Master!$A:$A, Rate_Master!$D:$D, "") -> 5750 | I29: =G29+H29 -> 40250 | J29: =I29*E29 -> 5.128919e+08 | K29: =I29*F29 -> 5.128919e+08
A30: =$A$23&"."&ROW()-ROW($A$23) -> 2A.C2.7 | B30: San gạt, lu nền hiện trạng nhà xưởng, độ chặt k>=0.90 整平並碾壓廠房現況地基，壓實系數k≥0.90 | D30: sqm M2 | E30: 12742.656 | F30: 12742.656 | G30: =_xlfn.XLOOKUP(B30, Rate_Master!$A:$A, Rate_Master!$C:$C, "") -> 0 | H30: =_xlfn.XLOOKUP(B30, Rate_Master!$A:$A, Rate_Master!$D:$D, "") -> 13800 | I30: =G30+H30 -> 13800 | J30: =I30*E30 -> 1.7584865e+08 | K30: =I30*F30 -> 1.7584865e+08
A31: =$A$23&"."&ROW()-ROW($A$23) -> 2A.C2.8 | B31: Cấp phối đá dăm loại II đầm chặt,dày 35cm, k>=0.92 二型碎石級配層35cm厚，壓實k>=0.92 | D31: cum M3 | E31: 4480.581 | F31: 4480.581 | G31: =_xlfn.XLOOKUP(B31, Rate_Master!$A:$A, Rate_Master!$C:$C, "") -> 512325 | H31: =_xlfn.XLOOKUP(B31, Rate_Master!$A:$A, Rate_Master!$D:$D, "") -> 103500 | I31: =G31+H31 -> 615825 | J31: =I31*E31 -> 2.7592538e+09 | K31: =I31*F31 -> 2.7592538e+09
A32: =$A$10&3 -> 2A.C3 | B32: Công tác bê tông 混凝土工項 | G32: =_xlfn.XLOOKUP(B32, Rate_Master!$A:$A, Rate_Master!$C:$C, "") -> 0 | H32: =_xlfn.XLOOKUP(B32, Rate_Master!$A:$A, Rate_Master!$D:$D, "") -> 0 | J32: =SUBTOTAL(9,J33:J39) -> 1.1916675e+10 | K32: =SUBTOTAL(9,K33:K39) -> 1.1916675e+10
A33: =$A$32&"."&ROW()-ROW($A$32) -> 2A.C3.1 | B33: Bê tông lót đá 1x2 B7.5 cho móng, dầm móng, nền 基礎、基礎樑、底層的石1x2 B7.5混凝土墊層 | D33: cum M3 | E33: 408.693 | F33: 408.693 | G33: =_xlfn.XLOOKUP(B33, Rate_Master!$A:$A, Rate_Master!$C:$C, "") -> 1249762.5 | H33: =_xlfn.XLOOKUP(B33, Rate_Master!$A:$A, Rate_Master!$D:$D, "") -> 207000 | I33: =+H33+G33 -> 1456762.5 | J33: =I33*E33 -> 5.9536864e+08 | K33: =I33*F33 -> 5.9536864e+08
A34: =$A$32&"."&ROW()-ROW($A$32) -> 2A.C3.2 | B34: Bê tông đá 1x2 B30 cho đài móng, dầm móng, cổ cột, vách hố pit thang máy,nền sàn tầng 1 承台、基礎樑、柱頸、電梯坑、一層地面的石1x2 B30混凝土 | D34: cum M3 | E34: 6225.379 | F34: 6225.379 | G34: =_xlfn.XLOOKUP(B34, Rate_Master!$A:$A, Rate_Master!$C:$C, "") -> 1607444.4 | H34: =_xlfn.XLOOKUP(B34, Rate_Master!$A:$A, Rate_Master!$D:$D, "") -> 149500 | I34: =+H34+G34 -> 1756944.4 | J34: =I34*E34 -> 1.0937645e+10 | K34: =I34*F34 -> 1.0937645e+10
A35: =$A$32&"."&ROW()-ROW($A$32) -> 2A.C3.3 | B35: Bê tông đá 1x2 B30 cho cột từ tầng 1 đến tầng mái 從一層到屋頂的柱子採用石1x2 B30混凝土 | D35: cum M3 | E35: 83.051 | F35: 83.051 | G35: =_xlfn.XLOOKUP(B35, Rate_Master!$A:$A, Rate_Master!$C:$C, "") -> 1520555.6 | H35: =_xlfn.XLOOKUP(B35, Rate_Master!$A:$A, Rate_Master!$D:$D, "") -> 253000 | I35: =+H35+G35 -> 1773555.6 | J35: =I35*E35 -> 1.4729556e+08 | K35: =I35*F35 -> 1.4729556e+08
A36: =$A$32&"."&ROW()-ROW($A$32) -> 2A.C3.4 | B36: Bê tông đá 1x2 B30 cho dầm sàn từ tầng 2 đến tầng mái 二樓至屋頂地板樑的石1x2 B30混凝土 | D36: cum M3 | E36: 49.571 | F36: 49.571 | G36: =_xlfn.XLOOKUP(B36, Rate_Master!$A:$A, Rate_Master!$C:$C, "") -> 1520555.6 | H36: =_xlfn.XLOOKUP(B36, Rate_Master!$A:$A, Rate_Master!$D:$D, "") -> 149500 | I36: =+H36+G36 -> 1670055.6 | J36: =I36*E36 -> 82786324 | K36: =I36*F36 -> 82786324
A37: =$A$32&"."&ROW()-ROW($A$32) -> 2A.C3.5 | B37: Bê tông đá mi M250 bảo vệ lớp chống thấm mái 保護屋頂防水層的石M250混凝土 | D37: cum M3 | E37: 3.22914 | F37: 3.22914 | G37: =_xlfn.XLOOKUP(B37, Rate_Master!$A:$A, Rate_Master!$C:$C, "") -> 1390222.2 | H37: =_xlfn.XLOOKUP(B37, Rate_Master!$A:$A, Rate_Master!$D:$D, "") -> 149500 | I37: =+H37+G37 -> 1539722.2 | J37: =I37*E37 -> 4971978.6 | K37: =I37*F37 -> 4971978.6
A38: =$A$32&"."&ROW()-ROW($A$32) -> 2A.C3.6 | B38: Bê tông đá mi M250 bảo vệ chân cột kết cấu thép thép 保護鋼結構柱腳之M250細石混凝土 | D38: cum M3 | E38: 48.546 | F38: 48.546 | G38: =_xlfn.XLOOKUP(B38, Rate_Master!$A:$A, Rate_Master!$C:$C, "") -> 1390222.2 | H38: =_xlfn.XLOOKUP(B38, Rate_Master!$A:$A, Rate_Master!$D:$D, "") -> 149500 | I38: =+H38+G38 -> 1539722.2 | J38: =I38*E38 -> 74747355 | K38: =I38*F38 -> 74747355
A39: =$A$32&"."&ROW()-ROW($A$32) -> 2A.C3.7 | B39: Vữa tự chảy không co ngót cường độ cao cho chân cột kết cấu thép ‌鋼結構柱腳的高強度無收縮自流砂漿 | D39: cum M3 | E39: 2.4273 | F39: 2.4273 | G39: =_xlfn.XLOOKUP(B39, Rate_Master!$A:$A, Rate_Master!$C:$C, "") -> 22425000 | H39: =_xlfn.XLOOKUP(B39, Rate_Master!$A:$A, Rate_Master!$D:$D, "") -> 8004000 | I39: =+H39+G39 -> 30429000 | J39: =I39*E39 -> 73860312 | K39: =I39*F39 -> 73860312
A40: =$A$10&4 -> 2A.C4 | B40: Công tác ván khuôn 模板工項 | G40: =_xlfn.XLOOKUP(B40, Rate_Master!$A:$A, Rate_Master!$C:$C, "") -> 0 | H40: =_xlfn.XLOOKUP(B40, Rate_Master!$A:$A, Rate_Master!$D:$D, "") -> 0 | J40: =SUBTOTAL(9,J41:J45) -> 2.511177e+09 | K40: =SUBTOTAL(9,K41:K45) -> 2.511177e+09
A41: =$A$40&"."&ROW()-ROW($A$40) -> 2A.C4.1 | B41: Ván khuôn bê tông lót cho móng, dầm móng, nền 基礎、基礎樑和地面的混凝土墊層模板 | D41: sqm M2 | E41: 1091.083 | F41: 1091.083 | G41: =_xlfn.XLOOKUP(B41, Rate_Master!$A:$A, Rate_Master!$C:$C, "") -> 80500 | H41: =_xlfn.XLOOKUP(B41, Rate_Master!$A:$A, Rate_Master!$D:$D, "") -> 92000 | I41: =+H41+G41 -> 172500 | J41: =I41*E41 -> 1.8821182e+08 | K41: =I41*F41 -> 1.8821182e+08
...

Sheet 3A
A2: 工程標單 (II) 詳細價目表 (Detail sheet)
B3: Chủ đầu tư 業主
B4: Dự án 工程名稱
B5: Địa điểm 工程名稱
B6: Hạng mục công trình | C6: =INDEX(總表!$B$9:$B$47,MATCH('3A'!A9,總表!$A$9:$A$48,0)) -> Nhà xưởng sản xuất 2 二號生產廠房
B7: Nhà thầu thi công | C7: Công ty TNHH Công trình L&K Việt Nam
A8: TT 專案 | B8: Tên hạng mục 專案名稱 | C8: Thông số kỹ thuật , mô tả 規格及說明 | D8: Đơn vị 单位 | E8: Khối lượng 專案數量 | F8: Khối lượng Nhà thầu | G8: Vật tư chính 主要材料 | H8: Nhân công + vật tư phụ+ máy thi công 人工+輔助材料+施工機械 | I8: Đơn giá 專案單價 (VND) | J8: Thành Tiền 專案複價 (VND) | K8: Thành tiền Nhà thầu | L8: Ghi chú
A9: 3A | B9: =C6 -> Nhà xưởng sản xuất 2 二號生產廠房 | G9: =_xlfn.XLOOKUP(B9, Rate_Master!$A:$A, Rate_Master!$C:$C, "") -> 0 | H9: =_xlfn.XLOOKUP(B9, Rate_Master!$A:$A, Rate_Master!$D:$D, "") -> 0 | J9: =SUBTOTAL(9,J10:J184) -> 9.2953723e+10 | K9: =SUBTOTAL(9,K10:K184) -> 9.3648496e+10
A10: =$A$9&".C" -> 3A.C | B10: KẾT CẤU BÊ TÔNG 混凝土結構 | G10: =_xlfn.XLOOKUP(B10, Rate_Master!$A:$A, Rate_Master!$C:$C, "") -> 0 | H10: =_xlfn.XLOOKUP(B10, Rate_Master!$A:$A, Rate_Master!$D:$D, "") -> 0
A11: =$A$10&1 -> 3A.C1 | B11: Công tác cọc 基樁工項 | G11: =_xlfn.XLOOKUP(B11, Rate_Master!$A:$A, Rate_Master!$C:$C, "") -> 0 | H11: =_xlfn.XLOOKUP(B11, Rate_Master!$A:$A, Rate_Master!$D:$D, "") -> 0 | J11: =SUBTOTAL(9,J12:J22) -> 1.5131364e+10 | K11: =SUBTOTAL(9,K12:K22) -> 1.5131364e+10
A12: =$A$11&"."&ROW()-ROW($A$11) -> 3A.C1.1 | B12: Huy động và giải thể thiết bị ép cọc 調動和拆除壓樁設備 | D12: Set | E12: 1 | F12: 1 | G12: =_xlfn.XLOOKUP(B12, Rate_Master!$A:$A, Rate_Master!$C:$C, "") -> 0 | H12: =_xlfn.XLOOKUP(B12, Rate_Master!$A:$A, Rate_Master!$D:$D, "") -> 1.15e+08 | I12: =G12+H12 -> 1.15e+08 | J12: =I12*E12 -> 1.15e+08 | K12: =I12*F12 -> 1.15e+08
A13: =$A$11&"."&ROW()-ROW($A$11) -> 3A.C1.2 | B13: Cung cấp cọc thí nghiệm PHC D400A 提供PHC D400A試驗樁 | D13: M | E13: 288 | F13: 288 | G13: =_xlfn.XLOOKUP(B13, Rate_Master!$A:$A, Rate_Master!$C:$C, "") -> 425500 | H13: =_xlfn.XLOOKUP(B13, Rate_Master!$A:$A, Rate_Master!$D:$D, "") -> 0 | I13: =G13+H13 -> 425500 | J13: =I13*E13 -> 1.22544e+08 | K13: =I13*F13 -> 1.22544e+08
A14: =$A$11&"."&ROW()-ROW($A$11) -> 3A.C1.3 | B14: Thi công khoan dẫn cho cọc thí nghiệm PHC D400A PHC D400A試驗樁導孔施工 | D14: M | E14: 264 | F14: 264 | G14: =_xlfn.XLOOKUP(B14, Rate_Master!$A:$A, Rate_Master!$C:$C, "") -> 0 | H14: =_xlfn.XLOOKUP(B14, Rate_Master!$A:$A, Rate_Master!$D:$D, "") -> 69000 | I14: =G14+H14 -> 69000 | J14: =I14*E14 -> 18216000 | K14: =I14*F14 -> 18216000
A15: =$A$11&"."&ROW()-ROW($A$11) -> 3A.C1.4 | B15: Thi công ép cọc thí nghiệm PHC D400A PHC D400A試驗樁壓樁施工 | D15: M | E15: 276 | F15: 276 | G15: =_xlfn.XLOOKUP(B15, Rate_Master!$A:$A, Rate_Master!$C:$C, "") -> 0 | H15: =_xlfn.XLOOKUP(B15, Rate_Master!$A:$A, Rate_Master!$D:$D, "") -> 57500 | I15: =G15+H15 -> 57500 | J15: =I15*E15 -> 15870000 | K15: =I15*F15 -> 15870000
A16: =$A$11&"."&ROW()-ROW($A$11) -> 3A.C1.5 | B16: Thí nghiệm nén tĩnh cọc (khả năng chịu nén, bao gồm ép cọc thí nghiệm và thí nghiệm nghiệm thu khả năng chịu lực của cọc, cao độ đỉnh cọc là cao độ mặt đất sau khi san lấp mặt bằng, Sức chịu tải của cọc đơn là 1100kN, và Tải trọng thí nghiệm là 2200kN) 基樁靜載試驗(抗壓,含先行試打樁及承載力驗收樁檢測、樁頂標高為整地後地面標高，單樁抗壓承載力特徵值1100kN，試驗值為2200kN) | D16: Pcs | E16: 12 | F16: 12 | G16: =_xlfn.XLOOKUP(B16, Rate_Master!$A:$A, Rate_Master!$C:$C, "") -> 0 | H16: =_xlfn.XLOOKUP(B16, Rate_Master!$A:$A, Rate_Master!$D:$D, "") -> 13800000 | I16: =G16+H16 -> 13800000 | J16: =I16*E16 -> 1.656e+08 | K16: =I16*F16 -> 1.656e+08
A17: =$A$11&"."&ROW()-ROW($A$11) -> 3A.C1.6 | B17: Thí nghiệm biến dạng nhỏ PIT cho cọc 基樁小應變試驗 | D17: Pcs | E17: 240 | F17: 240 | G17: =_xlfn.XLOOKUP(B17, Rate_Master!$A:$A, Rate_Master!$C:$C, "") -> 0 | H17: =_xlfn.XLOOKUP(B17, Rate_Master!$A:$A, Rate_Master!$D:$D, "") -> 253000 | I17: =G17+H17 -> 253000 | J17: =I17*E17 -> 60720000 | K17: =I17*F17 -> 60720000
A18: =$A$11&"."&ROW()-ROW($A$11) -> 3A.C1.7 | B18: Cung cấp cọc đại trà PHC D400A 提供PHC D400A工程樁 | D18: M | E18: 26092 | F18: 26092 | G18: =_xlfn.XLOOKUP(B18, Rate_Master!$A:$A, Rate_Master!$C:$C, "") -> 402500 | H18: =_xlfn.XLOOKUP(B18, Rate_Master!$A:$A, Rate_Master!$D:$D, "") -> 0 | I18: =G18+H18 -> 402500 | J18: =I18*E18 -> 1.050203e+10 | K18: =I18*F18 -> 1.050203e+10
A19: =$A$11&"."&ROW()-ROW($A$11) -> 3A.C1.8 | B19: Cung cấp mũi cọc D400 提供D400樁尖 | D19: Pcs | E19: 1198 | F19: 1198 | G19: =_xlfn.XLOOKUP(B19, Rate_Master!$A:$A, Rate_Master!$C:$C, "") -> 80500 | H19: =_xlfn.XLOOKUP(B19, Rate_Master!$A:$A, Rate_Master!$D:$D, "") -> 0 | I19: =G19+H19 -> 80500 | J19: =I19*E19 -> 96439000 | K19: =I19*F19 -> 96439000
A20: =$A$11&"."&ROW()-ROW($A$11) -> 3A.C1.9 | B20: Thi công khoan dẫn cho cọc đại trà PHC D400A PHC D400A工程樁導孔施工 | D20: M | E20: 25258.8 | F20: 25258.8 | G20: =_xlfn.XLOOKUP(B20, Rate_Master!$A:$A, Rate_Master!$C:$C, "") -> 0 | H20: =_xlfn.XLOOKUP(B20, Rate_Master!$A:$A, Rate_Master!$D:$D, "") -> 69000 | I20: =G20+H20 -> 69000 | J20: =I20*E20 -> 1742857200 | K20: =I20*F20 -> 1742857200
A21: =$A$11&"."&ROW()-ROW($A$11) -> 3A.C1.10 | B21: Thi công ép cọc đại trà PHC D400A PHC D400A工程樁壓樁施工 | D21: M | E21: 26444.8 | F21: 26444.8 | G21: =_xlfn.XLOOKUP(B21, Rate_Master!$A:$A, Rate_Master!$C:$C, "") -> 0 | H21: =_xlfn.XLOOKUP(B21, Rate_Master!$A:$A, Rate_Master!$D:$D, "") -> 57500 | I21: =G21+H21 -> 57500 | J21: =I21*E21 -> 1.520576e+09 | K21: =I21*F21 -> 1.520576e+09
A22: =$A$11&"."&ROW()-ROW($A$11) -> 3A.C1.11 | B22: Xử lý đầu cọc D400 ( Bao gồm cắt , cốt thép, bê tông đầu cọc và vận chuyển đầu cọc thừa ra ngoài công trường nếu có) 樁頭處理D400mm(包括切割、鋼筋、樁頭混凝土以及將多餘的樁頭移運到工地外面) | D22: Pcs | E22: 1198 | F22: 1198 | G22: =_xlfn.XLOOKUP(B22, Rate_Master!$A:$A, Rate_Master!$C:$C, "") -> 483000 | H22: =_xlfn.XLOOKUP(B22, Rate_Master!$A:$A, Rate_Master!$D:$D, "") -> 161000 | I22: =G22+H22 -> 644000 | J22: =I22*E22 -> 771512000 | K22: =I22*F22 -> 771512000
A23: =$A$10&2 -> 3A.C2 | B23: Công tác đất 土方工項 | G23: =_xlfn.XLOOKUP(B23, Rate_Master!$A:$A, Rate_Master!$C:$C, "") -> 0 | H23: =_xlfn.XLOOKUP(B23, Rate_Master!$A:$A, Rate_Master!$D:$D, "") -> 0 | J23: =SUBTOTAL(9,J24:J31) -> 3.8413103e+09 | K23: =SUBTOTAL(9,K24:K31) -> 3.8413103e+09
A24: =$A$23&"."&ROW()-ROW($A$23) -> 3A.C2.1 | B24: Đào đất móng, dầm móng 地基、基礎梁開挖 | D24: cum M3 | E24: 3861.199 | F24: 3861.199 | G24: =_xlfn.XLOOKUP(B24, Rate_Master!$A:$A, Rate_Master!$C:$C, "") -> 0 | H24: =_xlfn.XLOOKUP(B24, Rate_Master!$A:$A, Rate_Master!$D:$D, "") -> 32200 | I24: =G24+H24 -> 32200 | J24: =I24*E24 -> 1.2433061e+08 | K24: =I24*F24 -> 1.2433061e+08
A25: =$A$23&"."&ROW()-ROW($A$23) -> 3A.C2.2 | B25: Đầm chặt đất đáy móng, dầm móng 將基礎底部土壤、基礎梁壓實 | D25: sqm M2 | E25: 4108.178 | F25: 4108.178 | G25: =_xlfn.XLOOKUP(B25, Rate_Master!$A:$A, Rate_Master!$C:$C, "") -> 0 | H25: =_xlfn.XLOOKUP(B25, Rate_Master!$A:$A, Rate_Master!$D:$D, "") -> 17250 | I25: =G25+H25 -> 17250 | J25: =I25*E25 -> 70866070 | K25: =I25*F25 -> 70866070
A26: =$A$23&"."&ROW()-ROW($A$23) -> 3A.C2.3 | B26: Lấp đất móng và đầm chặt 將基礎回填並壓實 | D26: cum M3 | E26: 2528.894 | F26: 2528.894 | G26: =_xlfn.XLOOKUP(B26, Rate_Master!$A:$A, Rate_Master!$C:$C, "") -> 0 | H26: =_xlfn.XLOOKUP(B26, Rate_Master!$A:$A, Rate_Master!$D:$D, "") -> 37950 | I26: =G26+H26 -> 37950 | J26: =I26*E26 -> 95971527 | K26: =I26*F26 -> 95971527
A27: =$A$23&"."&ROW()-ROW($A$23) -> 3A.C2.4 | B27: Vận chuyển xử lý đất thừa ( Trong phạm vi công trường) 多餘土壤運輸和處理（施工現場內） | C27: Tận dụng đắp nền nhà xưởng 回填利用廠房地坪 | D27: cum M3 | E27: 1332.307 | F27: 1332.307 | G27: =_xlfn.XLOOKUP(B27, Rate_Master!$A:$A, Rate_Master!$C:$C, "") -> 0 | H27: =_xlfn.XLOOKUP(B27, Rate_Master!$A:$A, Rate_Master!$D:$D, "") -> 32200 | I27: =G27+H27 -> 32200 | J27: =I27*E27 -> 42900285 | K27: =I27*F27 -> 42900285
A28: =$A$23&"."&ROW()-ROW($A$23) -> 3A.C2.5 | B28: Lớp nylon lót cho bê tông lót đài móng dầm móng 用於混凝土承台和基礎樑的尼龍墊層 | D28: sqm M2 | E28: 4108.178 | F28: 4108.178 | G28: =_xlfn.XLOOKUP(B28, Rate_Master!$A:$A, Rate_Master!$C:$C, "") -> 6900 | H28: =_xlfn.XLOOKUP(B28, Rate_Master!$A:$A, Rate_Master!$D:$D, "") -> 1725 | I28: =G28+H28 -> 8625 | J28: =I28*E28 -> 35433035 | K28: =I28*F28 -> 35433035
A29: =$A$23&"."&ROW()-ROW($A$23) -> 3A.C2.6 | B29: Lớp màng HDPE chống ẩm, chống thấm dày 0.3mm ( hàn nhiệt) cho sàn nền tầng 1 一樓地板防潮防水HDPE膜層0.3mm厚（熱焊接） | D29: sqm M2 | E29: 12832.367 | F29: 12832.367 | G29: =_xlfn.XLOOKUP(B29, Rate_Master!$A:$A, Rate_Master!$C:$C, "") -> 34500 | H29: =_xlfn.XLOOKUP(B29, Rate_Master!$A:$A, Rate_Master!$D:$D, "") -> 5750 | I29: =G29+H29 -> 40250 | J29: =I29*E29 -> 5.1650277e+08 | K29: =I29*F29 -> 5.1650277e+08
A30: =$A$23&"."&ROW()-ROW($A$23) -> 3A.C2.7 | B30: San gạt, lu nền hiện trạng nhà xưởng, độ chặt k>=0.90 整平並碾壓廠房現況地基，壓實系數k≥0.90 | D30: sqm M2 | E30: 12832.367 | F30: 12832.367 | G30: =_xlfn.XLOOKUP(B30, Rate_Master!$A:$A, Rate_Master!$C:$C, "") -> 0 | H30: =_xlfn.XLOOKUP(B30, Rate_Master!$A:$A, Rate_Master!$D:$D, "") -> 13800 | I30: =G30+H30 -> 13800 | J30: =I30*E30 -> 1.7708666e+08 | K30: =I30*F30 -> 1.7708666e+08
A31: =$A$23&"."&ROW()-ROW($A$23) -> 3A.C2.8 | B31: Cấp phối đá dăm loại II đầm chặt,dày 35cm, k>=0.92 二型碎石級配層35cm厚，壓實k>=0.92 | D31: cum M3 | E31: 4511.378 | F31: 4511.378 | G31: =_xlfn.XLOOKUP(B31, Rate_Master!$A:$A, Rate_Master!$C:$C, "") -> 512325 | H31: =_xlfn.XLOOKUP(B31, Rate_Master!$A:$A, Rate_Master!$D:$D, "") -> 103500 | I31: =G31+H31 -> 615825 | J31: =I31*E31 -> 2.7782194e+09 | K31: =I31*F31 -> 2.7782194e+09
A32: =$A$10&3 -> 3A.C3 | B32: Công tác bê tông 混凝土工項 | G32: =_xlfn.XLOOKUP(B32, Rate_Master!$A:$A, Rate_Master!$C:$C, "") -> 0 | H32: =_xlfn.XLOOKUP(B32, Rate_Master!$A:$A, Rate_Master!$D:$D, "") -> 0 | J32: =SUBTOTAL(9,J33:J39) -> 1.2062033e+10 | K32: =SUBTOTAL(9,K33:K39) -> 1.2062033e+10
A33: =$A$32&"."&ROW()-ROW($A$32) -> 3A.C3.1 | B33: Bê tông lót đá 1x2 B7.5 cho móng, dầm móng, nền 基礎、基礎樑、底層的石1x2 B7.5混凝土墊層 | D33: cum M3 | E33: 413.654 | F33: 413.654 | G33: =_xlfn.XLOOKUP(B33, Rate_Master!$A:$A, Rate_Master!$C:$C, "") -> 1249762.5 | H33: =_xlfn.XLOOKUP(B33, Rate_Master!$A:$A, Rate_Master!$D:$D, "") -> 207000 | I33: =+H33+G33 -> 1456762.5 | J33: =I33*E33 -> 6.0259564e+08 | K33: =I33*F33 -> 6.0259564e+08
A34: =$A$32&"."&ROW()-ROW($A$32) -> 3A.C3.2 | B34: Bê tông đá 1x2 B30 cho đài móng, dầm móng, cổ cột, vách hố pit thang máy,nền sàn tầng 1 承台、基礎樑、柱頸、電梯坑、一層地面的石1x2 B30混凝土 | D34: cum M3 | E34: 6255.218 | F34: 6255.218 | G34: =_xlfn.XLOOKUP(B34, Rate_Master!$A:$A, Rate_Master!$C:$C, "") -> 1607444.4 | H34: =_xlfn.XLOOKUP(B34, Rate_Master!$A:$A, Rate_Master!$D:$D, "") -> 149500 | I34: =+H34+G34 -> 1756944.4 | J34: =I34*E34 -> 1.0990071e+10 | K34: =I34*F34 -> 1.0990071e+10
A35: =$A$32&"."&ROW()-ROW($A$32) -> 3A.C3.3 | B35: Bê tông đá 1x2 B30 cho cột từ tầng 1 đến tầng mái 從一層到屋頂的柱子採用石1x2 B30混凝土 | D35: cum M3 | E35: 85.486 | F35: 85.486 | G35: =_xlfn.XLOOKUP(B35, Rate_Master!$A:$A, Rate_Master!$C:$C, "") -> 1520555.6 | H35: =_xlfn.XLOOKUP(B35, Rate_Master!$A:$A, Rate_Master!$D:$D, "") -> 253000 | I35: =+H35+G35 -> 1773555.6 | J35: =I35*E35 -> 1.5161417e+08 | K35: =I35*F35 -> 1.5161417e+08
A36: =$A$32&"."&ROW()-ROW($A$32) -> 3A.C3.4 | B36: Bê tông đá 1x2 B30 cho dầm sàn từ tầng 2 đến tầng mái 二樓至屋頂地板樑的石1x2 B30混凝土 | D36: cum M3 | E36: 88.968 | F36: 88.968 | G36: =_xlfn.XLOOKUP(B36, Rate_Master!$A:$A, Rate_Master!$C:$C, "") -> 1520555.6 | H36: =_xlfn.XLOOKUP(B36, Rate_Master!$A:$A, Rate_Master!$D:$D, "") -> 149500 | I36: =+H36+G36 -> 1670055.6 | J36: =I36*E36 -> 1.485815e+08 | K36: =I36*F36 -> 1.485815e+08
A37: =$A$32&"."&ROW()-ROW($A$32) -> 3A.C3.5 | B37: Bê tông đá mi M250 bảo vệ lớp chống thấm mái 保護屋頂防水層的石M250混凝土 | D37: cum M3 | E37: 13.0233 | F37: 13.0233 | G37: =_xlfn.XLOOKUP(B37, Rate_Master!$A:$A, Rate_Master!$C:$C, "") -> 1390222.2 | H37: =_xlfn.XLOOKUP(B37, Rate_Master!$A:$A, Rate_Master!$D:$D, "") -> 149500 | I37: =+H37+G37 -> 1539722.2 | J37: =I37*E37 -> 20052264 | K37: =I37*F37 -> 20052264
A38: =$A$32&"."&ROW()-ROW($A$32) -> 3A.C3.6 | B38: Bê tông đá mi M250 bảo vệ chân cột kết cấu thép thép 保護鋼結構柱腳之M250細石混凝土 | D38: cum M3 | E38: 48.713 | F38: 48.713 | G38: =_xlfn.XLOOKUP(B38, Rate_Master!$A:$A, Rate_Master!$C:$C, "") -> 1390222.2 | H38: =_xlfn.XLOOKUP(B38, Rate_Master!$A:$A, Rate_Master!$D:$D, "") -> 149500 | I38: =+H38+G38 -> 1539722.2 | J38: =I38*E38 -> 75004489 | K38: =I38*F38 -> 75004489
A39: =$A$32&"."&ROW()-ROW($A$32) -> 3A.C3.7 | B39: Vữa tự chảy không co ngót cường độ cao cho chân cột kết cấu thép ‌鋼結構柱腳的高強度無收縮自流砂漿 | D39: cum M3 | E39: 2.43565 | F39: 2.43565 | G39: =_xlfn.XLOOKUP(B39, Rate_Master!$A:$A, Rate_Master!$C:$C, "") -> 22425000 | H39: =_xlfn.XLOOKUP(B39, Rate_Master!$A:$A, Rate_Master!$D:$D, "") -> 8004000 | I39: =+H39+G39 -> 30429000 | J39: =I39*E39 -> 74114394 | K39: =I39*F39 -> 74114394
A40: =$A$10&4 -> 3A.C4 | B40: Công tác ván khuôn 模板工項 | G40: =_xlfn.XLOOKUP(B40, Rate_Master!$A:$A, Rate_Master!$C:$C, "") -> 0 | H40: =_xlfn.XLOOKUP(B40, Rate_Master!$A:$A, Rate_Master!$D:$D, "") -> 0 | J40: =SUBTOTAL(9,J41:J45) -> 2639384435 | K40: =SUBTOTAL(9,K41:K45) -> 2639384435
A41: =$A$40&"."&ROW()-ROW($A$40) -> 3A.C4.1 | B41: Ván khuôn bê tông lót cho móng, dầm móng, nền 基礎、基礎樑和地面的混凝土墊層模板 | D41: sqm M2 | E41: 1106.517 | F41: 1106.517 | G41: =_xlfn.XLOOKUP(B41, Rate_Master!$A:$A, Rate_Master!$C:$C, "") -> 80500 | H41: =_xlfn.XLOOKUP(B41, Rate_Master!$A:$A, Rate_Master!$D:$D, "") -> 92000 | I41: =+H41+G41 -> 172500 | J41: =I41*E41 -> 1.9087418e+08 | K41: =I41*F41 -> 1.9087418e+08
...

Sheet 4A
A2: 工程標單 (II) 詳細價目表 (Detail sheet)
B3: Chủ đầu tư 業主
B4: Dự án 工程名稱
B5: Địa điểm 工程名稱
B6: Hạng mục công trình | C6: =INDEX(總表!$B$9:$B$47,MATCH('4A'!A9,總表!$A$9:$A$48,0)) -> Nhà xưởng sản xuất 3 三號生產廠房
B7: Nhà thầu thi công | C7: Công ty TNHH Công trình L&K Việt Nam
A8: TT 專案 | B8: Tên hạng mục 專案名稱 | C8: Thông số kỹ thuật , mô tả 規格及說明 | D8: Đơn vị 单位 | E8: Khối lượng 專案數量 | G8: Khối lượng Nhà thầu | H8: Vật tư chính 主要材料 | I8: Nhân công + vật tư phụ+ máy thi công 人工+輔助材料+施工機械 | J8: Đơn giá 專案單價 (VND) | K8: Thành Tiền 專案複價 (VND) | L8: Thành tiền Nhà thầu | M8: Ghi chú
A9: 4A | B9: =C6 -> Nhà xưởng sản xuất 3 三號生產廠房 | H9: =_xlfn.XLOOKUP(B9, Rate_Master!$A:$A, Rate_Master!$C:$C, "") -> 0 | I9: =_xlfn.XLOOKUP(B9, Rate_Master!$A:$A, Rate_Master!$D:$D, "") -> 0 | K9: =SUBTOTAL(9,K10:K180) -> 1.1934102e+11 | L9: =SUBTOTAL(9,L10:L180) -> 1.347729e+11
A10: =$A$9&".C" -> 4A.C | B10: KẾT CẤU BÊ TÔNG 混凝土結構 | H10: =_xlfn.XLOOKUP(B10, Rate_Master!$A:$A, Rate_Master!$C:$C, "") -> 0 | I10: =_xlfn.XLOOKUP(B10, Rate_Master!$A:$A, Rate_Master!$D:$D, "") -> 0
A11: =$A$10&1 -> 4A.C1 | B11: Công tác cọc 基樁工項 | H11: =_xlfn.XLOOKUP(B11, Rate_Master!$A:$A, Rate_Master!$C:$C, "") -> 0 | I11: =_xlfn.XLOOKUP(B11, Rate_Master!$A:$A, Rate_Master!$D:$D, "") -> 0 | K11: =SUBTOTAL(9,K12:K22) -> 1.9922871e+10 | L11: =SUBTOTAL(9,L12:L22) -> 20351146350
A12: =$A$11&"."&ROW()-ROW($A$11) -> 4A.C1.1 | B12: Huy động và giải thể thiết bị ép cọc 調動和拆除壓樁設備 | D12: Set | E12: 1 | G12: 1 | H12: =_xlfn.XLOOKUP(B12, Rate_Master!$A:$A, Rate_Master!$C:$C, "") -> 0 | I12: =_xlfn.XLOOKUP(B12, Rate_Master!$A:$A, Rate_Master!$D:$D, "") -> 1.15e+08 | J12: =H12+I12 -> 1.15e+08 | K12: =J12*E12 -> 1.15e+08 | L12: =+G12*J12 -> 1.15e+08
A13: =$A$11&"."&ROW()-ROW($A$11) -> 4A.C1.2 | B13: Cung cấp cọc thí nghiệm PHC D400A 提供PHC D400A試驗樁 | D13: M | E13: 384 | G13: 384 | H13: =_xlfn.XLOOKUP(B13, Rate_Master!$A:$A, Rate_Master!$C:$C, "") -> 425500 | I13: =_xlfn.XLOOKUP(B13, Rate_Master!$A:$A, Rate_Master!$D:$D, "") -> 0 | J13: =H13+I13 -> 425500 | K13: =J13*E13 -> 1.63392e+08 | L13: =+G13*J13 -> 1.63392e+08
A14: =$A$11&"."&ROW()-ROW($A$11) -> 4A.C1.3 | B14: Thi công khoan dẫn cho cọc thí nghiệm PHC D400A PHC D400A試驗樁導孔施工 | D14: M | E14: 352 | G14: 384 | H14: =_xlfn.XLOOKUP(B14, Rate_Master!$A:$A, Rate_Master!$C:$C, "") -> 0 | I14: =_xlfn.XLOOKUP(B14, Rate_Master!$A:$A, Rate_Master!$D:$D, "") -> 69000 | J14: =H14+I14 -> 69000 | K14: =J14*E14 -> 24288000 | L14: =+G14*J14 -> 26496000
A15: =$A$11&"."&ROW()-ROW($A$11) -> 4A.C1.4 | B15: Thi công ép cọc thí nghiệm PHC D400A PHC D400A試驗樁壓樁施工 | D15: M | E15: 368 | G15: 384 | H15: =_xlfn.XLOOKUP(B15, Rate_Master!$A:$A, Rate_Master!$C:$C, "") -> 0 | I15: =_xlfn.XLOOKUP(B15, Rate_Master!$A:$A, Rate_Master!$D:$D, "") -> 57500 | J15: =H15+I15 -> 57500 | K15: =J15*E15 -> 21160000 | L15: =+G15*J15 -> 22080000
A16: =$A$11&"."&ROW()-ROW($A$11) -> 4A.C1.5 | B16: Thí nghiệm nén tĩnh cọc (khả năng chịu nén, bao gồm ép cọc thí nghiệm và thí nghiệm nghiệm thu khả năng chịu lực của cọc, cao độ đỉnh cọc là cao độ mặt đất sau khi san lấp mặt bằng, Sức chịu tải của cọc đơn là 1100kN, và Tải trọng thí nghiệm là 2200kN) 基樁靜載試驗(抗壓,含先行試打樁及承載力驗收樁檢測、樁頂標高為整地後地面標高，單樁抗壓承載力特徵值1100kN，試驗值為2200kN) | D16: Pcs | E16: 16 | G16: 16 | H16: =_xlfn.XLOOKUP(B16, Rate_Master!$A:$A, Rate_Master!$C:$C, "") -> 0 | I16: =_xlfn.XLOOKUP(B16, Rate_Master!$A:$A, Rate_Master!$D:$D, "") -> 13800000 | J16: =H16+I16 -> 13800000 | K16: =J16*E16 -> 2.208e+08 | L16: =+G16*J16 -> 2.208e+08
A17: =$A$11&"."&ROW()-ROW($A$11) -> 4A.C1.6 | B17: Thí nghiệm biến dạng nhỏ PIT cho cọc 基樁小應變試驗 | D17: Pcs | E17: 317 | G17: 384 | H17: =_xlfn.XLOOKUP(B17, Rate_Master!$A:$A, Rate_Master!$C:$C, "") -> 0 | I17: =_xlfn.XLOOKUP(B17, Rate_Master!$A:$A, Rate_Master!$D:$D, "") -> 253000 | J17: =H17+I17 -> 253000 | K17: =J17*E17 -> 80201000 | L17: =+G17*J17 -> 97152000
A18: =$A$11&"."&ROW()-ROW($A$11) -> 4A.C1.7 | B18: Cung cấp cọc đại trà PHC D400A 提供PHC D400A工程樁 | D18: M | E18: 34408 | G18: 34694 | H18: =_xlfn.XLOOKUP(B18, Rate_Master!$A:$A, Rate_Master!$C:$C, "") -> 402500 | I18: =_xlfn.XLOOKUP(B18, Rate_Master!$A:$A, Rate_Master!$D:$D, "") -> 0 | J18: =H18+I18 -> 402500 | K18: =J18*E18 -> 1.384922e+10 | L18: =+G18*J18 -> 1.3964335e+10
A19: =$A$11&"."&ROW()-ROW($A$11) -> 4A.C1.8 | B19: Cung cấp mũi cọc D400 提供D400樁尖 | D19: Pcs | E19: 1580 | G19: 1593 | H19: =_xlfn.XLOOKUP(B19, Rate_Master!$A:$A, Rate_Master!$C:$C, "") -> 80500 | I19: =_xlfn.XLOOKUP(B19, Rate_Master!$A:$A, Rate_Master!$D:$D, "") -> 0 | J19: =H19+I19 -> 80500 | K19: =J19*E19 -> 127190000 | L19: =+G19*J19 -> 128236500
A20: =$A$11&"."&ROW()-ROW($A$11) -> 4A.C1.9 | B20: Thi công khoan dẫn cho cọc đại trà PHC D400A PHC D400A工程樁導孔施工 | D20: M | E20: 33313.6 | G20: 36266.9 | H20: =_xlfn.XLOOKUP(B20, Rate_Master!$A:$A, Rate_Master!$C:$C, "") -> 0 | I20: =_xlfn.XLOOKUP(B20, Rate_Master!$A:$A, Rate_Master!$D:$D, "") -> 69000 | J20: =H20+I20 -> 69000 | K20: =J20*E20 -> 2298638400 | L20: =+G20*J20 -> 2502416100
A21: =$A$11&"."&ROW()-ROW($A$11) -> 4A.C1.10 | B21: Thi công ép cọc đại trà PHC D400A PHC D400A工程樁壓樁施工 | D21: M | E21: 34877.6 | G21: 36266.9 | H21: =_xlfn.XLOOKUP(B21, Rate_Master!$A:$A, Rate_Master!$C:$C, "") -> 0 | I21: =_xlfn.XLOOKUP(B21, Rate_Master!$A:$A, Rate_Master!$D:$D, "") -> 57500 | J21: =H21+I21 -> 57500 | K21: =J21*E21 -> 2.005462e+09 | L21: =+G21*J21 -> 2.0853467e+09
A22: =$A$11&"."&ROW()-ROW($A$11) -> 4A.C1.11 | B22: Xử lý đầu cọc D400 ( Bao gồm cắt , cốt thép, bê tông đầu cọc và vận chuyển đầu cọc thừa ra ngoài công trường nếu có) 樁頭處理D400mm(包括切割、鋼筋、樁頭混凝土以及將多餘的樁頭移運到工地外面) | D22: Pcs | E22: 1580 | G22: 1593 | H22: =_xlfn.XLOOKUP(B22, Rate_Master!$A:$A, Rate_Master!$C:$C, "") -> 483000 | I22: =_xlfn.XLOOKUP(B22, Rate_Master!$A:$A, Rate_Master!$D:$D, "") -> 161000 | J22: =H22+I22 -> 644000 | K22: =J22*E22 -> 1017520000 | L22: =+G22*J22 -> 1025892000
A23: =$A$10&2 -> 4A.C2 | B23: Công tác đất 土方工項 | H23: =_xlfn.XLOOKUP(B23, Rate_Master!$A:$A, Rate_Master!$C:$C, "") -> 0 | I23: =_xlfn.XLOOKUP(B23, Rate_Master!$A:$A, Rate_Master!$D:$D, "") -> 0 | K23: =SUBTOTAL(9,K24:K31) -> 5.1211789e+09 | L23: =SUBTOTAL(9,L24:L31) -> 5.7387377e+09
A24: =$A$23&"."&ROW()-ROW($A$23) -> 4A.C2.1 | B24: Đào đất móng, dầm móng 地基、基礎梁開挖 | D24: cum M3 | E24: 5123.405 | G24: 7482.07 | H24: =_xlfn.XLOOKUP(B24, Rate_Master!$A:$A, Rate_Master!$C:$C, "") -> 0 | I24: =_xlfn.XLOOKUP(B24, Rate_Master!$A:$A, Rate_Master!$D:$D, "") -> 32200 | J24: =H24+I24 -> 32200 | K24: =J24*E24 -> 1.6497364e+08 | L24: =+G24*J24 -> 2.4092265e+08
A25: =$A$23&"."&ROW()-ROW($A$23) -> 4A.C2.2 | B25: Đầm chặt đất đáy móng, dầm móng 將基礎底部土壤、基礎梁壓實 | D25: sqm M2 | E25: 5414.064 | G25: 5546.72 | H25: =_xlfn.XLOOKUP(B25, Rate_Master!$A:$A, Rate_Master!$C:$C, "") -> 0 | I25: =_xlfn.XLOOKUP(B25, Rate_Master!$A:$A, Rate_Master!$D:$D, "") -> 17250 | J25: =H25+I25 -> 17250 | K25: =J25*E25 -> 93392604 | L25: =+G25*J25 -> 95680920
A26: =$A$23&"."&ROW()-ROW($A$23) -> 4A.C2.3 | B26: Lấp đất móng và đầm chặt 將基礎回填並壓實 | D26: cum M3 | E26: 3334.038 | G26: 3941.73 | H26: =_xlfn.XLOOKUP(B26, Rate_Master!$A:$A, Rate_Master!$C:$C, "") -> 0 | I26: =_xlfn.XLOOKUP(B26, Rate_Master!$A:$A, Rate_Master!$D:$D, "") -> 37950 | J26: =H26+I26 -> 37950 | K26: =J26*E26 -> 1.2652674e+08 | L26: =+G26*J26 -> 1.4958865e+08
A27: =$A$23&"."&ROW()-ROW($A$23) -> 4A.C2.4 | B27: Vận chuyển xử lý đất thừa ( Trong phạm vi công trường) 多餘土壤運輸和處理（施工現場內） | C27: Tận dụng đắp nền nhà xưởng 回填利用廠房地坪 | D27: cum M3 | E27: 1789.366 | G27: 3540.34 | H27: =_xlfn.XLOOKUP(B27, Rate_Master!$A:$A, Rate_Master!$C:$C, "") -> 0 | I27: =_xlfn.XLOOKUP(B27, Rate_Master!$A:$A, Rate_Master!$D:$D, "") -> 32200 | J27: =H27+I27 -> 32200 | K27: =J27*E27 -> 57617585 | L27: =+G27*J27 -> 1.1399895e+08
A28: =$A$23&"."&ROW()-ROW($A$23) -> 4A.C2.5 | B28: Lớp nylon lót cho bê tông lót đài móng dầm móng 用於混凝土承台和基礎樑的尼龍墊層 | D28: sqm M2 | E28: 5414.064 | G28: 5546.72 | H28: =_xlfn.XLOOKUP(B28, Rate_Master!$A:$A, Rate_Master!$C:$C, "") -> 6900 | I28: =_xlfn.XLOOKUP(B28, Rate_Master!$A:$A, Rate_Master!$D:$D, "") -> 1725 | J28: =H28+I28 -> 8625 | K28: =J28*E28 -> 46696302 | L28: =+G28*J28 -> 47840460
A29: =$A$23&"."&ROW()-ROW($A$23) -> 4A.C2.6 | B29: Lớp màng HDPE chống ẩm, chống thấm dày 0.3mm ( hàn nhiệt) cho sàn nền tầng 1 一樓地板防潮防水HDPE膜層0.3mm厚（熱焊接） | D29: sqm M2 | E29: 17101.829 | G29: 18883.23 | H29: =_xlfn.XLOOKUP(B29, Rate_Master!$A:$A, Rate_Master!$C:$C, "") -> 34500 | I29: =_xlfn.XLOOKUP(B29, Rate_Master!$A:$A, Rate_Master!$D:$D, "") -> 5750 | J29: =H29+I29 -> 40250 | K29: =J29*E29 -> 6.8834862e+08 | L29: =+G29*J29 -> 7.6005001e+08
A30: =$A$23&"."&ROW()-ROW($A$23) -> 4A.C2.7 | B30: San gạt, lu nền hiện trạng nhà xưởng, độ chặt k>=0.90 整平並碾壓廠房現況地基，壓實系數k≥0.90 | D30: sqm M2 | E30: 17101.829 | G30: 18883.23 | H30: =_xlfn.XLOOKUP(B30, Rate_Master!$A:$A, Rate_Master!$C:$C, "") -> 0 | I30: =_xlfn.XLOOKUP(B30, Rate_Master!$A:$A, Rate_Master!$D:$D, "") -> 13800 | J30: =H30+I30 -> 13800 | K30: =J30*E30 -> 2.3600524e+08 | L30: =+G30*J30 -> 2.6058857e+08
A31: =$A$23&"."&ROW()-ROW($A$23) -> 4A.C2.8 | B31: Cấp phối đá dăm loại II đầm chặt,dày 35cm, k>=0.92 二型碎石級配層35cm厚，壓實k>=0.92 | D31: cum M3 | E31: 6020.571 | G31: 6609.13 | H31: =_xlfn.XLOOKUP(B31, Rate_Master!$A:$A, Rate_Master!$C:$C, "") -> 512325 | I31: =_xlfn.XLOOKUP(B31, Rate_Master!$A:$A, Rate_Master!$D:$D, "") -> 103500 | J31: =H31+I31 -> 615825 | K31: =J31*E31 -> 3.7076181e+09 | L31: =+G31*J31 -> 4.0700675e+09
